Workbook
Name CQ: '[1]Roll-Forward Dates'!$C$124
Name CQ_and_PY_Date: '[1]Roll-Forward Dates'!$C$153
Name CQ_CAPS: '[1]Roll-Forward Dates'!$C$125
Name CQ_Comparative: '[1]Roll-Forward Dates'!$C$148
Name CY_FiHis_FF1: 'VIII-B'!$C$149:$E$160
Name CY_FiHis_FF2: 'VIII-C'!$C$148:$E$159
Name CY_FiHis_FF3: 'VIII-D'!$C$148:$E$159
Name CY_FiHis_MF: 'EFM V'!$C$50:$E$61
Name CY_FiHis_MF: VIII!$C$149:$E$160
Name CYTD: '[1]Roll-Forward Dates'!$C$147
Name CYTD_and_YE_PY_Date: '[1]Roll-Forward Dates'!$C$152
Name FS_Stm_Oprations: [1]Inc!$A$7:$C$30
Name Period_05: '[1]Roll-Forward Dates'!$C$126
Name PY: '[1]Roll-Forward Dates'!$C$122
Name PY_Date: '[1]Roll-Forward Dates'!$C$140

Sheet VIII
E8: 45473
C17: Internal rate of return
C18: Internal rate of return after incentive allocation | E18: =G140 -> 0.0063035399
C19: ROI | E19: =(G138+I139)/-I138 -> 1.0330539
C21: Sample Investor Ownership Percentage (Pro-rata share of commitments - to calculate fund level amounts divide the cash flows in column G by the ownership % below)
C22: 0.000831429
C23: Contributions 2010 | E23: 40512 | G23: -63000
C24: Contributions 2011 | E24: 40570 | G24: -31500
E25: 40661 | G25: -24194.61
E26: 40704 | G26: -38162.64
E27: 40751 | G27: -36499.78
E28: 40765 | G28: -60694.39
E29: 40813 | G29: -53460.95
E30: 40879 | G30: -25691.19
E31: 40886 | G31: -35003.2
C32: Contributions 2012 | E32: 40927 | G32: -58532.67
E33: 40942 | G33: -274371.9
E34: 40970 | G34: -43650.08
E35: 41001 | G35: -25524.9
E36: 41024 | G36: -30264.05
E37: 41054 | G37: -39409.78
E38: 41080 | G38: -73082.7
E39: 41103 | G39: -23695.76
E40: 41121 | G40: -22864.33
E41: 41152 | G41: -30264
E42: 41180 | G42: -57368.58
E43: 41194 | G43: -28185.43
E44: 41250 | G44: -127125.41
E45: 41264 | G45: -112908
C46: Distribution 2012 | E46: 41030 | G46: 112056.47
E47: 41108 | G47: 24215.98
E48: 41137 | G48: 10363.64
E49: 41173 | G49: 223637.66
C50: Contributions 2013 | E50: 41284 | G50: -33340.28
E51: 41298 | G51: -42652.29
E52: 41345 | G52: -43733.14
E53: 41360 | G53: -39160.28
E54: 41393 | G54: -31511.15
E55: 41404 | G55: -42901.72
E56: 41423 | G56: -37164.86
...

Sheet VIII-B
E8: =+VIII!E8 -> 45473
C17: Internal rate of return
C18: Internal rate of return after incentive allocation | E18: =+G140 -> 0.0039684743
C19: ROI | E19: =(G138+I139)/-I138 -> 1.0210875
C21: Sample Investor Ownership Percentage (Pro-rata share of commitments - to calculate fund level amounts divide the cash flows in column G by the ownership % below)
C22: 0.033025234
C23: Contributions 2010 | E23: 40512 | G23: -157500
C24: Contributions 2011 | E24: 40570 | G24: -78750
E25: 40661 | G25: -60486.43
E26: 40704 | G26: -95406.42
E27: 40751 | G27: -91249.28
E28: 40765 | G28: -151735.71
E29: 40813 | G29: -133652.14
E30: 40879 | G30: -64227.85
E31: 40886 | G31: -87507.85
C32: Contributions 2012 | E32: 40927 | G32: -146331.42
E33: 40942 | G33: -685928.54
E34: 40970 | G34: -109124.99
E35: 41001 | G35: -63812.14
E36: 41024 | G36: -75660
E37: 41054 | G37: -98524.28
E38: 41080 | G38: -182706.42
E39: 41103 | G39: -59239.28
E40: 41121 | G40: -57160.71
E41: 41152 | G41: -75660.01
E42: 41180 | G42: -143421.43
E43: 41194 | G43: -70463.57
E44: 41250 | G44: -317813.58
E45: 41264 | G45: -282270
C46: Distribution 2012 | E46: 41030 | G46: 235528.56
E47: 41108 | G47: 59889.22
E48: 41137 | G48: 25909.14
E49: 41173 | G49: 519144.04
C50: Contributions 2013 | E50: 41284 | G50: -83350.73
E51: 41298 | G51: -106630.71
E52: 41345 | G52: -109332.86
E53: 41360 | G53: -97900.71
E54: 41393 | G54: -78777.85
E55: 41404 | G55: -107254.28
E56: 41423 | G56: -92912.15
...

Sheet VIII-C
E8: =+VIII!E8 -> 45473
C17: Internal rate of return
C18: Internal rate of return after incentive allocation | E18: =+G139 -> 0.0046625227
C19: ROI | E19: =(G137+I138)/-I137 -> 1.0246434
C21: Sample Investor Ownership Percentage (Pro-rata share of commitments - to calculate fund level amounts divide the cash flows in column G by the ownership % below)
C22: 0.15163002
C23: Contributions 2011 | E23: 40590 | G23: -3150000
E24: 40661 | G24: -806485.68
E25: 40704 | G25: -1272085.7
E26: 40751 | G26: -1216657.1
E27: 40765 | G27: -2023142.8
E28: 40813 | G28: -1782028.5
E29: 40879 | G29: -856371.39
E30: 40886 | G30: -1166771.4
C31: Contributions 2012 | E31: 40927 | G31: -1951085.6
E32: 40942 | G32: -9145713.9
E33: 40970 | G33: -1454999.9
E34: 41001 | G34: -850828.54
E35: 41024 | G35: -1008800
E36: 41054 | G36: -1313657.1
E37: 41080 | G37: -2436085.6
E38: 41103 | G38: -789857.11
E39: 41121 | G39: -762142.83
E40: 41152 | G40: -1008800
E41: 41180 | G41: -1912285.7
E42: 41194 | G42: -939514.29
E43: 41250 | G43: -4237514.3
E44: 41264 | G44: -3763600
C45: Distribution 2012 | E45: 41030 | G45: 3231985.6
E46: 41108 | G46: 805926.42
E47: 41137 | G47: 345455.13
E48: 41173 | G48: 7058897.3
C49: Contributions 2013 | E49: 41284 | G49: -1111342.9
E50: 41298 | G50: -1421742.9
E51: 41345 | G51: -1457771.4
E52: 41360 | G52: -1305342.8
E53: 41393 | G53: -1050371.4
E54: 41404 | G54: -1430057.1
E55: 41423 | G55: -1238828.6
E56: 41446 | G56: -3785771.4
...

Sheet VIII-D
E8: =+VIII!E8 -> 45473
C17: Internal rate of return
C18: Internal rate of return after incentive allocation | E18: =+G139 -> 0.0055457741
C19: ROI | E19: =(G137+I138)/-I137 -> 1.0290692
C21: Sample Investor Ownership Percentage (Pro-rata share of commitments - to calculate fund level amounts divide the cash flows in column G by the ownership % below)
C22: 0.028643258
C23: Contributions 2011 | E23: 40590 | G23: -244125
E24: 40661 | G24: -62502.65
E25: 40704 | G25: -98586.65
E26: 40751 | G26: -94290.93
E27: 40765 | G27: -156793.58
E28: 40813 | G28: -138107.22
E29: 40879 | G29: -66368.79
E30: 40886 | G30: -90424.79
C31: Contributions 2012 | E31: 40927 | G31: -151209.15
E32: 40942 | G32: -708792.89
E33: 40970 | G33: -112762.51
E34: 41001 | G34: -65939.22
E35: 41024 | G35: -78182
E36: 41030 | G36: 288418.75
E37: 41054 | G37: -101808.43
E38: 41080 | G38: -188796.65
E39: 41103 | G39: -61213.93
E40: 41108 | G40: 62022.65
E41: 41121 | G41: -59066.07
E42: 41137 | G42: 26772.78
E43: 41152 | G43: -78182.01
E44: 41173 | G44: 577612.2
C45: Distribution 2012 | E45: 41180 | G45: -148202.14
E46: 41194 | G46: -72812.36
E47: 41250 | G47: -328407.36
E48: 41264 | G48: -291678.99
C49: Contributions 2013 | E49: 41284 | G49: -86129.08
E50: 41298 | G50: -110185.07
E51: 41345 | G51: -112977.29
E52: 41360 | G52: -101164.06
E53: 41393 | G53: -81403.8
E54: 41404 | G54: -110829.43
E55: 41418 | G55: 33721.7
E56: 41423 | G56: -96009.23
...

Sheet Fund IX
E8: 45473
C17: Internal rate of return
C18: Internal rate of return after incentive allocation | E18: =G174 -> 0.10949377
C19: ROI | E19: =(G172+I173)/-I172 -> 1.5203454
C21: Sample Investor Ownership Percentage (Pro-rata share of commitments - to calculate fund level amounts divide the cash flows in column G by the ownership % below)
C22: 0.000194
C23: Contributions 2013 | E23: 41282 | G23: -6000
E24: 41359 | G24: -4947
E25: 41381 | G25: -1920.6
E26: 41424 | G26: -1610.2
E27: 41446 | G27: -58665.6
E28: 41498 | G28: -3918.8
E29: 41527 | G29: -9855.2
E30: 41534 | G30: -5024.6
E31: 41551 | G31: -4772.4
E32: 41585 | G32: -9137.4
E33: 41621 | G33: -16625.8
E34: 41635 | G34: -6770.6
C35: Contributions 2014 | E35: 41670 | G35: -5781.2
E36: 41712 | G36: -14666.47
E37: 41724 | G37: -5315.6
E38: 41733 | G38: -8380.8
E39: 41764 | G39: -7333.21
E40: 41774 | G40: -10320.8
E41: 41788 | G41: -8012.19
E42: 41817 | G42: -14394.8
E43: 41830 | G43: -9098.61
E44: 41851 | G44: -5121.6
E45: 41859 | G45: -9777.6
E46: 41880 | G46: -6052.8
E47: 41900 | G47: -24948.41
... E51: 41977 | G51: -19109
C52: Distributions 2014 | E52: 41817 | G52: 14124.6
C53: Contributions 2015 | E53: 42009 | G53: -61672.6
E54: 42027 | G54: -29216.4
E55: 42048 | G55: -13075.61
E56: 42061 | G56: -9525.4
E57: 42088 | G57: -20331.2
E58: 42111 | G58: -16431.79
E59: 42138 | G59: -14200.8
...

Sheet Fund IX-C
E8: =+'Fund IX'!E8 -> 45473
C17: Internal rate of return
C18: Internal rate of return after incentive allocation | E18: =G175 -> 0.096679205
C19: ROI | E19: =(G173+I174)/-I173 -> 1.4943762
C21: Sample Investor Ownership Percentage (Pro-rata share of commitments - to calculate fund level amounts divide the cash flows in column G by the ownership % below)
C22: 0.013382981
C23: Contributions 2013 | E23: 41282 | G23: -90000
E24: 41359 | G24: -74205
E25: 41381 | G25: -28809
E26: 41424 | G26: -24153.01
E27: 41446 | G27: -879983.99
E28: 41498 | G28: -58782
E29: 41527 | G29: -147828
E30: 41534 | G30: -75369.01
E31: 41551 | G31: -71586
E32: 41585 | G32: -137061
E33: 41621 | G33: -249387
E34: 41635 | G34: -101559
C35: Contributions 2014 | E35: 41670 | G35: -86718
E36: 41712 | G36: -219997.24
E37: 41724 | G37: -79734
E38: 41733 | G38: -125712
E39: 41764 | G39: -109998
E40: 41774 | G40: -154812
E41: 41788 | G41: -120183.01
E42: 41817 | G42: -215922
E43: 41830 | G43: -136478.99
E44: 41851 | G44: -76824
E45: 41859 | G45: -146664
E46: 41880 | G46: -90792
E47: 41900 | G47: -374226
... E51: 41977 | G51: -286635
C52: Distributions 2014 | E52: 41817 | G52: 197235.54
C53: Contributions 2015 | E53: 42009 | G53: -925089.01
E54: 42027 | G54: -438246
E55: 42048 | G55: -196133.99
E56: 42061 | G56: -142881
E57: 42088 | G57: -304968.01
E58: 42111 | G58: -246477.01
E59: 42138 | G59: -213012
...

Sheet Fund IX-D
E8: =+'Fund IX'!E8 -> 45473
C17: Internal rate of return
C18: Internal rate of return after incentive allocation | E18: =G175 -> 0.10905294
C19: ROI | E19: =(G173+I174)/-I173 -> 1.5183514
C21: Sample Investor Ownership Percentage (Pro-rata share of commitments - to calculate fund level amounts divide the cash flows in column G by the ownership % below)
C22: 0.0030979702
C23: Contributions 2013 | E23: 41282 | G23: -6000
E24: 41359 | G24: -4947
E25: 41381 | G25: -1920.6
E26: 41424 | G26: -1610.2
E27: 41446 | G27: -58665.6
E28: 41498 | G28: -3918.8
E29: 41527 | G29: -9855.2
E30: 41534 | G30: -5024.6
E31: 41551 | G31: -4772.4
E32: 41585 | G32: -9137.4
E33: 41621 | G33: -16625.8
E34: 41635 | G34: -6770.6
C35: Contributions 2014 | E35: 41670 | G35: -5781.2
E36: 41712 | G36: -14666.47
E37: 41724 | G37: -5315.6
E38: 41733 | G38: -8380.8
E39: 41764 | G39: -7333.21
E40: 41774 | G40: -10320.8
E41: 41788 | G41: -8012.2
E42: 41817 | G42: -14394.8
E43: 41830 | G43: -9098.61
E44: 41851 | G44: -5121.6
E45: 41859 | G45: -9777.6
E46: 41880 | G46: -6052.8
E47: 41900 | G47: -24948.41
... E51: 41977 | G51: -19109
C52: Distributions 2014 | E52: 41817 | G52: 13980.57
C53: Contributions 2015 | E53: 42009 | G53: -61672.6
E54: 42027 | G54: -29216.4
E55: 42048 | G55: -13075.61
E56: 42061 | G56: -9525.4
E57: 42088 | G57: -20331.2
E58: 42111 | G58: -16431.8
E59: 42138 | G59: -14200.8
...

Sheet Fund X
E8: 45473
C17: Internal rate of return
C18: Internal rate of return after incentive allocation | E18: =G169 -> 0.16366394
C19: ROI | E19: =-(G167+J170)/J169 -> 2.0419294
C21: Sample Investor Ownership Percentage (Pro-rata share of commitments - to calculate fund level amounts divide the cash flows in column G by the ownership % below)
C22: 0.000223846
C24: Contributions 2015 | E24: 42089 | G24: -71700
E25: 42118 | G25: 23052.4
E26: 42180 | G26: -7095.93
E27: 42201 | G27: -2216.09
E28: 42271 | G28: -6961.62
E29: 42324 | G29: -10587.93
E30: 42367 | G30: -28316.54
C31: Contributions 2016 | E31: 42396 | G31: -46425.69
E32: 42453 | G32: -10319.32
E33: 42461 | G33: -7476.46
E34: 42500 | G34: -6446.76
E35: 42513 | G35: -21354.92
E36: 42524 | G36: -50052
E37: 42544 | G37: -73690.16
E38: 42564 | G38: -8058.46
E39: 42585 | G39: -35860.15
E40: 42614 | G40: -13676.99
E41: 42641 | G41: -20952
E42: 42656 | G42: -22362.23
E43: 42704 | G43: -19183.62
... E45: 42733 | G45: -13318.84
C46: Distributions 2016 | E46: 42716 | G46: 17744.73
C47: Contributions 2017 | E47: 42754 | G47: -12983.08
E48: 42765 | G48: -13251.7
E49: 42773 | G49: -22608.46
E50: 42797 | G50: -31629.46
E51: 42817 | G51: -18758.31
E52: 42828 | G52: -16296
E53: 42851 | G53: -71496.45
E54: 42863 | G54: -15087.24
E55: 42878 | G55: -17057.08
E56: 42893 | G56: -32032.38
E57: 42907 | G57: -16989.92
E58: 42915 | G58: -38949.24
...

Sheet Fund X-C
E8: =+'Fund X'!E8 -> 45473
C17: Internal rate of return
C18: Internal rate of return after incentive allocation | E18: =G169 -> 0.1491946
C19: ROI | E19: =-(G167+J170)/J169 -> 1.9077009
C21: Sample Investor Ownership Percentage (Pro-rata share of commitments - to calculate fund level amounts divide the cash flows in column G by the ownership % below)
C22: 0.001086909
C24: Contributions 2015 | E24: 42089 | G24: -71700
E25: 42118 | G25: 23052.4
E26: 42180 | G26: -7095.93
E27: 42201 | G27: -2216.09
E28: 42271 | G28: -6961.62
E29: 42324 | G29: -10587.93
E30: 42367 | G30: -28316.54
C31: Contributions 2016 | E31: 42396 | G31: -46425.69
E32: 42453 | G32: -10319.32
E33: 42461 | G33: -7476.46
E34: 42500 | G34: -6446.76
E35: 42513 | G35: -21354.92
E36: 42524 | G36: -50052
E37: 42544 | G37: -73690.16
E38: 42564 | G38: -8058.46
E39: 42585 | G39: -35860.16
E40: 42614 | G40: -13676.99
E41: 42641 | G41: -20952
E42: 42656 | G42: -22362.23
E43: 42704 | G43: -19183.62
... E45: 42733 | G45: -13318.84
C46: Distributions 2016 | E46: 42716 | G46: 17585.47
C47: Contributions 2017 | E47: 42754 | G47: -12983.08
E48: 42765 | G48: -13251.7
E49: 42773 | G49: -22608.46
E50: 42797 | G50: -31629.46
E51: 42817 | G51: -18758.31
E52: 42828 | G52: -16296
E53: 42851 | G53: -71496.45
E54: 42863 | G54: -15087.24
E55: 42878 | G55: -17057.08
E56: 42893 | G56: -32032.38
E57: 42907 | G57: -16989.92
E58: 42915 | G58: -38949.24
...

Sheet Fund X-D
E8: =+'Fund X'!E8 -> 45473
C17: Internal rate of return
C18: Internal rate of return after incentive allocation | E18: =G169 -> 0.16335827
C19: ROI | E19: =-(G167+J170)/(J169) -> 2.0406042
C21: Sample Investor Ownership Percentage (Pro-rata share of commitments - to calculate fund level amounts divide the cash flows in column G by the ownership % below)
C22: 0.009989242
C24: Contributions 2015 | E24: 42089 | G24: -155350
E25: 42118 | G25: 49946.86
E26: 42180 | G26: -15374.51
E27: 42201 | G27: -4801.51
E28: 42271 | G28: -15083.5
E29: 42324 | G29: -22940.5
E30: 42367 | G30: -61352.5
C31: Contributions 2016 | E31: 42396 | G31: -100589
E32: 42453 | G32: -22358.5
E33: 42461 | G33: -16199
E34: 42500 | G34: -13968
E35: 42513 | G35: -46268.99
E36: 42524 | G36: -108446
E37: 42544 | G37: -159662
E38: 42564 | G38: -17460
E39: 42585 | G39: -77697.02
E40: 42614 | G40: -29633.49
E41: 42641 | G41: -45396
E42: 42656 | G42: -48451.5
E43: 42704 | G43: -41564.5
... E45: 42733 | G45: -28857.49
C46: Distributions 2016 | E46: 42716 | G46: 37881.4
C47: Contributions 2017 | E47: 42754 | G47: -28130
E48: 42765 | G48: -28711.99
E49: 42773 | G49: -48985
E50: 42797 | G50: -68530.51
E51: 42817 | G51: -40643
E52: 42828 | G52: -35308
E53: 42851 | G53: -154909
E54: 42863 | G54: -32689.01
E55: 42878 | G55: -36957
E56: 42893 | G56: -69403.5
E57: 42907 | G57: -36811.5
E58: 42915 | G58: -84390
...

Sheet Fund XI
E8: 45473
C17: Internal rate of return
C18: Internal rate of return after incentive allocation | E18: =G136 -> 0.22160023
C19: ROI | E19: =-(G134+J137)/J136 -> 1.8470878
C21: Sample Investor Ownership Percentage (Pro-rata share of commitments - to calculate fund level amounts divide the cash flows in column G by the ownership % below)
C22: =2000000/6961190721.65 -> 0.00028730717
C24: Contributions 2017 | E24: 42933 | G24: -33800
E25: 43010 | G25: -8200
E26: 43052 | G26: -3600
E27: 43087 | G27: -15835.83
E28: 43096 | G28: -9710.99
C29: Contributions 2018 | E29: 43182 | G29: -70246.61
E30: 43276 | G30: -24938.27
E31: 43363 | G31: -18588.78
E32: 43398 | G32: -16290.31
E33: 43433 | G33: -13216.14
C34: Contributions 2019 | E34: 43468 | G34: -22438.69
E35: 43495 | G35: -36976.44
E36: 43510 | G36: -14853.79
E37: 43559 | G37: -20599.93
E38: 43593 | G38: -20542.46
E39: 43642 | G39: -32810.49
E40: 43656 | G40: -24363.64
E41: 43684 | G41: -21260.73
E42: 43768 | G42: -21030.88
E43: 43817 | G43: -161696.48
C44: Contributions 2020 | E44: 44006 | G44: -11980.7
E45: 44026 | G45: -29621.37
E46: 44106 | G46: -10170.67
E47: 44182 | G47: -41228.58
E48: 44188 | G48: -9596.06
C49: Contributions 2021 | E49: 44246 | G49: -8849.07
E50: 44250 | G50: -9337.48
E51: 44274 | G51: -14710.13
E52: 44305 | G52: -163880.01
E53: 44362 | G53: 25713.99
E54: 44400 | G54: -20111.5
E55: 44407 | G55: -21548.04
E56: 44440 | G56: -10285.59
E57: 44453 | G57: -16979.85
...

Sheet Fund XI-C
B4: Financial Highlights Fund XI-C
E8: ='Fund XI'!E8 -> 45473
C17: Internal rate of return
C18: Internal rate of return after incentive allocation | E18: =G136 -> 0.20284775
C19: ROI | E19: =-(G134+J137)/J136 -> 1.7493065
C21: Sample Investor Ownership Percentage (Pro-rata share of commitments - to calculate fund level amounts divide the cash flows in column G by the ownership % below)
C22: 0.027350044
C24: Contributions 2017 | E24: 42933 | G24: -422500
E25: 43010 | G25: -102500
E26: 43052 | G26: -45000
E27: 43087 | G27: -197947.88
E28: 43096 | G28: -121387.29
C29: Contributions 2018 | E29: 43182 | G29: -878082.53
E30: 43276 | G30: -311728.27
E31: 43363 | G31: -232359.67
E32: 43398 | G32: -203628.95
E33: 43433 | G33: -165201.61
C34: Contributions 2019 | E34: 43468 | G34: -280483.64
E35: 43495 | G35: -462205.41
E36: 43510 | G36: -185672.25
E37: 43559 | G37: -257499.03
E38: 43593 | G38: -256780.77
E39: 43642 | G39: -410130.99
E40: 43656 | G40: -304545.62
E41: 43684 | G41: -265759.16
E42: 43768 | G42: -262886.05
E43: 43817 | G43: -2021205.9
C44: Contributions 2020 | E44: 44006 | G44: -149758.87
E45: 44026 | G45: -370267.11
E46: 44105 | G46: -127133.42
E47: 44182 | G47: -515357.25
E48: 44188 | G48: -119950.73
C49: Contributions 2021 | E49: 44246 | G49: -110613.25
E50: 44250 | G50: -116718.53
E51: 44274 | G51: -183876.57
E52: 44305 | G52: -2048500.1
E53: 44362 | G53: 321424.89
E54: 44400 | G54: -251393.78
E55: 44407 | G55: -269350.47
E56: 44440 | G56: -128569.95
...

Sheet Fund XI-D
E8: ='Fund XI'!E8 -> 45473
C17: Internal rate of return
C18: Internal rate of return after incentive allocation | E18: =G136 -> 0.22131165
C19: ROI | E19: =-(G134+J137)/J136 -> 1.8461387
C21: Sample Investor Ownership Percentage (Pro-rata share of commitments - to calculate fund level amounts divide the cash flows in column G by the ownership % below)
C22: 0.012144909
C24: Contributions 2017 | E24: 42933 | G24: -118300
E25: 43010 | G25: -28700
E26: 43052 | G26: -12600
E27: 43087 | G27: -55425.4
E28: 43096 | G28: -33988.44
C29: Contributions 2018 | E29: 43182 | G29: -245863.11
E30: 43276 | G30: -87283.92
E31: 43363 | G31: -65060.71
E32: 43398 | G32: -57016.11
E33: 43433 | G33: -46256.45
C34: Contributions 2019 | E34: 43468 | G34: -78535.4
E35: 43495 | G35: -129417.52
E36: 43510 | G36: -51988.23
E37: 43559 | G37: -72099.73
E38: 43593 | G38: -71898.61
E39: 43642 | G39: -114836.68
E40: 43656 | G40: -85272.77
E41: 43684 | G41: -74412.54
E42: 43768 | G42: -73608.09
E43: 43817 | G43: -565937.67
C44: Contributions 2020 | E44: 44006 | G44: -41932.49
E45: 44026 | G45: -103674.79
E46: 44105 | G46: -35597.36
E47: 44182 | G47: -144300.02
E48: 44188 | G48: -33586.21
C49: Contributions 2021 | E49: 44246 | G49: -30971.71
E50: 44250 | G50: -32681.18
E51: 44274 | G51: -51485.45
E52: 44305 | G52: -573580.03
E53: 44362 | G53: 89998.97
E54: 44400 | G54: -70390.26
E55: 44407 | G55: -75418.13
E56: 44440 | G56: -35999.59
E57: 44453 | G57: -59429.49
...

Sheet Fund XII
E8: 45473
C17: Internal rate of return
C18: Internal rate of return after incentive allocation | E18: =G38 -> 0.69209448
C19: ROI | E19: =-(G36+J39)/J38 -> 1.420493
C21: Sample Investor Ownership Percentage (Pro-rata share of commitments - to calculate fund level amounts divide the cash flows in column G by the ownership % below)
C22: 1
C24: Contributions 2023 | E24: 45083 | G24: -5.0081108e+08
E25: 45119 | G25: -44193508
E26: 45142 | G26: =-198857476.16-3845352.53 -> -2.0270283e+08
E27: 45146 | G27: 2.5920489e+08
E28: 45239 | G28: =-87193668.87+3105142.88 -> -84088526
C29: Contributions 2024 | E29: 45327 | G29: -68426622
E30: 45357 | G30: 99078816
E31: 45383 | G31: -80702625
E32: 45407 | G32: -52042125
E33: 45413 | G33: -38413114
E34: 45443 | G34: -3.3661151e+08
C36: Net assets | E36: =+E8 -> 45473 | G36: 1.4911032e+09
C38: Total return | G38: =XIRR(G24:G36,E24:E36,0.1) -> 0.69209448 | J38: =+SUMIF($G$24:$G$35,"<0",$G$24:$G$35)+G27+G30 -> -1.0497082e+09 | K38: check figure-Contributions
J39: =+SUMIF($G$24:$G$35,">0",$G$24:$G$35)-G27-G30 -> 0 | K39: check figure-Distributions

Sheet EETF I-A
E8: 45473
C17: Internal rate of return
C18: Internal rate of return after incentive allocation | E18: =G83 -> 0.23142801
C19: ROI | E19: =-(G81+I82)/I81 -> 1.3947364
C21: Sample Investor Ownership Percentage (Pro-rata share of commitments - to calculate fund level amounts divide the cash flows in column G by the ownership % below)
C22: 1
C24: Contributions 2020 | E24: 43857 | G24: =-8355693.57*193814409.75/213814409.75 -> -7574109.8
E25: 43985 | G25: =-8946403.4*193814409.75/213814409.75 -> -8109565.2
E26: 44076 | G26: =-8101403.91*193814409.75/213814409.75-1912477.07 -> -9256083.2
E27: 44117 | G27: =-10183965.83*193814409.75/213814409.75 -> -9231367.2
E28: 44141 | G28: =-9094491.06*193814409.75/213814409.75 -> -8243800.9
E29: 44148 | G29: =-4743875.63*193814409.75/213814409.75 -> -4300137.9
E30: 44187 | G30: =-4000309.07*193814409.75/213814409.75-294804.35 -> -3920928.2
C31: Contributions 2021 | E31: 44203 | G31: =-17965219.19*193814409.75/213814409.75-492157.19 -> -16776927
E32: 44217 | G32: =-2420477.32*193814409.75/213814409.75 -> -2194068.1
E33: 44250 | G33: =8743624.8*193814409.75/213814409.75 -> 7925754.3
E34: 44265 | G34: =-5278462.5*193814409.75/213814409.75-155480.19 -> -4940200.2
E35: 44291 | G35: =-12658173.89*193814409.75/213814409.75-268874.97 -> -11743015
E36: 44307 | G36: =-28503534.36*193814409.75/213814409.75-795428.94 -> -26632769
E37: 44319 | G37: =29772852.87*193814409.75/213814409.75 -> 26987928
E38: 44335 | G38: =-13567083.21*193814409.75/213814409.75-457505.62 -> -12755537
E39: 44344 | G39: =16251618.18*193814409.75/213814409.75 -> 14731457
E40: 44361 | G40: =416746.8*193814409.75/213814409.75+67984.53 -> 445749.22
E41: 44375 | G41: -6218476.1
E42: 44405 | G42: -3521086
E43: 44468 | G43: -1653652.9
E44: 44475 | G44: -4024098.3
E45: 44483 | G45: -4703164.9
E46: 44505 | G46: -4225303.2
E47: 44551 | G47: -2584225.6
C48: Distributions 2021 | E48: 44558 | G48: 41112360
C49: Contributions 2022 | E49: 44599 | G49: -1735392.4
E50: 44635 | G50: -5023835.2
E51: 44676 | G51: -2842019.4
E52: 44686 | G52: -6312804.1
E53: 44701 | G53: -6438557.2
E54: 44728 | G54: -3414195.9
E55: 44781 | G55: -8173949.6
E56: 44817 | G56: -11771667
E57: 44852 | G57: -2791718.2
...

Sheet EFM II
E8: 45473
C17: Internal rate of return
C18: Internal rate of return after incentive allocation | E18: =G99 -> 0.25848636
C19: ROI | E19: =-(G97+J100)/(J99) -> 1.6337399
C21: Sample Investor Ownership Percentage (Pro-rata share of commitments - to calculate fund level amounts divide the cash flows in column G by the ownership % below)
C22: 0.0056
C23: Contributions 2012 | E23: 41089 | G23: -75000
E24: 41166 | G24: -94080
E25: 41270 | G25: -273280
C26: Contributions 2013 | E26: 41311 | G26: -97440
E27: 41341 | G27: -140000
E28: 41361 | G28: -62720
E29: 41387 | G29: -136640
E30: 41408 | G30: -58800
E31: 41439 | G31: -136080
E32: 41479 | G32: -150640
E33: 41515 | G33: -94640
E34: 41543 | G34: -352800
E35: 41605 | G35: -83440
E36: 41638 | G36: -59920
C37: Contributions 2014 | E37: 41683 | G37: -61600
E38: 41701 | G38: -89599.99
E39: 41729 | G39: -115360
E40: 41751 | G40: -81200
E41: 41782 | G41: -138320
E42: 41808 | G42: -332080
E43: 41894 | G43: -69440
E44: 41942 | G44: -98560
E45: 41962 | G45: -218960
E46: 41975 | G46: -257600
C47: Distributions 2014 | E47: 41969 | G47: 950190.04
C48: Contributions 2015 | E48: 42037 | G48: -216720
E49: 42094 | G49: -188160
E50: 42110 | G50: -157360
E51: 42145 | G51: -196560
E52: 42158 | G52: -563360
E53: 42261 | G53: -423920
E54: 42366 | G54: -105840
C55: Distributions 2015 | E55: 42341 | G55: 167083.98
C56: Contributions 2016 | E56: 42397 | G56: -152880
...

Sheet EFM II-C
E8: =+'EFM II'!E8 -> 45473
C17: Internal rate of return
C18: Internal rate of return after incentive allocation | E18: =G99 -> 0.20748523
C19: ROI | E19: =-(G97+J100)/(J99) -> 1.5275372
C21: Sample Investor Ownership Percentage (Pro-rata share of commitments - to calculate fund level amounts divide the cash flows in column G by the ownership % below)
C22: 0.01538501
C23: Contributions 2012 | E23: 41089 | G23: -22500
E24: 41166 | G24: -28224
E25: 41270 | G25: -81984
C26: Contributions 2013 | E26: 41311 | G26: -29232
E27: 41341 | G27: -42000
E28: 41361 | G28: -18816
E29: 41387 | G29: -40992
E30: 41408 | G30: -17640
E31: 41439 | G31: -40824
E32: 41479 | G32: -45192
E33: 41515 | G33: -28392
E34: 41543 | G34: -105840
E35: 41605 | G35: -25032
E36: 41638 | G36: -17976
C37: Contributions 2014 | E37: 41683 | G37: -18480
E38: 41701 | G38: -26880
E39: 41729 | G39: -34608
E40: 41751 | G40: -24360
E41: 41782 | G41: -41496
E42: 41808 | G42: -99624
E43: 41894 | G43: -20832
E44: 41942 | G44: -29568
E45: 41962 | G45: -65688
E46: 41975 | G46: -77280
C47: Distributions 2014 | E47: 41969 | G47: 273860.4
C48: Contributions 2015 | E48: 42037 | G48: -65016.01
E49: 42094 | G49: -56448
E50: 42110 | G50: -47208
E51: 42145 | G51: -58968
E52: 42158 | G52: -169008
E53: 42261 | G53: -127176
E54: 42366 | G54: -31752
C55: Distributions 2015 | E55: 42341 | G55: 48606.68
C56: Contributions 2016 | E56: 42397 | G56: -45864
...

Sheet EFM II-D
E8: =+'EFM II'!E8 -> 45473
C17: Internal rate of return
C18: Internal rate of return after incentive allocation | E18: =G99 -> 0.255703
C19: ROI | E19: =-(G97+J100)/(J99) -> 1.6251946
C21: Sample Investor Ownership Percentage (Pro-rata share of commitments - to calculate fund level amounts divide the cash flows in column G by the ownership % below)
C22: 0.012345679
C23: Contributions 2012 | E23: 41089 | G23: -7500
E24: 41166 | G24: -9408
E25: 41270 | G25: -27328
C26: Contributions 2013 | E26: 41311 | G26: -9744
E27: 41341 | G27: -14000
E28: 41361 | G28: -6272
E29: 41387 | G29: -13664
E30: 41408 | G30: -5880
E31: 41439 | G31: -13608
E32: 41479 | G32: -15064
E33: 41515 | G33: -9464
E34: 41543 | G34: -35280
E35: 41605 | G35: -8344
E36: 41638 | G36: -5992
C37: Contributions 2014 | E37: 41683 | G37: -6160
E38: 41701 | G38: -8960
E39: 41729 | G39: -11536
E40: 41751 | G40: -8120
E41: 41782 | G41: -13832
E42: 41808 | G42: -33208
E43: 41894 | G43: -6944
E44: 41942 | G44: -9856
E45: 41962 | G45: -21896
E46: 41975 | G46: -25760
C47: Distributions 2014 | E47: 41969 | G47: 93993.46
C48: Contributions 2015 | E48: 42037 | G48: -21672
E49: 42094 | G49: -18816
E50: 42110 | G50: -15736
E51: 42145 | G51: -19656
E52: 42158 | G52: -56336
E53: 42261 | G53: -42391.99
E54: 42366 | G54: -10584
C55: Distributions 2015 | E55: 42341 | G55: 15844.88
C56: Contributions 2016 | E56: 42397 | G56: -15288
...

Sheet EFM III
E8: 45473
C17: Internal rate of return
C18: Internal rate of return after incentive allocation | E18: =G129 -> 0.099048942
C19: ROI | E19: =-(G127+I128)/I127 -> 1.4086438
C21: Sample Investor Ownership Percentage (Pro-rata share of commitments - to calculate fund level amounts divide the cash flows in column G by the ownership % below)
C22: 0.0049
C24: Contributions 2014 | E24: 41829 | G24: -169050
E25: 41894 | G25: -87710
E26: 41942 | G26: -46060
E27: 41999 | G27: -65660
C28: Contributions 2015 | E28: 42037 | G28: -64680
E29: 42093 | G29: -83790
E30: 42109 | G30: -62720
E31: 42144 | G31: -36750
E32: 42184 | G32: -56350
E33: 42227 | G33: -74970
E34: 42261 | G34: -98980
E35: 42368 | G35: -80850
C36: Contributions 2016 | E36: 42396 | G36: -1416590
E37: 42445 | G37: -120050
E38: 42549 | G38: -194530
E39: 42586 | G39: -149450
E40: 42607 | G40: -113190
E41: 42613 | G41: -2398550
E42: 42640 | G42: -56350
E43: 42732 | G43: -78400
C44: Distributions 2016 | E44: 42377 | G44: 711402.14
E45: 42551 | G45: 75179.43
E46: 42642 | G46: 140484.82
E47: 42655 | G47: 57417.44
C48: Contributions 2017 | E48: 42765 | G48: -258720
E49: 42822 | G49: -143570
E50: 42852 | G50: -149940
E51: 42913 | G51: -601720
E52: 42991 | G52: -264600
E53: 43006 | G53: -188650
E54: 43080 | G54: -94080
E55: 43095 | G55: -187180
C56: Distributions 2017 | E56: 42747 | G56: 212932.02
C57: Contributions 2018 | E57: 43130 | G57: -1817900
...

Sheet EFM III-C
E8: =+'EFM III'!E8 -> 45473
C17: Internal rate of return
C18: Internal rate of return after incentive allocation | E18: =G129 -> 0.095954689
C19: ROI | E19: =-(G127+I128)/I127 -> 1.4007356
C21: Sample Investor Ownership Percentage (Pro-rata share of commitments - to calculate fund level amounts divide the cash flows in column G by the ownership % below)
C22: 0.017131137
C24: Contributions 2014 | E24: 41829 | G24: -84525
E25: 41894 | G25: -43855
E26: 41942 | G26: -23030
E27: 41999 | G27: -32830
C28: Contributions 2015 | E28: 42037 | G28: -32340
E29: 42093 | G29: -41895
E30: 42109 | G30: -31360
E31: 42144 | G31: -18375
E32: 42184 | G32: -28175
E33: 42227 | G33: -37485
E34: 42261 | G34: -49489.99
E35: 42368 | G35: -40425
C36: Contributions 2016 | E36: 42396 | G36: -708295
E37: 42445 | G37: -60024.99
E38: 42549 | G38: -97265.01
E39: 42586 | G39: -74725
E40: 42607 | G40: -56595.01
E41: 42613 | G41: -1199275
E42: 42640 | G42: -28175
E43: 42732 | G43: -39200
C44: Distributions 2016 | E44: 42377 | G44: 259838.31
E45: 42551 | G45: 74232.03
E46: 42642 | G46: 70073.67
E47: 42655 | G47: 28437.88
C48: Contributions 2017 | E48: 42765 | G48: -129360
E49: 42822 | G49: -71785
E50: 42852 | G50: -74970
E51: 42913 | G51: -300860.01
E52: 42991 | G52: -132300
E53: 43006 | G53: -94325
E54: 43080 | G54: -47040
E55: 43095 | G55: -93590
C56: Distributions 2017 | E56: 42747 | G56: 106466.01
C57: Contributions 2018 | E57: 43130 | G57: -908950
...

Sheet EFM III-D
E8: =+'EFM III'!E8 -> 45473
C17: Internal rate of return
C18: Internal rate of return after incentive allocation | E18: =G128 -> 0.09827463
C19: ROI | E19: =-(G126+I127)/(I126) -> 1.4061929
C21: Sample Investor Ownership Percentage (Pro-rata share of commitments - to calculate fund level amounts divide the cash flows in column G by the ownership % below)
C22: 0.005037783
C24: Contributions 2014 | E24: 41829 | G24: -11269.99
E25: 41894 | G25: -5847.33
E26: 41942 | G26: -3070.67
E27: 41999 | G27: -4377.33
C28: Contributions 2015 | E28: 42037 | G28: -4312
E29: 42093 | G29: -5586
E30: 42109 | G30: -4181.33
E31: 42144 | G31: -2450
E32: 42184 | G32: -3756.67
E33: 42227 | G33: -4998
E34: 42261 | G34: -6598.67
E35: 42368 | G35: -5390
C36: Contributions 2016 | E36: 42396 | G36: -94439.34
E37: 42445 | G37: -8003.34
E38: 42549 | G38: -12968.67
E39: 42586 | G39: -9963.33
E40: 42607 | G40: -7546
E41: 42613 | G41: -159903.33
E42: 42640 | G42: -3756.67
E43: 42732 | G43: -5226.67
C44: Distributions 2016 | E44: 42377 | G44: 47121.98
E45: 42551 | G45: 4861.16
E46: 42642 | G46: 9354.83
E47: 42655 | G47: 3825.81
C48: Contributions 2017 | E48: 42765 | G48: -17248
E49: 42822 | G49: -9571.33
E50: 42852 | G50: -9996
E51: 42913 | G51: -40114.67
E52: 42991 | G52: -17640
E53: 43006 | G53: -12576.67
E54: 43080 | G54: -6272
E55: 43095 | G55: -12478.67
C56: Distributions 2017 | E56: 42747 | G56: 14195.47
C57: Contributions 2018 | E57: 43130 | G57: -121193.33
...

Sheet EFM IV
E8: 45473
C17: Internal rate of return
C18: Internal rate of return after incentive allocation | E18: =G78 -> 0.081090853
C19: ROI | E19: =-(G76+I77)/I76 -> 1.2450086
C21: Sample Investor Ownership Percentage (Pro-rata share of commitments - to calculate fund level amounts divide the cash flows in column G by the ownership % below)
C22: 0.000753846
C24: Contributions 2018 | E24: 43136 | G24: -100336.92
E25: 43193 | G25: -10327.69
E26: 43286 | G26: -9423.08
E27: 43328 | G27: -35355.39
E28: 43369 | G28: -734246.17
E29: 43391 | G29: 196000
E30: 43461 | G30: -12740.01
C31: Contributions 2019 | E31: 43494 | G31: -19675.39
E32: 43622 | G32: -13116.92
E33: 43670 | G33: -19750.78
E34: 43742 | G34: -14323.08
E35: 43794 | G35: -35053.83
E36: 43801 | G36: -67167.69
C37: Distributions 2019 | E37: 43671 | G37: 65298.04
C38: Contributions 2020 | E38: 43859 | G38: -18996.92
E39: 43916 | G39: -18619.99
E40: 44103 | G40: -24047.7
E41: 44126 | G41: -80661.55
C42: Contributions 2021 | E42: 44200 | G42: -13267.7
E43: 44376 | G43: -14323.07
E44: 44466 | G44: -9423.08
E45: 44530 | G45: -18619.99
C46: Distributions 2021 | E46: 44463 | G46: 12662.99
E47: 44484 | G47: 484615.55
E48: 44539 | G48: 39200
C49: Contributions 2022 | E49: 44606 | G49: -237386.15
E50: 44649 | G50: -9423.08
E51: 44672 | G51: -3844.61
E52: 44736 | G52: -30983.07
E53: 44764 | G53: -150090.78
E54: 44819 | G54: -340587.69
E55: 44875 | G55: -16810.77
E56: 44915 | G56: -152880.01
C57: Distributions 2022 | E57: 44615 | G57: 8403.74
...

Sheet EFM IV-C
E8: =+'EFM IV'!E8 -> 45473
C17: Internal rate of return
C18: Internal rate of return after incentive allocation | E18: =G80 -> 0.078237507
C19: ROI | E19: =-(G78+I79)/I78 -> 1.2369182
C21: Sample Investor Ownership Percentage (Pro-rata share of commitments - to calculate fund level amounts divide the cash flows in column G by the ownership % below)
C22: 0.003167063
C24: Contributions 2018 | E24: 43136 | G24: -40134.77
E25: 43193 | G25: -4131.08
E26: 43286 | G26: -3769.23
E27: 43328 | G27: -14142.15
E28: 43369 | G28: -293698.46
E29: 43391 | G29: 78400
E30: 43461 | G30: -5096.01
C31: Contributions 2019 | E31: 43494 | G31: -7870.16
E32: 43622 | G32: -5246.77
E33: 43670 | G33: -7900.31
E34: 43742 | G34: -5729.23
E35: 43794 | G35: -14021.53
E36: 43801 | G36: -26867.08
C37: Distributions 2019 | E37: 43671 | G37: 25873.43
C38: Contributions 2020 | E38: 43859 | G38: -7598.78
E39: 43916 | G39: -7447.99
E40: 44103 | G40: -9619.08
E41: 44126 | G41: -32264.62
C42: Contributions 2021 | E42: 44200 | G42: -5307.07
E43: 44376 | G43: -5729.22
E44: 44466 | G44: -3769.23
E45: 44530 | G45: -7448.01
C46: Distributions 2021 | E46: 44463 | G46: 4310.1
E47: 44484 | G47: 190670.31
E48: 44539 | G48: 15666.13
C49: Contributions 2022 | E49: 44606 | G49: -94954.46
E50: 44649 | G50: -3769.23
E51: 44672 | G51: -1537.85
E52: 44736 | G52: -12393.23
E53: 44764 | G53: -60036.31
E54: 44819 | G54: -136235.06
E55: 44875 | G55: -6724.31
E56: 44915 | G56: -61152.01
C57: Distributions 2022 | E57: 44615 | G57: 3257.23
...

Sheet EFM IV-D
E8: =+'EFM IV'!E8 -> 45473
C17: Internal rate of return
C18: Internal rate of return after incentive allocation | E18: =G79 -> 0.080467638
C19: ROI | E19: =-(G77+I78)/(I77) -> 1.2431521
C21: Sample Investor Ownership Percentage (Pro-rata share of commitments - to calculate fund level amounts divide the cash flows in column G by the ownership % below)
C22: 0.017458101
C24: Contributions 2018 | E24: 43136 | G24: -200673.85
E25: 43193 | G25: -20655.39
E26: 43286 | G26: -18846.15
E27: 43328 | G27: -70710.78
E28: 43369 | G28: -1468492.3
E29: 43391 | G29: 392000
E30: 43461 | G30: -25480
C31: Contributions 2019 | E31: 43494 | G31: -39350.78
E32: 43622 | G32: -26233.85
E33: 43670 | G33: -39501.54
E34: 43742 | G34: -28646.15
E35: 43794 | G35: -70107.7
E36: 43801 | G36: -134335.38
C37: Distributions 2019 | E37: 43671 | G37: 129646.89
C38: Contributions 2020 | E38: 43859 | G38: -37993.85
E39: 43916 | G39: -37240
E40: 44103 | G40: -48095.38
E41: 44126 | G41: -161323.07
C42: Contributions 2021 | E42: 44200 | G42: -26535.39
E43: 44376 | G43: -28646.16
E44: 44466 | G44: -18846.15
E45: 44530 | G45: -37240.01
C46: Distributions 2021 | E46: 44463 | G46: 22626.91
E47: 44484 | G47: 969199.17
E48: 44539 | G48: 78313.97
C49: Contributions 2022 | E49: 44606 | G49: -474772.3
E50: 44649 | G50: -18846.15
E51: 44672 | G51: -7689.23
E52: 44736 | G52: -61966.16
E53: 44764 | G53: -300181.54
E54: 44819 | G54: -681175.39
E55: 44875 | G55: -33621.54
E56: 44915 | G56: -305760
C57: Distributions 2022 | E57: 44615 | G57: 16557.02
...

Sheet EFM V
E8: 45473
C17: Internal rate of return
C18: Internal rate of return after incentive allocation | E18: =G41 -> 0.15559234
C19: ROI | E19: =-(G39+I40)/I39 -> 1.1517562
C21: Sample Investor Ownership Percentage (Pro-rata share of commitments - to calculate fund level amounts divide the cash flows in column G by the ownership % below)
C22: 1
C24: Contributions 2023 | E24: 44950 | G24: -76575350
E25: 44988 | G25: -7249182.5
E26: 45027 | G26: -8628801
E27: 45048 | G27: -95262250
E28: 45114 | G28: -9451875
E29: 45132 | G29: =-10162729.06+590732.39 -> -9571996.7
E30: 45163 | G30: -36731041
E31: 45233 | G31: -14518860
E32: 45251 | G32: -39026731
E33: 45282 | G33: -10386618
C34: Contributions 2023 | E34: 45345 | G34: -5509656.2
E35: 45362 | G35: -34435351
E36: 45392 | G36: -3040410.1
E37: 45450 | G37: -3841666.7
C39: Net assets | E39: =+E8 -> 45473 | G39: =L39 -> 407986370 | I39: =+SUMIF($G$24:$G$38,"<0",$G$24:$G$38) -> -3.5422979e+08 | J39: check figure-Contributions | L39: 407986370
I40: =+SUMIF($G$24:$G$38,">0",$G$24:$G$38) -> 0 | J40: check figure-Distributions
C41: Total return | G41: =+XIRR(G24:G39,E24:E39,0.01) -> 0.15559234
