Workbook
Name CQ: '[1]Roll-Forward Dates'!$C$124
Name CQ_and_PY_Date: '[1]Roll-Forward Dates'!$C$153
Name CQ_CAPS: '[1]Roll-Forward Dates'!$C$125
Name CQ_Comparative: '[1]Roll-Forward Dates'!$C$148
Name CY_FiHis_ETFA: #REF!
Name CY_FiHis_ETFB: #REF!
Name CY_FiHis_ETFC: #REF!
Name CY_FiHis_ETFCIA: #REF!
Name CY_FiHis_ETFCIB: #REF!
Name CY_FiHis_ETFCIC: #REF!
Name CY_FiHis_ETFCIE: #REF!
Name CY_FiHis_ETFCombined: #REF!
Name CY_FiHis_ETFE: #REF!
Name CY_FiHis_ETFSCA: #REF!
Name CY_FiHis_ETFSCB: #REF!
Name CY_FiHis_ETFSCC: #REF!
Name CY_FiHis_FF1: 'Fund X-C'!$C$163:$E$174
Name CY_FiHis_FF2: 'Fund X-D'!$C$163:$E$174
Name CY_FiHis_FF3: 'VIII-D'!$C$146:$E$157
Name CY_FiHis_MF: 'Fund X'!$C$163:$E$174
Name CYTD: '[1]Roll-Forward Dates'!$C$147
Name CYTD_and_YE_PY_Date: '[1]Roll-Forward Dates'!$C$152
Name FS_Stm_Oprations: [1]Inc!$A$7:$C$30
Name Period_05: '[1]Roll-Forward Dates'!$C$126
Name PY: '[1]Roll-Forward Dates'!$C$122
Name PY_Date: '[1]Roll-Forward Dates'!$C$140

Sheet Combined A Funds
B4: Financial Highlights EETF - Combined A Funds
E8: 44561 | I8: INPUT CELLS
G9: INPUT CELLS | I9: =29562500/35776020.41 -> 0.82632164 | J9: INPUT CELLS
C10: Net investment income/loss | E10: =I10/(J33) -> #DIV/0! | G10: =0-129939-241022 -> -370961 | I10: =(G10*$I$9)+J10 -> -752400.1 | J10: -445867 | K10: Mgmt fees
C12: Expense ratios
C13: Operating expenses | E13: =I13/(J33) -> #DIV/0! | G13: =129939+241022 -> 370961 | I13: =G13*$I$9+J13 -> 752400.1 | J13: =-J10 -> 445867
C14: Incentive allocation | E14: =(I14)/(J33) -> #DIV/0! | G14: 0 | I14: =G14*$I$9 -> 0
C15: Total expenses and incentive allocation | E15: =E13+E14 -> #DIV/0!
C17: Internal rate of return
C18: Internal rate of return after incentive allocation | E18: =G68 -> #REF!
C19: ROI | E19: =-(G66+I67)/I66 -> #REF!
J20: INPUT CELLS
J21: =L21+M21+N21+O21+P21+Q21+R21+S21+T21+U21+V21 -> 0 | K21: Jan
J22: =L22+M22+N22+O22+P22+Q22+R22+S22+T22+U22+V22 -> 0 | K22: Feb
J23: =L23+M23+N23+O23+P23+Q23+R23+S23+T23+U23+V23 -> 0 | K23: Mar
C24: Contributions | E24: 43857 | G24: -693875 | J24: =L24+M24+N24+O24+P24+Q24+R24+S24+T24+U24+V24 -> 0 | K24: Apr
C25: All Activity pasted in from subsequent tabs | E25: 43985 | G25: -7416500 | J25: =L25+M25+N25+O25+P25+Q25+R25+S25+T25+U25+V25 -> 0 | K25: May
E26: 44076 | G26: -4382625 | J26: =L26+M26+N26+O26+P26+Q26+R26+S26+T26+U26+V26 -> 0 | K26: Jun
E27: 44141 | G27: -3082950 | J27: =L27+M27+N27+O27+P27+Q27+R27+S27+T27+U27+V27 -> 0 | K27: Jul
E28: 44148 | G28: -7275862.5 | J28: =L28+M28+N28+O28+P28+Q28+R28+S28+T28+U28+V28 -> 0 | K28: Aug
E29: 44187 | G29: -1892000 | J29: =L29+M29+N29+O29+P29+Q29+R29+S29+T29+U29+V29 -> 0 | K29: Sep
E30: 44203 | G30: -24296301 | J30: =L30+M30+N30+O30+P30+Q30+R30+S30+T30+U30+V30 -> 0 | K30: Oct
E31: 44250 | G31: 5859033.8 | J31: =L31+M31+N31+O31+P31+Q31+R31+S31+T31+U31+V31 -> 0 | K31: Nov
E32: 44265 | G32: -20755762 | J32: =L32+M32+N32+O32+P32+Q32+R32+S32+T32+U32+V32 -> 0 | K32: Dec
E33: 44291 | G33: -29642140 | J33: =SUM(J21:J32)/12 -> 0 | K33: AVG NAV
E34: 44307 | G34: -35880618
E35: 44319 | G35: 37809430
E36: 44335 | G36: -4205628.6
E37: 44344 | G37: 20268178
E38: 44375 | G38: -6218476.1
E39: 44405 | G39: -3521086
E40: 44468 | G40: -1653652.9
E41: 44148 | G41: -2425287.5
E42: 44187 | G42: -200800
E43: 44203 | G43: -7819766.9
E44: 44250 | G44: 1248011.3
E45: 44265 | G45: -4375937.5
... E60: 44375 | G60: -2219396.2
C66: Net assets | E66: =+E8 -> 44561 | G66: =#REF!+#REF!+#REF! -> #REF! | I66: =SUM(G24:G60) -> -1.4833891e+08 | J66: check figure-Contributions
I67: 0 | J67: check figure-Distributions
...

Sheet Combined A Hypo
B4: Financial Highlights EETF - Combined A Funds (Hypothetical CFs)
E8: 44561 | I8: INPUT CELLS
G9: INPUT CELLS | I9: =29562500/35776020.41 -> 0.82632164 | J9: INPUT CELLS
C10: Net investment income/loss | E10: =I10/(J33) -> #DIV/0! | G10: =0-129939-241022 -> -370961 | I10: =(G10*$I$9)+J10 -> -752400.1 | J10: -445867 | K10: Mgmt fees
C12: Expense ratios
C13: Operating expenses | E13: =I13/(J33) -> #DIV/0! | G13: =129939+241022 -> 370961 | I13: =G13*$I$9+J13 -> 752400.1 | J13: =-J10 -> 445867
C14: Incentive allocation | E14: =(I14)/(J33) -> #DIV/0! | G14: 0 | I14: =G14*$I$9 -> 0
C15: Total expenses and incentive allocation | E15: =E13+E14 -> #DIV/0!
C17: Internal rate of return
C18: Internal rate of return after incentive allocation | E18: =G87 -> #REF!
C19: ROI | E19: =-(G85+I86)/I85 -> #REF!
J20: INPUT CELLS
J21: =L21+M21+N21+O21+P21+Q21+R21+S21+T21+U21+V21 -> 0 | K21: Jan
J22: =L22+M22+N22+O22+P22+Q22+R22+S22+T22+U22+V22 -> 0 | K22: Feb
J23: =L23+M23+N23+O23+P23+Q23+R23+S23+T23+U23+V23 -> 0 | K23: Mar
C24: Contributions | E24: 43857 | G24: -7574109.8 | J24: =L24+M24+N24+O24+P24+Q24+R24+S24+T24+U24+V24 -> 0 | K24: Apr
C25: All Activity pasted in from subsequent tabs | E25: 43985 | G25: -8109565.2 | J25: =L25+M25+N25+O25+P25+Q25+R25+S25+T25+U25+V25 -> 0 | K25: May
E26: 44076 | G26: -9256083.2 | J26: =L26+M26+N26+O26+P26+Q26+R26+S26+T26+U26+V26 -> 0 | K26: Jun
E27: 44117 | G27: -9231367.2 | J27: =L27+M27+N27+O27+P27+Q27+R27+S27+T27+U27+V27 -> 0 | K27: Jul
E28: 44141 | G28: -8243800.9 | J28: =L28+M28+N28+O28+P28+Q28+R28+S28+T28+U28+V28 -> 0 | K28: Aug
E29: 44148 | G29: -4300137.9 | J29: =L29+M29+N29+O29+P29+Q29+R29+S29+T29+U29+V29 -> 0 | K29: Sep
E30: 44187 | G30: -3920928.2 | J30: =L30+M30+N30+O30+P30+Q30+R30+S30+T30+U30+V30 -> 0 | K30: Oct
E31: 44203 | G31: -16776927 | J31: =L31+M31+N31+O31+P31+Q31+R31+S31+T31+U31+V31 -> 0 | K31: Nov
E32: 44217 | G32: -2194068.1 | J32: =L32+M32+N32+O32+P32+Q32+R32+S32+T32+U32+V32 -> 0 | K32: Dec
E33: 44250 | G33: 7925754.3 | J33: =SUM(J21:J32)/12 -> 0 | K33: AVG NAV
E34: 44265 | G34: -4940200.2
E35: 44291 | G35: -11743015
E36: 44307 | G36: -26632769
E37: 44319 | G37: 26987928
E38: 44335 | G38: -12755537
E39: 44344 | G39: 14731457
E40: 44361 | G40: 445749.22
E41: 44375 | G41: -6218476.1
E42: 44405 | G42: -3521086
E43: 44468 | G43: -1653652.9
E44: 43857 | G44: -1916207.2
E45: 43985 | G45: -2051674.4
... E73: 44250 | G73: 4272371.4
E74: 44265 | G74: =-2252124.74360582-327074.700190716 -> -2579199.4
E75: 44291 | G75: -6226211.2
...

Sheet ETF Main Co A funds hypo
B4: Financial Highlights EETF I-A
C8: Internal rate of return
C9: Internal rate of return after incentive allocation | E9: =G43 -> #REF!
C10: ROI | E10: =-(G41+I42)/I41 -> #REF!
C15: Contributions 2020 | E15: 43857 | G15: ='EETF I-A'!G24+'EETF Co Inv I-A Hypo'!G21 -> -9490317
E16: 43985 | G16: ='EETF I-A'!G25+'EETF Co Inv I-A Hypo'!G22 -> -10161240
E17: 44076 | G17: ='EETF I-A'!G26+'EETF Co Inv I-A Hypo'!G23 -> -11185362
E18: 44117 | G18: ='EETF I-A'!G27+'EETF Co Inv I-A Hypo'!G24 -> -11566851
E19: 44141 | G19: ='EETF I-A'!G28+'EETF Co Inv I-A Hypo'!G25 -> -10329436
E20: 44148 | G20: ='EETF I-A'!G29+'EETF Co Inv I-A Hypo'!G26 -> -5388048.7
E21: 44187 | G21: ='EETF I-A'!G30+'EETF Co Inv I-A Hypo'!G27 -> -4849321.5
C22: Contributions 2021 | E22: 44203 | G22: ='EETF I-A'!G31+'EETF Co Inv I-A Hypo'!G28 -> -20915253
E23: 44217 | G23: ='EETF I-A'!G32+'EETF Co Inv I-A Hypo'!G29 -> -2749155
E24: 44250 | G24: ='EETF I-A'!G33+'EETF Co Inv I-A Hypo'!G30 -> 9930925.6
E25: 44265 | G25: ='EETF I-A'!G34+'EETF Co Inv I-A Hypo'!G31 -> -6156511.2
E26: 44291 | G26: ='EETF I-A'!G35+'EETF Co Inv I-A Hypo'!G32 -> -14655944
E27: 44307 | G27: ='EETF I-A'!G36+'EETF Co Inv I-A Hypo'!G33 -> -33199163
E28: 44319 | G28: ='EETF I-A'!G37+'EETF Co Inv I-A Hypo'!G34 -> 33815722
E29: 44335 | G29: ='EETF I-A'!G38+'EETF Co Inv I-A Hypo'!G35 -> -15883947
E30: 44344 | G30: ='EETF I-A'!G39+'EETF Co Inv I-A Hypo'!G36 -> 18458433
E31: 44361 | G31: ='EETF I-A'!G40+'EETF Co Inv I-A Hypo'!G37 -> 541321.57
E32: 44375 | G32: ='EETF I-A'!G41+'EETF Co Inv I-A Hypo'!G38 -> -7483634.6
E33: 44405 | G33: ='EETF I-A'!G42+'EETF Co Inv I-A Hypo'!G39 -> -4410936.6
E34: 44468 | G34: ='EETF I-A'!G43+'EETF Co Inv I-A Hypo'!G40 -> -1935800.6
... E39: 44558 | G39: ='EETF I-A'!G48+'EETF Co Inv I-A Hypo'!G45 -> 51543245
C41: Net assets | E41: 44561 | G41: ='EETF I-A'!G69+'EETF Co Inv I-A Hypo'!G49 -> #REF! | I41: =+SUMIF($G$15:$G$40,"<0",$G$15:$G$40)+G24+G28+G30+G31 -> -1.2697116e+08 | J41: check figure-Contributions
I42: =+SUMIF($G$15:$G$40,">0",$G$15:$G$40)-G24-G28-G30-G31 -> 51543245 | J42: check figure-Distributions
C43: Total return | G43: =+XIRR(G15:G41,E15:E41,0.1) -> #REF!

Sheet ETF A funds Combined hypo
B4: Financial Highlights EETF I-A
C8: Internal rate of return
C9: Internal rate of return after incentive allocation | E9: =G45 -> #REF!
C10: ROI | E10: =-(G43+I44)/I43 -> #REF!
C15: Contributions 2020 | E15: 43857 | G15: ='EETF I-A'!G24+'EETF Co Inv I-A Hypo'!G21+'EETF Sidecar I-A Hypo'!G21 -> -13573135
E16: 43985 | G16: ='EETF I-A'!G25+'EETF Co Inv I-A Hypo'!G22+'EETF Sidecar I-A Hypo'!G22 -> -14532694
E17: 44076 | G17: ='EETF I-A'!G26+'EETF Co Inv I-A Hypo'!G23+'EETF Sidecar I-A Hypo'!G23 -> -15143927
E18: 44117 | G18: ='EETF I-A'!G27+'EETF Co Inv I-A Hypo'!G24+'EETF Sidecar I-A Hypo'!G24 -> -16543012
E19: 44141 | G19: ='EETF I-A'!G28+'EETF Co Inv I-A Hypo'!G25+'EETF Sidecar I-A Hypo'!G25 -> -14773250
E20: 44148 | G20: ='EETF I-A'!G29+'EETF Co Inv I-A Hypo'!G26+'EETF Sidecar I-A Hypo'!G26 -> -7706034.5
E21: 44187 | G21: ='EETF I-A'!G30+'EETF Co Inv I-A Hypo'!G27+'EETF Sidecar I-A Hypo'!G27 -> -6803980.6
C22: Contributions 2021 | E22: 44203 | G22: ='EETF I-A'!G31+'EETF Co Inv I-A Hypo'!G28+'EETF Sidecar I-A Hypo'!G28 -> -29693544
E23: 44217 | G23: ='EETF I-A'!G32+'EETF Co Inv I-A Hypo'!G29+'EETF Sidecar I-A Hypo'!G29 -> -3972951
E24: 44250 | G24: ='EETF I-A'!G33+'EETF Co Inv I-A Hypo'!G30+'EETF Sidecar I-A Hypo'!G30 -> 14203297
E25: 44265 | G25: ='EETF I-A'!G34+'EETF Co Inv I-A Hypo'!G31+'EETF Sidecar I-A Hypo'!G31 -> -8735710.6
E26: 44291 | G26: ='EETF I-A'!G35+'EETF Co Inv I-A Hypo'!G32+'EETF Sidecar I-A Hypo'!G32 -> -20882156
E27: 44307 | G27: ='EETF I-A'!G36+'EETF Co Inv I-A Hypo'!G33+'EETF Sidecar I-A Hypo'!G33 -> -47126760
E28: 44319 | G28: ='EETF I-A'!G37+'EETF Co Inv I-A Hypo'!G34+'EETF Sidecar I-A Hypo'!G34 -> 48363543
E29: 44335 | G29: ='EETF I-A'!G38+'EETF Co Inv I-A Hypo'!G35+'EETF Sidecar I-A Hypo'!G35 -> -22513190
E30: 44344 | G30: ='EETF I-A'!G39+'EETF Co Inv I-A Hypo'!G36+'EETF Sidecar I-A Hypo'!G36 -> 26399413
E31: 44361 | G31: ='EETF I-A'!G40+'EETF Co Inv I-A Hypo'!G37+'EETF Sidecar I-A Hypo'!G37 -> 744955.32
E32: 44375 | G32: ='EETF I-A'!G41+'EETF Co Inv I-A Hypo'!G38+'EETF Sidecar I-A Hypo'!G38 -> -9703030.8
E33: 44405 | G33: ='EETF I-A'!G42+'EETF Co Inv I-A Hypo'!G39 -> -4410936.6
E34: 44468 | G34: ='EETF I-A'!G43+'EETF Co Inv I-A Hypo'!G40 -> -1935800.6
E35: 44475 | G35: ='EETF I-A'!G44+'EETF Co Inv I-A Hypo'!G41+'EETF Sidecar I-A Hypo'!G39 -> -7188775.3
E36: 44483 | G36: ='EETF I-A'!G45+'EETF Co Inv I-A Hypo'!G42+'EETF Sidecar I-A Hypo'!G40 -> -6315014.1
E37: 44505 | G37: ='EETF I-A'!G46+'EETF Co Inv I-A Hypo'!G43+'EETF Sidecar I-A Hypo'!G41 -> -7363013.7
E38: 44551 | G38: ='EETF I-A'!G47+'EETF Co Inv I-A Hypo'!G44+'EETF Sidecar I-A Hypo'!G42 -> -4273521.1
C39: Distributions 2021 | E39: 44558 | G39: ='EETF I-A'!G48+'EETF Co Inv I-A Hypo'!G45+'EETF Sidecar I-A Hypo'!G43 -> 72289581
C40: Contributions 2022 | E40: 44599 | G40: ='EETF I-A'!G49+'EETF Co Inv I-A Hypo'!G46 -> -2191169.5
E41: 44635 | G41: ='EETF I-A'!G50+'EETF Co Inv I-A Hypo'!G47+'EETF Sidecar I-A Hypo'!G44 -> -8436152.7
C43: Net assets | E43: =#REF! -> #REF! | G43: ='EETF I-A'!G69+'EETF Co Inv I-A Hypo'!G49+'EETF Sidecar I-A Hypo'!G46 -> #REF! | I43: =+SUMIF($G$15:$G$42,"<0",$G$15:$G$42)+G24+G28+G30+G31 -> -1.8410655e+08 | J43: check figure-Contributions | K43: =I43-('EETF I-A'!I69+'EETF Co Inv I-A Hypo'!I49+'EETF Sidecar I-A Hypo'!I46) -> 75025771 | L43: =I43-(#REF!+#REF!+#REF!) -> #REF!
I44: =+SUMIF($G$15:$G$42,">0",$G$15:$G$42)-G24-G28-G30-G31 -> 72289581 | J44: check figure-Distributions | K44: =I44-('EETF I-A'!I70+'EETF Co Inv I-A Hypo'!I50+'EETF Sidecar I-A Hypo'!I47) -> -90628832 | L44: =I44-(#REF!+#REF!+#REF!) -> #REF!
C45: Total return | G45: =+XIRR(G15:G43,E15:E43,0.1) -> #REF!

Sheet Actual Hypo %s
B6: A | C6: B | D6: C* | E6: E | F6: CIA | G6: CIB | H6: CIC* | I6: CIE | J6: SCA | K6: SCB | L6: SCC*
A7: Total LP - Actual | B7: =#REF! -> #REF! | C7: =#REF! -> #REF! | D7: =#REF! -> #REF! | E7: =#REF! -> #REF! | F7: =#REF! -> #REF! | G7: =#REF! -> #REF! | H7: =#REF! -> #REF! | I7: =#REF! -> #REF! | ... L7: =#REF! -> #REF!
A8: Total LP - Hypo | B8: ='EETF I-A'!G71 -> 0.25984918 | C8: ='EETF I-B hypo'!G52 -> 0.37967424 | D8: ='EETF I-C hypo'!G52 -> 0.27906733 | E8: ='EETF I-E hypo'!G52 -> 0.38163324 | F8: ='EETF Co Inv I-A Hypo'!G51 -> #REF! | G8: ='EETF Co Inv I-B hypo'!G49 -> #REF! | H8: ='EETF Co Inv I-C hypo'!G49 -> #REF! | I8: ='EETF Co Inv I-E hypo'!G49 -> #REF! | J8: ='EETF Sidecar I-A Hypo'!G48 -> #REF! | K8: ='EETF Sidecar I-B hypo'!G47 -> #REF! | L8: ='EETF Sidecar I-C hypo'!G47 -> #REF!
A9: * Note Broad Reach tax provision only impacts the C funds

Sheet EETF I-A w INT
B4: Financial Highlights EETF I-A
E8: 44561 | I8: INPUT CELLS
G9: INPUT CELLS | I9: =29562500/35776020.41 -> 0.82632164 | J9: INPUT CELLS
C10: Net investment income/loss | E10: =I10/(J33) -> -0.051530979 | G10: =0-129939-241022 -> -370961 | I10: =(G10*$I$9)+J10 -> -752400.1 | J10: -445867 | K10: Mgmt fees
C12: Expense ratios
C13: Operating expenses | E13: =I13/(J33) -> 0.051530979 | G13: =129939+241022 -> 370961 | I13: =G13*$I$9+J13 -> 752400.1 | J13: =-J10 -> 445867
C14: Incentive allocation | E14: =(I14)/(J33) -> 0 | G14: 0 | I14: =G14*$I$9 -> 0
C15: Total expenses and incentive allocation | E15: =E13+E14 -> 0.051530979
C17: Internal rate of return
C18: Internal rate of return after incentive allocation | E18: =G55 -> 0.44265724
C19: ROI | E19: =-(G53+I54)/I53 -> 1.3823748
J20: INPUT CELLS
J21: =693875 -> 693875 | K21: Jan
J22: =693875 -> 693875 | K22: Feb
J23: =674251 -> 674251 | K23: Mar
C24: Contributions 2020 | E24: 43857 | G24: -693875 | J24: =662813 -> 662813 | K24: Apr
E25: 43985 | G25: -7416500 | J25: =550875 -> 550875 | K25: May
E26: 44076 | G26: -4382625 | J26: =7912747 -> 7912747 | K26: Jun
E27: 44141 | G27: -3082950 | J27: =7837185 -> 7837185 | K27: Jul
E28: 44148 | G28: -7275862.5 | J28: =7837185 -> 7837185 | K28: Aug
E29: 44187 | G29: -1892000 | J29: =12208967 -> 12208967 | K29: Sep
C30: Contributions 2021 | E30: 44203 | G30: -24296301 | J30: =12133404 -> 12133404 | K30: Oct
E31: 44250 | G31: 5859033.8 | J31: =21943654 -> 21943654 | K31: Nov
E32: 44265 | G32: -20755762 | J32: =G53 -> 102062302 | K32: Dec
E33: 44291 | G33: -29642140 | J33: =SUM(J21:J32)/12 -> 14600928 | K33: AVG NAV
E34: 44307 | G34: -35880618
E35: 44319 | G35: 37809430
E36: 44335 | G36: -4205628.6
E37: 44344 | G37: =20268177.93+830538.11-1675268.66 -> 19423447
E38: 44375 | G38: =-6218476.1-209162.1 -> -6427638.2
E39: 44405 | G39: -3521086
E40: 44468 | G40: -1653652.9
E41: 44475 | G41: -4024098.3
E42: 44483 | G42: -4703164.9
E43: 44505 | G43: -4225303.2
E44: 44551 | G44: -2584225.6
E45: 44558 | G45: 41112360
C53: Net assets | E53: =+E8 -> 44561 | G53: 102062302 | I53: =+SUMIF($G$24:$G$52,"<0",$G$24:$G$52)+G31+G35+G37 -> -1.0357152e+08 | J53: check figure-Contributions
I54: =+SUMIF($G$24:$G$52,">0",$G$24:$G$52)-G31-G35-G37 -> 41112360 | J54: check figure-Distributions
C55: Total return | G55: =+XIRR(G24:G53,E24:E53,0.1) -> 0.44265724
...

Sheet EETF I-A 1st close LP
B4: Financial Highlights EETF I-A
E8: 44561 | I8: INPUT CELLS
G9: INPUT CELLS | I9: =29562500/35776020.41 -> 0.82632164 | J9: INPUT CELLS
C10: Net investment income/loss | E10: =I10/(J33) -> -0.12254834 | G10: =0-129939-241022 -> -370961 | I10: =(G10*$I$9)+J10 -> -752400.1 | J10: -445867 | K10: Mgmt fees
C12: Expense ratios
C13: Operating expenses | E13: =I13/(J33) -> 0.12254834 | G13: =129939+241022 -> 370961 | I13: =G13*$I$9+J13 -> 752400.1 | J13: =-J10 -> 445867
C14: Incentive allocation | E14: =(I14)/(J33) -> 0 | G14: 0 | I14: =G14*$I$9 -> 0
C15: Total expenses and incentive allocation | E15: =E13+E14 -> 0.12254834
C17: Internal rate of return
C18: Internal rate of return after incentive allocation | E18: =G45 -> 0.19971798
C19: ROI | E19: =-(G43+I50)/I49 -> 1.3965858
J20: INPUT CELLS
J21: =693875 -> 693875 | K21: Jan
C22: Serapis | J22: =693875 -> 693875 | K22: Feb
J23: =674251 -> 674251 | K23: Mar
C24: Contributions 2020 | E24: 43857 | G24: -227500 | J24: =662813 -> 662813 | K24: Apr
E25: 43985 | G25: -175000 | J25: =550875 -> 550875 | K25: May
E26: 44076 | G26: -217500 | J26: =7912747 -> 7912747 | K26: Jun
E27: 44141 | G27: -153000 | J27: =7837185 -> 7837185 | K27: Jul
E28: 44187 | G28: -64000 | J28: =7837185 -> 7837185 | K28: Aug
C29: Contributions 2021 | E29: 44250 | G29: 100000 | J29: =12208967 -> 12208967 | K29: Sep
E30: 44319 | G30: 237000 | J30: =12133404 -> 12133404 | K30: Oct
E31: 44344 | G31: 110000 | J31: =21943654 -> 21943654 | K31: Nov
E32: 44375 | G32: -32084.7 | J32: =G43 -> 526598.12 | K32: Dec
E33: 44405 | G33: -18167.31 | J33: =SUM(J21:J32)/12 -> 6139619.1 | K33: AVG NAV
E34: 44468 | G34: -8532.15
E35: 44475 | G35: -20762.64
E36: 44483 | G36: -24266.33
E37: 44505 | G37: -21800.77
E38: 44551 | G38: -13333.51
E39: 44558 | G39: 212122.31
C43: Net assets | E43: =+E8 -> 44561 | G43: 526598.12
C45: Total return | G45: =+XIRR(G24:G43,E24:E43,0.1) -> 0.19971798
I49: =+SUMIF($G$24:$G$42,"<0",$G$24:$G$42)+G29+G30+G31 -> -528947.41 | J49: check figure-Contributions
I50: =+SUMIF($G$24:$G$42,">0",$G$24:$G$42)-G29-G30-G31 -> 212122.31 | J50: check figure-Distributions
C54: Net investment loss ratio | E54: =E10 -> -0.12254834
C56: Expense ratios:
C57: Operating expenses | E57: =E13 -> 0.12254834
C58: Unearned incentive allocation | E58: =E14 -> 0
C59: Operating expenses and unearned incentive allocation ratio | E59: =SUM(E57:E58) -> 0.12254834
...

Sheet EETF I-A 1st close LP w INT
B4: Financial Highlights EETF I-A
E8: 44561 | I8: INPUT CELLS
G9: INPUT CELLS | I9: =29562500/35776020.41 -> 0.82632164 | J9: INPUT CELLS
C10: Net investment income/loss | E10: =I10/(J33) -> -0.12254834 | G10: =0-129939-241022 -> -370961 | I10: =(G10*$I$9)+J10 -> -752400.1 | J10: -445867 | K10: Mgmt fees
C12: Expense ratios
C13: Operating expenses | E13: =I13/(J33) -> 0.12254834 | G13: =129939+241022 -> 370961 | I13: =G13*$I$9+J13 -> 752400.1 | J13: =-J10 -> 445867
C14: Incentive allocation | E14: =(I14)/(J33) -> 0 | G14: 0 | I14: =G14*$I$9 -> 0
C15: Total expenses and incentive allocation | E15: =E13+E14 -> 0.12254834
C17: Internal rate of return
C18: Internal rate of return after incentive allocation | E18: =G45 -> 0.23668283
C19: ROI | E19: =-(G43+I50)/I49 -> 1.5016662
J20: INPUT CELLS
J21: =693875 -> 693875 | K21: Jan
C22: Serapis | J22: =693875 -> 693875 | K22: Feb
J23: =674251 -> 674251 | K23: Mar
C24: Contributions 2020 | E24: 43857 | G24: -227500 | J24: =662813 -> 662813 | K24: Apr
E25: 43985 | G25: -175000 | J25: =550875 -> 550875 | K25: May
E26: 44076 | G26: -217500 | J26: =7912747 -> 7912747 | K26: Jun
E27: 44141 | G27: -153000 | J27: =7837185 -> 7837185 | K27: Jul
E28: 44187 | G28: -64000 | J28: =7837185 -> 7837185 | K28: Aug
C29: Contributions 2021 | E29: 44250 | G29: 100000 | J29: =12208967 -> 12208967 | K29: Sep
E30: 44319 | G30: 237000 | J30: =12133404 -> 12133404 | K30: Oct
E31: 44344 | G31: =110000+37013.57 -> 147013.57 | J31: =21943654 -> 21943654 | K31: Nov
E32: 44375 | G32: -32084.7 | J32: =G43 -> 526598.12 | K32: Dec
E33: 44405 | G33: -18167.31 | J33: =SUM(J21:J32)/12 -> 6139619.1 | K33: AVG NAV
E34: 44468 | G34: -8532.15
E35: 44475 | G35: -20762.64
E36: 44483 | G36: -24266.33
E37: 44505 | G37: -21800.77
E38: 44551 | G38: -13333.51
E39: 44558 | G39: 212122.31
C43: Net assets | E43: =+E8 -> 44561 | G43: 526598.12
C45: Total return | G45: =+XIRR(G24:G43,E24:E43,0.1) -> 0.23668283
I49: =+SUMIF($G$24:$G$42,"<0",$G$24:$G$42)+G29+G30+G31 -> -491933.84 | J49: check figure-Contributions
I50: =+SUMIF($G$24:$G$42,">0",$G$24:$G$42)-G29-G30-G31 -> 212122.31 | J50: check figure-Distributions
C54: Net investment loss ratio | E54: =E10 -> -0.12254834
C56: Expense ratios:
C57: Operating expenses | E57: =E13 -> 0.12254834
C58: Unearned incentive allocation | E58: =E14 -> 0
C59: Operating expenses and unearned incentive allocation ratio | E59: =SUM(E57:E58) -> 0.12254834
...

Sheet VIII
E8: 45107
C17: Internal rate of return
C18: Internal rate of return after incentive allocation | E18: =G138 -> 0.0053216249
C19: ROI | E19: =(G136+I137)/-I136 -> 1.0259583
C21: Sample Investor Ownership Percentage (Pro-rata share of commitments - to calculate fund level amounts divide the cash flows in column G by the ownership % below)
C22: 0.000831429
C23: Contributions 2010 | E23: 40512 | G23: -63000
C24: Contributions 2011 | E24: 40570 | G24: -31500
E25: 40661 | G25: -24194.61
E26: 40704 | G26: -38162.64
E27: 40751 | G27: -36499.78
E28: 40765 | G28: -60694.39
E29: 40813 | G29: -53460.95
E30: 40879 | G30: -25691.19
E31: 40886 | G31: -35003.2
C32: Contributions 2012 | E32: 40927 | G32: -58532.67
E33: 40942 | G33: -274371.9
E34: 40970 | G34: -43650.08
E35: 41001 | G35: -25524.9
E36: 41024 | G36: -30264.05
E37: 41054 | G37: -39409.78
E38: 41080 | G38: -73082.7
E39: 41103 | G39: -23695.76
E40: 41121 | G40: -22864.33
E41: 41152 | G41: -30264
E42: 41180 | G42: -57368.58
E43: 41194 | G43: -28185.43
E44: 41250 | G44: -127125.41
E45: 41264 | G45: -112908
C46: Distribution 2012 | E46: 41030 | G46: 112056.47
E47: 41108 | G47: 24215.98
E48: 41137 | G48: 10363.64
E49: 41173 | G49: 223637.66
C50: Contributions 2013 | E50: 41284 | G50: -33340.28
E51: 41298 | G51: -42652.29
E52: 41345 | G52: -43733.14
E53: 41360 | G53: -39160.28
E54: 41393 | G54: -31511.15
E55: 41404 | G55: -42901.72
E56: 41423 | G56: -37164.86
...

Sheet VIII-B
E8: =+VIII!E8 -> 45107
C17: Internal rate of return
C18: Internal rate of return after incentive allocation | E18: =+G138 -> 0.0031879216
C19: ROI | E19: =(G136+I137)/-I136 -> 1.01579
C21: Sample Investor Ownership Percentage (Pro-rata share of commitments - to calculate fund level amounts divide the cash flows in column G by the ownership % below)
C22: 0.033025234
C23: Contributions 2010 | E23: 40512 | G23: -157500
C24: Contributions 2011 | E24: 40570 | G24: -78750
E25: 40661 | G25: -60486.43
E26: 40704 | G26: -95406.42
E27: 40751 | G27: -91249.28
E28: 40765 | G28: -151735.71
E29: 40813 | G29: -133652.14
E30: 40879 | G30: -64227.85
E31: 40886 | G31: -87507.85
C32: Contributions 2012 | E32: 40927 | G32: -146331.42
E33: 40942 | G33: -685928.54
E34: 40970 | G34: -109124.99
E35: 41001 | G35: -63812.14
E36: 41024 | G36: -75660
E37: 41054 | G37: -98524.28
E38: 41080 | G38: -182706.42
E39: 41103 | G39: -59239.28
E40: 41121 | G40: -57160.71
E41: 41152 | G41: -75660.01
E42: 41180 | G42: -143421.43
E43: 41194 | G43: -70463.57
E44: 41250 | G44: -317813.58
E45: 41264 | G45: -282270
C46: Distribution 2012 | E46: 41030 | G46: 235528.56
E47: 41108 | G47: 59889.22
E48: 41137 | G48: 25909.14
E49: 41173 | G49: 519144.04
C50: Contributions 2013 | E50: 41284 | G50: -83350.73
E51: 41298 | G51: -106630.71
E52: 41345 | G52: -109332.86
E53: 41360 | G53: -97900.71
E54: 41393 | G54: -78777.85
E55: 41404 | G55: -107254.28
E56: 41423 | G56: -92912.15
...

Sheet VIII-C
E8: =+VIII!E8 -> 45107
C17: Internal rate of return
C18: Internal rate of return after incentive allocation | E18: =+G137 -> 0.0038677067
C19: ROI | E19: =(G135+I136)/-I135 -> 1.019048
C21: Sample Investor Ownership Percentage (Pro-rata share of commitments - to calculate fund level amounts divide the cash flows in column G by the ownership % below)
C22: 0.15163002
C23: Contributions 2011 | E23: 40590 | G23: -3150000
E24: 40661 | G24: -806485.68
E25: 40704 | G25: -1272085.7
E26: 40751 | G26: -1216657.1
E27: 40765 | G27: -2023142.8
E28: 40813 | G28: -1782028.5
E29: 40879 | G29: -856371.39
E30: 40886 | G30: -1166771.4
C31: Contributions 2012 | E31: 40927 | G31: -1951085.6
E32: 40942 | G32: -9145713.9
E33: 40970 | G33: -1454999.9
E34: 41001 | G34: -850828.54
E35: 41024 | G35: -1008800
E36: 41054 | G36: -1313657.1
E37: 41080 | G37: -2436085.6
E38: 41103 | G38: -789857.11
E39: 41121 | G39: -762142.83
E40: 41152 | G40: -1008800
E41: 41180 | G41: -1912285.7
E42: 41194 | G42: -939514.29
E43: 41250 | G43: -4237514.3
E44: 41264 | G44: -3763600
C45: Distribution 2012 | E45: 41030 | G45: 3231985.6
E46: 41108 | G46: 805926.42
E47: 41137 | G47: 345455.13
E48: 41173 | G48: 7058897.3
C49: Contributions 2013 | E49: 41284 | G49: -1111342.9
E50: 41298 | G50: -1421742.9
E51: 41345 | G51: -1457771.4
E52: 41360 | G52: -1305342.8
E53: 41393 | G53: -1050371.4
E54: 41404 | G54: -1430057.1
E55: 41423 | G55: -1238828.6
E56: 41446 | G56: -3785771.4
...

Sheet VIII-D
E8: =+VIII!E8 -> 45107
C17: Internal rate of return
C18: Internal rate of return after incentive allocation | E18: =+G137 -> 0.0045827895
C19: ROI | E19: =(G135+I136)/-I135 -> 1.0223455
C21: Sample Investor Ownership Percentage (Pro-rata share of commitments - to calculate fund level amounts divide the cash flows in column G by the ownership % below)
C22: 0.028643258
C23: Contributions 2011 | E23: 40590 | G23: -244125
E24: 40661 | G24: -62502.65
E25: 40704 | G25: -98586.65
E26: 40751 | G26: -94290.93
E27: 40765 | G27: -156793.58
E28: 40813 | G28: -138107.22
E29: 40879 | G29: -66368.79
E30: 40886 | G30: -90424.79
C31: Contributions 2012 | E31: 40927 | G31: -151209.15
E32: 40942 | G32: -708792.89
E33: 40970 | G33: -112762.51
E34: 41001 | G34: -65939.22
E35: 41024 | G35: -78182
E36: 41030 | G36: 288418.75
E37: 41054 | G37: -101808.43
E38: 41080 | G38: -188796.65
E39: 41103 | G39: -61213.93
E40: 41108 | G40: 62022.65
E41: 41121 | G41: -59066.07
E42: 41137 | G42: 26772.78
E43: 41152 | G43: -78182.01
E44: 41173 | G44: 577612.2
C45: Distribution 2012 | E45: 41180 | G45: -148202.14
E46: 41194 | G46: -72812.36
E47: 41250 | G47: -328407.36
E48: 41264 | G48: -291678.99
C49: Contributions 2013 | E49: 41284 | G49: -86129.08
E50: 41298 | G50: -110185.07
E51: 41345 | G51: -112977.29
E52: 41360 | G52: -101164.06
E53: 41393 | G53: -81403.8
E54: 41404 | G54: -110829.43
E55: 41418 | G55: 33721.7
E56: 41423 | G56: -96009.23
...

Sheet Fund IX
E8: 45107
C17: Internal rate of return
C18: Internal rate of return after incentive allocation | E18: =G161 -> 0.10392523
C19: ROI | E19: =(G159+I160)/-I159 -> 1.454375
C21: Sample Investor Ownership Percentage (Pro-rata share of commitments - to calculate fund level amounts divide the cash flows in column G by the ownership % below)
C22: 0.000194
C23: Contributions 2013 | E23: 41282 | G23: -6000
E24: 41359 | G24: -4947
E25: 41381 | G25: -1920.6
E26: 41424 | G26: -1610.2
E27: 41446 | G27: -58665.6
E28: 41498 | G28: -3918.8
E29: 41527 | G29: -9855.2
E30: 41534 | G30: -5024.6
E31: 41551 | G31: -4772.4
E32: 41585 | G32: -9137.4
E33: 41621 | G33: -16625.8
E34: 41635 | G34: -6770.6
C35: Contributions 2014 | E35: 41670 | G35: -5781.2
E36: 41712 | G36: -14666.47
E37: 41724 | G37: -5315.6
E38: 41733 | G38: -8380.8
E39: 41764 | G39: -7333.21
E40: 41774 | G40: -10320.8
E41: 41788 | G41: -8012.19
E42: 41817 | G42: -14394.8
E43: 41830 | G43: -9098.61
E44: 41851 | G44: -5121.6
E45: 41859 | G45: -9777.6
E46: 41880 | G46: -6052.8
E47: 41900 | G47: -24948.41
... E51: 41977 | G51: -19109
C52: Distributions 2014 | E52: 41817 | G52: 14124.6
C53: Contributions 2015 | E53: 42009 | G53: -61672.6
E54: 42027 | G54: -29216.4
E55: 42048 | G55: -13075.61
E56: 42061 | G56: -9525.4
E57: 42088 | G57: -20331.2
E58: 42111 | G58: -16431.79
E59: 42138 | G59: -14200.8
...

Sheet Fund IX-C
E8: =+'Fund IX'!E8 -> 45107
C17: Internal rate of return
C18: Internal rate of return after incentive allocation | E18: =G162 -> 0.090281627
C19: ROI | E19: =(G160+I161)/-I160 -> 1.4232576
C21: Sample Investor Ownership Percentage (Pro-rata share of commitments - to calculate fund level amounts divide the cash flows in column G by the ownership % below)
C22: 0.013382981
C23: Contributions 2013 | E23: 41282 | G23: -90000
E24: 41359 | G24: -74205
E25: 41381 | G25: -28809
E26: 41424 | G26: -24153.01
E27: 41446 | G27: -879983.99
E28: 41498 | G28: -58782
E29: 41527 | G29: -147828
E30: 41534 | G30: -75369.01
E31: 41551 | G31: -71586
E32: 41585 | G32: -137061
E33: 41621 | G33: -249387
E34: 41635 | G34: -101559
C35: Contributions 2014 | E35: 41670 | G35: -86718
E36: 41712 | G36: -219997.24
E37: 41724 | G37: -79734
E38: 41733 | G38: -125712
E39: 41764 | G39: -109998
E40: 41774 | G40: -154812
E41: 41788 | G41: -120183.01
E42: 41817 | G42: -215922
E43: 41830 | G43: -136478.99
E44: 41851 | G44: -76824
E45: 41859 | G45: -146664
E46: 41880 | G46: -90792
E47: 41900 | G47: -374226
... E51: 41977 | G51: -286635
C52: Distributions 2014 | E52: 41817 | G52: 197235.54
C53: Contributions 2015 | E53: 42009 | G53: -925089.01
E54: 42027 | G54: -438246
E55: 42048 | G55: -196133.99
E56: 42061 | G56: -142881
E57: 42088 | G57: -304968.01
E58: 42111 | G58: -246477.01
E59: 42138 | G59: -213012
...

Sheet Fund IX-D
E8: =+'Fund IX'!E8 -> 45107
C17: Internal rate of return
C18: Internal rate of return after incentive allocation | E18: =G161 -> 0.10348694
C19: ROI | E19: =(G159+I160)/-I159 -> 1.4525535
C21: Sample Investor Ownership Percentage (Pro-rata share of commitments - to calculate fund level amounts divide the cash flows in column G by the ownership % below)
C22: 0.0030979702
C23: Contributions 2013 | E23: 41282 | G23: -6000
E24: 41359 | G24: -4947
E25: 41381 | G25: -1920.6
E26: 41424 | G26: -1610.2
E27: 41446 | G27: -58665.6
E28: 41498 | G28: -3918.8
E29: 41527 | G29: -9855.2
E30: 41534 | G30: -5024.6
E31: 41551 | G31: -4772.4
E32: 41585 | G32: -9137.4
E33: 41621 | G33: -16625.8
E34: 41635 | G34: -6770.6
C35: Contributions 2014 | E35: 41670 | G35: -5781.2
E36: 41712 | G36: -14666.47
E37: 41724 | G37: -5315.6
E38: 41733 | G38: -8380.8
E39: 41764 | G39: -7333.21
E40: 41774 | G40: -10320.8
E41: 41788 | G41: -8012.2
E42: 41817 | G42: -14394.8
E43: 41830 | G43: -9098.61
E44: 41851 | G44: -5121.6
E45: 41859 | G45: -9777.6
E46: 41880 | G46: -6052.8
E47: 41900 | G47: -24948.41
... E51: 41977 | G51: -19109
C52: Distributions 2014 | E52: 41817 | G52: 13980.57
C53: Contributions 2015 | E53: 42009 | G53: -61672.6
E54: 42027 | G54: -29216.4
E55: 42048 | G55: -13075.61
E56: 42061 | G56: -9525.4
E57: 42088 | G57: -20331.2
E58: 42111 | G58: -16431.8
E59: 42138 | G59: -14200.8
...

Sheet Fund X
E8: 45107
C17: Internal rate of return
C18: Internal rate of return after incentive allocation | E18: =G154 -> 0.15457376
C19: ROI | E19: =-(G152+J155)/J154 -> 1.8695651
C21: Sample Investor Ownership Percentage (Pro-rata share of commitments - to calculate fund level amounts divide the cash flows in column G by the ownership % below)
C22: 0.000223846
C24: Contributions 2015 | E24: 42089 | G24: -71700
E25: 42118 | G25: 23052.4
E26: 42180 | G26: -7095.93
E27: 42201 | G27: -2216.09
E28: 42271 | G28: -6961.62
E29: 42324 | G29: -10587.93
E30: 42367 | G30: -28316.54
C31: Contributions 2016 | E31: 42396 | G31: -46425.69
E32: 42453 | G32: -10319.32
E33: 42461 | G33: -7476.46
E34: 42500 | G34: -6446.76
E35: 42513 | G35: -21354.92
E36: 42524 | G36: -50052
E37: 42544 | G37: -73690.16
E38: 42564 | G38: -8058.46
E39: 42585 | G39: -35860.15
E40: 42614 | G40: -13676.99
E41: 42641 | G41: -20952
E42: 42656 | G42: -22362.23
E43: 42704 | G43: -19183.62
... E45: 42733 | G45: -13318.84
C46: Distributions 2016 | E46: 42716 | G46: 17744.73
C47: Contributions 2017 | E47: 42754 | G47: -12983.08
E48: 42765 | G48: -13251.7
E49: 42773 | G49: -22608.46
E50: 42797 | G50: -31629.46
E51: 42817 | G51: -18758.31
E52: 42828 | G52: -16296
E53: 42851 | G53: -71496.45
E54: 42863 | G54: -15087.24
E55: 42878 | G55: -17057.08
E56: 42893 | G56: -32032.38
E57: 42907 | G57: -16989.92
E58: 42915 | G58: -38949.24
...

Sheet Fund X-C
E8: =+'Fund X'!E8 -> 45107
C17: Internal rate of return
C18: Internal rate of return after incentive allocation | E18: =G154 -> 0.14180315
C19: ROI | E19: =-(G152+J155)/J154 -> 1.7697093
C21: Sample Investor Ownership Percentage (Pro-rata share of commitments - to calculate fund level amounts divide the cash flows in column G by the ownership % below)
C22: 0.001086909
C24: Contributions 2015 | E24: 42089 | G24: -71700
E25: 42118 | G25: 23052.4
E26: 42180 | G26: -7095.93
E27: 42201 | G27: -2216.09
E28: 42271 | G28: -6961.62
E29: 42324 | G29: -10587.93
E30: 42367 | G30: -28316.54
C31: Contributions 2016 | E31: 42396 | G31: -46425.69
E32: 42453 | G32: -10319.32
E33: 42461 | G33: -7476.46
E34: 42500 | G34: -6446.76
E35: 42513 | G35: -21354.92
E36: 42524 | G36: -50052
E37: 42544 | G37: -73690.16
E38: 42564 | G38: -8058.46
E39: 42585 | G39: -35860.16
E40: 42614 | G40: -13676.99
E41: 42641 | G41: -20952
E42: 42656 | G42: -22362.23
E43: 42704 | G43: -19183.62
... E45: 42733 | G45: -13318.84
C46: Distributions 2016 | E46: 42716 | G46: 17585.47
C47: Contributions 2017 | E47: 42754 | G47: -12983.08
E48: 42765 | G48: -13251.7
E49: 42773 | G49: -22608.46
E50: 42797 | G50: -31629.46
E51: 42817 | G51: -18758.31
E52: 42828 | G52: -16296
E53: 42851 | G53: -71496.45
E54: 42863 | G54: -15087.24
E55: 42878 | G55: -17057.08
E56: 42893 | G56: -32032.38
E57: 42907 | G57: -16989.92
E58: 42915 | G58: -38949.24
...

Sheet Fund X-D
E8: =+'Fund X'!E8 -> 45107
C17: Internal rate of return
C18: Internal rate of return after incentive allocation | E18: =G154 -> 0.15421506
C19: ROI | E19: =-(G152+J155)/(J154) -> 1.86785
C21: Sample Investor Ownership Percentage (Pro-rata share of commitments - to calculate fund level amounts divide the cash flows in column G by the ownership % below)
C22: 0.009989242
C24: Contributions 2015 | E24: 42089 | G24: -155350
E25: 42118 | G25: 49946.86
E26: 42180 | G26: -15374.51
E27: 42201 | G27: -4801.51
E28: 42271 | G28: -15083.5
E29: 42324 | G29: -22940.5
E30: 42367 | G30: -61352.5
C31: Contributions 2016 | E31: 42396 | G31: -100589
E32: 42453 | G32: -22358.5
E33: 42461 | G33: -16199
E34: 42500 | G34: -13968
E35: 42513 | G35: -46268.99
E36: 42524 | G36: -108446
E37: 42544 | G37: -159662
E38: 42564 | G38: -17460
E39: 42585 | G39: -77697.02
E40: 42614 | G40: -29633.49
E41: 42641 | G41: -45396
E42: 42656 | G42: -48451.5
E43: 42704 | G43: -41564.5
... E45: 42733 | G45: -28857.49
C46: Distributions 2016 | E46: 42716 | G46: 37881.4
C47: Contributions 2017 | E47: 42754 | G47: -28130
E48: 42765 | G48: -28711.99
E49: 42773 | G49: -48985
E50: 42797 | G50: -68530.51
E51: 42817 | G51: -40643
E52: 42828 | G52: -35308
E53: 42851 | G53: -154909
E54: 42863 | G54: -32689.01
E55: 42878 | G55: -36957
E56: 42893 | G56: -69403.5
E57: 42907 | G57: -36811.5
E58: 42915 | G58: -84390
...

Sheet Fund XI
E8: 45107
C17: Internal rate of return
C18: Internal rate of return after incentive allocation | E18: =G116 -> 0.18790023
C19: ROI | E19: =-(G114+J117)/J116 -> 1.5264786
C21: Sample Investor Ownership Percentage (Pro-rata share of commitments - to calculate fund level amounts divide the cash flows in column G by the ownership % below)
C22: =2000000/6961190721.65 -> 0.00028730717
C24: Contributions 2017 | E24: 42933 | G24: -33800
E25: 43010 | G25: -8200
E26: 43052 | G26: -3600
E27: 43087 | G27: -15835.83
E28: 43096 | G28: -9710.99
C29: Contributions 2018 | E29: 43182 | G29: -70246.61
E30: 43276 | G30: -24938.27
E31: 43363 | G31: -18588.78
E32: 43398 | G32: -16290.31
E33: 43433 | G33: -13216.14
C34: Contributions 2019 | E34: 43468 | G34: -22438.69
E35: 43495 | G35: -36976.44
E36: 43510 | G36: -14853.79
E37: 43559 | G37: -20599.93
E38: 43593 | G38: -20542.46
E39: 43642 | G39: -32810.49
E40: 43656 | G40: -24363.64
E41: 43684 | G41: -21260.73
E42: 43768 | G42: -21030.88
E43: 43817 | G43: -161696.48
C44: Contributions 2020 | E44: 44006 | G44: -11980.7
E45: 44026 | G45: -29621.37
E46: 44106 | G46: -10170.67
E47: 44182 | G47: -41228.58
E48: 44188 | G48: -9596.06
C49: Contributions 2021 | E49: 44246 | G49: -8849.07
E50: 44250 | G50: -9337.48
E51: 44274 | G51: -14710.13
E52: 44305 | G52: -163880.01
E53: 44362 | G53: 25713.99
E54: 44400 | G54: -20111.5
E55: 44407 | G55: -21548.04
E56: 44440 | G56: -10285.59
E57: 44453 | G57: -16979.85
...

Sheet Fund XI-C
E8: ='Fund XI'!E8 -> 45107
C17: Internal rate of return
C18: Internal rate of return after incentive allocation | E18: =G116 -> 0.16441737
C19: ROI | E19: =-(G114+J117)/J116 -> 1.4463268
C21: Sample Investor Ownership Percentage (Pro-rata share of commitments - to calculate fund level amounts divide the cash flows in column G by the ownership % below)
C22: 0.027350044
C24: Contributions 2017 | E24: 42933 | G24: -422500
E25: 43010 | G25: -102500
E26: 43052 | G26: -45000
E27: 43087 | G27: -197947.88
E28: 43096 | G28: -121387.29
C29: Contributions 2018 | E29: 43182 | G29: -878082.53
E30: 43276 | G30: -311728.27
E31: 43363 | G31: -232359.67
E32: 43398 | G32: -203628.95
E33: 43433 | G33: -165201.61
C34: Contributions 2019 | E34: 43468 | G34: -280483.64
E35: 43495 | G35: -462205.41
E36: 43510 | G36: -185672.25
E37: 43559 | G37: -257499.03
E38: 43593 | G38: -256780.77
E39: 43642 | G39: -410130.99
E40: 43656 | G40: -304545.62
E41: 43684 | G41: -265759.16
E42: 43768 | G42: -262886.05
E43: 43817 | G43: -2021205.9
C44: Contributions 2020 | E44: 44006 | G44: -149758.87
E45: 44026 | G45: -370267.11
E46: 44105 | G46: -127133.42
E47: 44182 | G47: -515357.25
E48: 44188 | G48: -119950.73
C49: Contributions 2021 | E49: 44246 | G49: -110613.25
E50: 44250 | G50: -116718.53
E51: 44274 | G51: -183876.57
E52: 44305 | G52: -2048500.1
E53: 44362 | G53: 321424.89
E54: 44400 | G54: -251393.78
E55: 44407 | G55: -269350.47
E56: 44440 | G56: -128569.95
E57: 44453 | G57: -212248.17
...

Sheet Fund XI-D
E8: ='Fund XI'!E8 -> 45107
C17: Internal rate of return
C18: Internal rate of return after incentive allocation | E18: =G116 -> 0.18758237
C19: ROI | E19: =-(G114+J117)/J116 -> 1.5256429
C21: Sample Investor Ownership Percentage (Pro-rata share of commitments - to calculate fund level amounts divide the cash flows in column G by the ownership % below)
C22: 0.012144909
C24: Contributions 2017 | E24: 42933 | G24: -118300
E25: 43010 | G25: -28700
E26: 43052 | G26: -12600
E27: 43087 | G27: -55425.4
E28: 43096 | G28: -33988.44
C29: Contributions 2018 | E29: 43182 | G29: -245863.11
E30: 43276 | G30: -87283.92
E31: 43363 | G31: -65060.71
E32: 43398 | G32: -57016.11
E33: 43433 | G33: -46256.45
C34: Contributions 2019 | E34: 43468 | G34: -78535.4
E35: 43495 | G35: -129417.52
E36: 43510 | G36: -51988.23
E37: 43559 | G37: -72099.73
E38: 43593 | G38: -71898.61
E39: 43642 | G39: -114836.68
E40: 43656 | G40: -85272.77
E41: 43684 | G41: -74412.54
E42: 43768 | G42: -73608.09
E43: 43817 | G43: -565937.67
C44: Contributions 2020 | E44: 44006 | G44: -41932.49
E45: 44026 | G45: -103674.79
E46: 44105 | G46: -35597.36
E47: 44182 | G47: -144300.02
E48: 44188 | G48: -33586.21
C49: Contributions 2021 | E49: 44246 | G49: -30971.71
E50: 44250 | G50: -32681.18
E51: 44274 | G51: -51485.45
E52: 44305 | G52: -573580.03
E53: 44362 | G53: 89998.97
E54: 44400 | G54: -70390.26
E55: 44407 | G55: -75418.13
E56: 44440 | G56: -35999.59
E57: 44453 | G57: -59429.49
...

Sheet EETF I-A
E8: 45107
C17: Internal rate of return
C18: Internal rate of return after incentive allocation | E18: =G71 -> 0.25984918
C19: ROI | E19: =-(G69+I70)/I69 -> 1.3753157
C21: Sample Investor Ownership Percentage (Pro-rata share of commitments - to calculate fund level amounts divide the cash flows in column G by the ownership % below)
C22: 1
C24: Contributions 2020 | E24: 43857 | G24: =-8355693.57*193814409.75/213814409.75 -> -7574109.8
E25: 43985 | G25: =-8946403.4*193814409.75/213814409.75 -> -8109565.2
E26: 44076 | G26: =-8101403.91*193814409.75/213814409.75-1912477.07 -> -9256083.2
E27: 44117 | G27: =-10183965.83*193814409.75/213814409.75 -> -9231367.2
E28: 44141 | G28: =-9094491.06*193814409.75/213814409.75 -> -8243800.9
E29: 44148 | G29: =-4743875.63*193814409.75/213814409.75 -> -4300137.9
E30: 44187 | G30: =-4000309.07*193814409.75/213814409.75-294804.35 -> -3920928.2
C31: Contributions 2021 | E31: 44203 | G31: =-17965219.19*193814409.75/213814409.75-492157.19 -> -16776927
E32: 44217 | G32: =-2420477.32*193814409.75/213814409.75 -> -2194068.1
E33: 44250 | G33: =8743624.8*193814409.75/213814409.75 -> 7925754.3
E34: 44265 | G34: =-5278462.5*193814409.75/213814409.75-155480.19 -> -4940200.2
E35: 44291 | G35: =-12658173.89*193814409.75/213814409.75-268874.97 -> -11743015
E36: 44307 | G36: =-28503534.36*193814409.75/213814409.75-795428.94 -> -26632769
E37: 44319 | G37: =29772852.87*193814409.75/213814409.75 -> 26987928
E38: 44335 | G38: =-13567083.21*193814409.75/213814409.75-457505.62 -> -12755537
E39: 44344 | G39: =16251618.18*193814409.75/213814409.75 -> 14731457
E40: 44361 | G40: =416746.8*193814409.75/213814409.75+67984.53 -> 445749.22
E41: 44375 | G41: -6218476.1
E42: 44405 | G42: -3521086
E43: 44468 | G43: -1653652.9
E44: 44475 | G44: -4024098.3
E45: 44483 | G45: -4703164.9
E46: 44505 | G46: -4225303.2
E47: 44551 | G47: -2584225.6
C48: Distributions 2021 | E48: 44558 | G48: 41112360
C49: Contributions 2022 | E49: 44599 | G49: -1735392.4
E50: 44635 | G50: -5023835.2
E51: 44676 | G51: -2842019.4
E52: 44686 | G52: -6312804.1
E53: 44701 | G53: -6438557.2
E54: 44728 | G54: -3414195.9
E55: 44781 | G55: -8173949.6
E56: 44817 | G56: -11771667
E57: 44852 | G57: -2791718.2
...

Sheet EFM II
E8: 45107
C17: Internal rate of return
C18: Internal rate of return after incentive allocation | E18: =G98 -> 0.2597451
C19: ROI | E19: =-(G96+J99)/(J98) -> 1.6236627
C21: Sample Investor Ownership Percentage (Pro-rata share of commitments - to calculate fund level amounts divide the cash flows in column G by the ownership % below)
C22: 0.0056
C23: Contributions 2012 | E23: 41089 | G23: -75000
E24: 41166 | G24: -94080
E25: 41270 | G25: -273280
C26: Contributions 2013 | E26: 41311 | G26: -97440
E27: 41341 | G27: -140000
E28: 41361 | G28: -62720
E29: 41387 | G29: -136640
E30: 41408 | G30: -58800
E31: 41439 | G31: -136080
E32: 41479 | G32: -150640
E33: 41515 | G33: -94640
E34: 41543 | G34: -352800
E35: 41605 | G35: -83440
E36: 41638 | G36: -59920
C37: Contributions 2014 | E37: 41683 | G37: -61600
E38: 41701 | G38: -89599.99
E39: 41729 | G39: -115360
E40: 41751 | G40: -81200
E41: 41782 | G41: -138320
E42: 41808 | G42: -332080
E43: 41894 | G43: -69440
E44: 41942 | G44: -98560
E45: 41962 | G45: -218960
E46: 41975 | G46: -257600
C47: Distributions 2014 | E47: 41969 | G47: 950190.04
C48: Contributions 2015 | E48: 42037 | G48: -216720
E49: 42094 | G49: -188160
E50: 42110 | G50: -157360
E51: 42145 | G51: -196560
E52: 42158 | G52: -563360
E53: 42261 | G53: -423920
E54: 42366 | G54: -105840
C55: Distributions 2015 | E55: 42341 | G55: 167083.98
C56: Contributions 2016 | E56: 42397 | G56: -152880
...

Sheet EFM II-C
E8: =+'EFM II'!E8 -> 45107
C17: Internal rate of return
C18: Internal rate of return after incentive allocation | E18: =G98 -> 0.20956618
C19: ROI | E19: =-(G96+J99)/(J98) -> 1.5243279
C21: Sample Investor Ownership Percentage (Pro-rata share of commitments - to calculate fund level amounts divide the cash flows in column G by the ownership % below)
C22: 0.01538501
C23: Contributions 2012 | E23: 41089 | G23: -22500
E24: 41166 | G24: -28224
E25: 41270 | G25: -81984
C26: Contributions 2013 | E26: 41311 | G26: -29232
E27: 41341 | G27: -42000
E28: 41361 | G28: -18816
E29: 41387 | G29: -40992
E30: 41408 | G30: -17640
E31: 41439 | G31: -40824
E32: 41479 | G32: -45192
E33: 41515 | G33: -28392
E34: 41543 | G34: -105840
E35: 41605 | G35: -25032
E36: 41638 | G36: -17976
C37: Contributions 2014 | E37: 41683 | G37: -18480
E38: 41701 | G38: -26880
E39: 41729 | G39: -34608
E40: 41751 | G40: -24360
E41: 41782 | G41: -41496
E42: 41808 | G42: -99624
E43: 41894 | G43: -20832
E44: 41942 | G44: -29568
E45: 41962 | G45: -65688
E46: 41975 | G46: -77280
C47: Distributions 2014 | E47: 41969 | G47: 273860.4
C48: Contributions 2015 | E48: 42037 | G48: -65016.01
E49: 42094 | G49: -56448
E50: 42110 | G50: -47208
E51: 42145 | G51: -58968
E52: 42158 | G52: -169008
E53: 42261 | G53: -127176
E54: 42366 | G54: -31752
C55: Distributions 2015 | E55: 42341 | G55: 48606.68
C56: Contributions 2016 | E56: 42397 | G56: -45864
...

Sheet EFM II-D
E8: =+'EFM II'!E8 -> 45107
C17: Internal rate of return
C18: Internal rate of return after incentive allocation | E18: =G98 -> 0.25706856
C19: ROI | E19: =-(G96+J99)/(J98) -> 1.6161491
C21: Sample Investor Ownership Percentage (Pro-rata share of commitments - to calculate fund level amounts divide the cash flows in column G by the ownership % below)
C22: 0.012345679
C23: Contributions 2012 | E23: 41089 | G23: -7500
E24: 41166 | G24: -9408
E25: 41270 | G25: -27328
C26: Contributions 2013 | E26: 41311 | G26: -9744
E27: 41341 | G27: -14000
E28: 41361 | G28: -6272
E29: 41387 | G29: -13664
E30: 41408 | G30: -5880
E31: 41439 | G31: -13608
E32: 41479 | G32: -15064
E33: 41515 | G33: -9464
E34: 41543 | G34: -35280
E35: 41605 | G35: -8344
E36: 41638 | G36: -5992
C37: Contributions 2014 | E37: 41683 | G37: -6160
E38: 41701 | G38: -8960
E39: 41729 | G39: -11536
E40: 41751 | G40: -8120
E41: 41782 | G41: -13832
E42: 41808 | G42: -33208
E43: 41894 | G43: -6944
E44: 41942 | G44: -9856
E45: 41962 | G45: -21896
E46: 41975 | G46: -25760
C47: Distributions 2014 | E47: 41969 | G47: 93993.46
C48: Contributions 2015 | E48: 42037 | G48: -21672
E49: 42094 | G49: -18816
E50: 42110 | G50: -15736
E51: 42145 | G51: -19656
E52: 42158 | G52: -56336
E53: 42261 | G53: -42391.99
E54: 42366 | G54: -10584
C55: Distributions 2015 | E55: 42341 | G55: 15844.88
C56: Contributions 2016 | E56: 42397 | G56: -15288
...

Sheet EFM III
E8: 45107
C17: Internal rate of return
C18: Internal rate of return after incentive allocation | E18: =G118 -> 0.10411286
C19: ROI | E19: =-(G116+I117)/I116 -> 1.3910247
C21: Sample Investor Ownership Percentage (Pro-rata share of commitments - to calculate fund level amounts divide the cash flows in column G by the ownership % below)
C22: 0.0049
C24: Contributions 2014 | E24: 41829 | G24: -169050
E25: 41894 | G25: -87710
E26: 41942 | G26: -46060
E27: 41999 | G27: -65660
C28: Contributions 2015 | E28: 42037 | G28: -64680
E29: 42093 | G29: -83790
E30: 42109 | G30: -62720
E31: 42144 | G31: -36750
E32: 42184 | G32: -56350
E33: 42227 | G33: -74970
E34: 42261 | G34: -98980
E35: 42368 | G35: -80850
C36: Contributions 2016 | E36: 42396 | G36: -1416590
E37: 42445 | G37: -120050
E38: 42549 | G38: -194530
E39: 42586 | G39: -149450
E40: 42607 | G40: -113190
E41: 42613 | G41: -2398550
E42: 42640 | G42: -56350
E43: 42732 | G43: -78400
C44: Distributions 2016 | E44: 42377 | G44: 711402.14
E45: 42551 | G45: 75179.43
E46: 42642 | G46: 140484.82
E47: 42655 | G47: 57417.44
C48: Contributions 2017 | E48: 42765 | G48: -258720
E49: 42822 | G49: -143570
E50: 42852 | G50: -149940
E51: 42913 | G51: -601720
E52: 42991 | G52: -264600
E53: 43006 | G53: -188650
E54: 43080 | G54: -94080
E55: 43095 | G55: -187180
C56: Distributions 2017 | E56: 42747 | G56: 212932.02
C57: Contributions 2018 | E57: 43130 | G57: -1817900
...

Sheet EFM III-C
E8: =+'EFM III'!E8 -> 45107
C17: Internal rate of return
C18: Internal rate of return after incentive allocation | E18: =G118 -> 0.10070497
C19: ROI | E19: =-(G116+I117)/I116 -> 1.382999
C21: Sample Investor Ownership Percentage (Pro-rata share of commitments - to calculate fund level amounts divide the cash flows in column G by the ownership % below)
C22: 0.017131137
C24: Contributions 2014 | E24: 41829 | G24: -84525
E25: 41894 | G25: -43855
E26: 41942 | G26: -23030
E27: 41999 | G27: -32830
C28: Contributions 2015 | E28: 42037 | G28: -32340
E29: 42093 | G29: -41895
E30: 42109 | G30: -31360
E31: 42144 | G31: -18375
E32: 42184 | G32: -28175
E33: 42227 | G33: -37485
E34: 42261 | G34: -49489.99
E35: 42368 | G35: -40425
C36: Contributions 2016 | E36: 42396 | G36: -708295
E37: 42445 | G37: -60024.99
E38: 42549 | G38: -97265.01
E39: 42586 | G39: -74725
E40: 42607 | G40: -56595.01
E41: 42613 | G41: -1199275
E42: 42640 | G42: -28175
E43: 42732 | G43: -39200
C44: Distributions 2016 | E44: 42377 | G44: 259838.31
E45: 42551 | G45: 74232.03
E46: 42642 | G46: 70073.67
E47: 42655 | G47: 28437.88
C48: Contributions 2017 | E48: 42765 | G48: -129360
E49: 42822 | G49: -71785
E50: 42852 | G50: -74970
E51: 42913 | G51: -300860.01
E52: 42991 | G52: -132300
E53: 43006 | G53: -94325
E54: 43080 | G54: -47040
E55: 43095 | G55: -93590
C56: Distributions 2017 | E56: 42747 | G56: 106466.01
C57: Contributions 2018 | E57: 43130 | G57: -908950
...

Sheet EFM III-D
E8: =+'EFM III'!E8 -> 45107
C17: Internal rate of return
C18: Internal rate of return after incentive allocation | E18: =G118 -> 0.10336152
C19: ROI | E19: =-(G116+I117)/(I116) -> 1.3888874
C21: Sample Investor Ownership Percentage (Pro-rata share of commitments - to calculate fund level amounts divide the cash flows in column G by the ownership % below)
C22: 0.005037783
C24: Contributions 2014 | E24: 41829 | G24: -11269.99
E25: 41894 | G25: -5847.33
E26: 41942 | G26: -3070.67
E27: 41999 | G27: -4377.33
C28: Contributions 2015 | E28: 42037 | G28: -4312
E29: 42093 | G29: -5586
E30: 42109 | G30: -4181.33
E31: 42144 | G31: -2450
E32: 42184 | G32: -3756.67
E33: 42227 | G33: -4998
E34: 42261 | G34: -6598.67
E35: 42368 | G35: -5390
C36: Contributions 2016 | E36: 42396 | G36: -94439.34
E37: 42445 | G37: -8003.34
E38: 42549 | G38: -12968.67
E39: 42586 | G39: -9963.33
E40: 42607 | G40: -7546
E41: 42613 | G41: -159903.33
E42: 42640 | G42: -3756.67
E43: 42732 | G43: -5226.67
C44: Distributions 2016 | E44: 42377 | G44: 47121.98
E45: 42551 | G45: 4861.16
E46: 42642 | G46: 9354.83
E47: 42655 | G47: 3825.81
C48: Contributions 2017 | E48: 42765 | G48: -17248
E49: 42822 | G49: -9571.33
E50: 42852 | G50: -9996
E51: 42913 | G51: -40114.67
E52: 42991 | G52: -17640
E53: 43006 | G53: -12576.67
E54: 43080 | G54: -6272
E55: 43095 | G55: -12478.67
C56: Distributions 2017 | E56: 42747 | G56: 14195.47
C57: Contributions 2018 | E57: 43130 | G57: -121193.33
...

Sheet EFM IV
E8: 45107
C17: Internal rate of return
C18: Internal rate of return after incentive allocation | E18: =G66 -> 0.079917642
C19: ROI | E19: =-(G64+I65)/I64 -> 1.1912212
C21: Sample Investor Ownership Percentage (Pro-rata share of commitments - to calculate fund level amounts divide the cash flows in column G by the ownership % below)
C22: 0.000753846
C24: Contributions 2018 | E24: 43136 | G24: -100336.92
E25: 43193 | G25: -10327.69
E26: 43286 | G26: -9423.08
E27: 43328 | G27: -35355.39
E28: 43369 | G28: -734246.17
E29: 43391 | G29: 196000
E30: 43461 | G30: -12740.01
C31: Contributions 2019 | E31: 43494 | G31: -19675.39
E32: 43622 | G32: -13116.92
E33: 43670 | G33: -19750.78
E34: 43742 | G34: -14323.08
E35: 43794 | G35: -35053.83
E36: 43801 | G36: -67167.69
C37: Distributions 2019 | E37: 43671 | G37: 65298.04
C38: Contributions 2020 | E38: 43859 | G38: -18996.92
E39: 43916 | G39: -18619.99
E40: 44103 | G40: -24047.7
E41: 44126 | G41: -80661.55
C42: Contributions 2021 | E42: 44200 | G42: -13267.7
E43: 44376 | G43: -14323.07
E44: 44466 | G44: -9423.08
E45: 44530 | G45: -18619.99
C46: Distributions 2021 | E46: 44463 | G46: 12662.99
E47: 44484 | G47: 484615.55
E48: 44539 | G48: 39200
C49: Contributions 2022 | E49: 44606 | G49: -237386.15
E50: 44649 | G50: -9423.08
E51: 44672 | G51: -3844.61
E52: 44736 | G52: -30983.07
E53: 44764 | G53: -150090.78
E54: 44819 | G54: -340587.69
E55: 44875 | G55: -16810.77
E56: 44915 | G56: -152880.01
C57: Distributions 2022 | E57: 44615 | G57: 8403.74
...

Sheet EFM IV-C
E8: =+'EFM IV'!E8 -> 45107
C17: Internal rate of return
C18: Internal rate of return after incentive allocation | E18: =G66 -> 0.075756285
C19: ROI | E19: =-(G64+I65)/I64 -> 1.1808249
C21: Sample Investor Ownership Percentage (Pro-rata share of commitments - to calculate fund level amounts divide the cash flows in column G by the ownership % below)
C22: 0.003167063
C24: Contributions 2018 | E24: 43136 | G24: -40134.77
E25: 43193 | G25: -4131.08
E26: 43286 | G26: -3769.23
E27: 43328 | G27: -14142.15
E28: 43369 | G28: -293698.46
E29: 43391 | G29: 78400
E30: 43461 | G30: -5096.01
C31: Contributions 2019 | E31: 43494 | G31: -7870.16
E32: 43622 | G32: -5246.77
E33: 43670 | G33: -7900.31
E34: 43742 | G34: -5729.23
E35: 43794 | G35: -14021.53
E36: 43801 | G36: -26867.08
C37: Distributions 2019 | E37: 43671 | G37: 25873.43
C38: Contributions 2020 | E38: 43859 | G38: -7598.78
E39: 43916 | G39: -7447.99
E40: 44103 | G40: -9619.08
E41: 44126 | G41: -32264.62
C42: Contributions 2021 | E42: 44200 | G42: -5307.07
E43: 44376 | G43: -5729.22
E44: 44466 | G44: -3769.23
E45: 44530 | G45: -7448.01
C46: Distributions 2021 | E46: 44463 | G46: 4310.1
E47: 44484 | G47: 190670.31
E48: 44539 | G48: 15666.13
C49: Contributions 2022 | E49: 44606 | G49: -94954.46
E50: 44649 | G50: -3769.23
E51: 44672 | G51: -1537.85
E52: 44736 | G52: -12393.23
E53: 44764 | G53: -60036.31
E54: 44819 | G54: -136235.06
E55: 44875 | G55: -6724.31
E56: 44915 | G56: -61152.01
C57: Distributions 2022 | E57: 44615 | G57: 3257.23
...

Sheet EFM IV-D
E8: =+'EFM IV'!E8 -> 45107
C17: Internal rate of return
C18: Internal rate of return after incentive allocation | E18: =G66 -> 0.0793349
C19: ROI | E19: =-(G64+I65)/(I64) -> 1.1898423
C21: Sample Investor Ownership Percentage (Pro-rata share of commitments - to calculate fund level amounts divide the cash flows in column G by the ownership % below)
C22: 0.017458101
C24: Contributions 2018 | E24: 43136 | G24: -200673.85
E25: 43193 | G25: -20655.39
E26: 43286 | G26: -18846.15
E27: 43328 | G27: -70710.78
E28: 43369 | G28: -1468492.3
E29: 43391 | G29: 392000
E30: 43461 | G30: -25480
C31: Contributions 2019 | E31: 43494 | G31: -39350.78
E32: 43622 | G32: -26233.85
E33: 43670 | G33: -39501.54
E34: 43742 | G34: -28646.15
E35: 43794 | G35: -70107.7
E36: 43801 | G36: -134335.38
C37: Distributions 2019 | E37: 43671 | G37: 129646.89
C38: Contributions 2020 | E38: 43859 | G38: -37993.85
E39: 43916 | G39: -37240
E40: 44103 | G40: -48095.38
E41: 44126 | G41: -161323.07
C42: Contributions 2021 | E42: 44200 | G42: -26535.39
E43: 44376 | G43: -28646.16
E44: 44466 | G44: -18846.15
E45: 44530 | G45: -37240.01
C46: Distributions 2021 | E46: 44463 | G46: 22626.91
E47: 44484 | G47: 969199.17
E48: 44539 | G48: 78313.97
C49: Contributions 2022 | E49: 44606 | G49: -474772.3
E50: 44649 | G50: -18846.15
E51: 44672 | G51: -7689.23
E52: 44736 | G52: -61966.16
E53: 44764 | G53: -300181.54
E54: 44819 | G54: -681175.39
E55: 44875 | G55: -33621.54
E56: 44915 | G56: -305760
C57: Distributions 2022 | E57: 44615 | G57: 16557.02
...

Sheet EETF I-A hypo w INT
B4: Financial Highlights EETF I-A
E8: 44561 | I8: INPUT CELLS
G9: INPUT CELLS | I9: =1-(20000000/213814409.75) -> 0.90646093 | J9: INPUT CELLS
C10: Net investment income/loss | E10: =I10/(J35) -> -0.079751738 | G10: =-6132648-J10 -> -748190 | I10: =(G10*$I$9)+J10 -> -6062663 | J10: -5384458 | K10: Mgmt fees
C12: Expense ratios
C13: Operating expenses | E13: =I13/(J35) -> 0.080862552 | G13: =6225805-J13 -> 841347 | I13: =G13*$I$9+J13 -> 6147106.2 | J13: =-J10 -> 5384458
C14: Incentive allocation | E14: =(G14)/(J35) -> 0.13550001 | G14: 10300602
C15: Total expenses and incentive allocation | E15: =E13+E14 -> 0.21636256
C17: Internal rate of return
C18: Internal rate of return after incentive allocation | E18: =G52 -> 0.37472666
C19: ROI | E19: =-(G50+I51)/I50 -> 1.3823748
J20: INPUT CELLS
C24: Contributions 2020 | E24: 43857 | G24: =-8355693.57*193814409.75/213814409.75 -> -7574109.8
E25: 43985 | G25: =-8946403.4*193814409.75/213814409.75 -> -8109565.2
E26: 44076 | G26: =-8101403.91*193814409.75/213814409.75-1912477.07 -> -9256083.2
E27: 44117 | G27: =-10183965.83*193814409.75/213814409.75 -> -9231367.2
E28: 44141 | G28: =-9094491.06*193814409.75/213814409.75 -> -8243800.9
E29: 44148 | G29: =-4743875.63*193814409.75/213814409.75 -> -4300137.9
E30: 44187 | G30: =-4000309.07*193814409.75/213814409.75-294804.35 -> -3920928.2 | J30: 23429675 | K30: PY NAV
C31: Contributions 2021 | E31: 44203 | G31: =-17965219.19*193814409.75/213814409.75-492157.19 -> -16776927 | J31: 60571194 | K31: 3/31 NAV
E32: 44217 | G32: =-2420477.32*193814409.75/213814409.75 -> -2194068.1 | J32: 95593774 | K32: 6/30 NAV
E33: 44250 | G33: =8743624.8*193814409.75/213814409.75 -> 7925754.3 | J33: 98439035 | K33: 9/30 NAV
E34: 44265 | G34: =-5278462.5*193814409.75/213814409.75-155480.19 -> -4940200.2 | J34: =G50 -> 102062302 | K34: CY NAV
E35: 44291 | G35: =-12658173.89*193814409.75/213814409.75-268874.97 -> -11743015 | J35: =SUM(J30:J34)/5 -> 76019196 | K35: AVG NAV
E36: 44307 | G36: =-28503534.36*193814409.75/213814409.75-795428.94 -> -26632769
E37: 44319 | G37: =29772852.87*193814409.75/213814409.75 -> 26987928
E38: 44335 | G38: =-13567083.21*193814409.75/213814409.75-457505.62 -> -12755537
E39: 44344 | G39: =16251618.18*193814409.75/213814409.75+830538.11-1675268.66 -> 13886726
E40: 44361 | G40: =416746.8*193814409.75/213814409.75+67984.53 -> 445749.22
E41: 44375 | G41: =-6218476.1-209162.1 -> -6427638.2
E42: 44405 | G42: -3521086
E43: 44468 | G43: -1653652.9
E44: 44475 | G44: -4024098.3
E45: 44483 | G45: -4703164.9
E46: 44505 | G46: -4225303.2
E47: 44551 | G47: -2584225.6
E48: 44558 | G48: 41112360
C50: Net assets | E50: =+E8 -> 44561 | G50: 102062302 | I50: =+SUMIF($G$24:$G$49,"<0",$G$24:$G$49)+G33+G37+G39+G40 -> -1.0357152e+08 | J50: check figure-Contributions
I51: =+SUMIF($G$24:$G$49,">0",$G$24:$G$49)-G33-G37-G39-G40 -> 41112360 | J51: check figure-Distributions
C52: Total return | G52: =+XIRR(G24:G50,E24:E50,0.1) -> 0.37472666
...

Sheet EETF I-B hypo
B4: Financial Highlights EETF I-B
E8: 44561
G9: INPUT CELLS
C10: Net investment income/loss | E10: =I10/(J35) -> 0 | G10: =-6132648-J10 -> -6132648
C12: Expense ratios
C13: Operating expenses | E13: =I13/(J35) -> 0 | G13: =6225805-J13 -> 6225805
C14: Incentive allocation | E14: =(G14)/(J35) -> 0.14150342 | G14: 10300602
C15: Total expenses and incentive allocation | E15: =E13+E14 -> 0.14150342
C17: Internal rate of return
C18: Internal rate of return after incentive allocation | E18: =G52 -> 0.37967424
C19: ROI | E19: =-(G50+I51)/I50 -> 1.3892632
J20: INPUT CELLS
C24: Contributions 2020 | E24: 43857 | G24: -6869196.6
E25: 43985 | G25: -7354817.8
E26: 44076 | G26: -8396286.7
E27: 44117 | G27: -8372215.1
E28: 44141 | G28: -7476560.3
E29: 44148 | G29: -3899929.3
E30: 44187 | G30: -3556267.5 | J30: 23869519 | K30: PY NAV
C31: Contributions 2021 | E31: 44203 | G31: -15215945 | J31: 72564673 | K31: 3/31 NAV
E32: 44217 | G32: -1989868.9 | J32: 86518493 | K32: 6/30 NAV
E33: 44250 | G33: 7188114 | J33: 89013713 | K33: 9/30 NAV
E34: 44265 | G34: -4480556.4 | J34: =G50 -> 92003681 | K34: CY NAV
E35: 44291 | G35: -10650340 | J35: =SUM(J30:J34)/5 -> 72794016 | K35: AVG NAV
E36: 44307 | G36: -24154779
E37: 44319 | G37: 24476194
E38: 44335 | G38: -11568790
E39: 44344 | G39: 13360418
E40: 44361 | G40: 342606.6
E41: 44375 | G41: -5666306.5
E42: 44405 | G42: -3196431.5
E43: 44468 | G43: -1501181.2
E44: 44475 | G44: -3653064.6
E45: 44483 | G45: -4269519.2
E46: 44505 | G46: -3835717.8
E47: 44551 | G47: -2345952.4
E48: 44558 | G48: 37317814
C50: Net assets | E50: =+E8 -> 44561 | G50: 92003681 | I50: =+SUMIF($G$24:$G$49,"<0",$G$24:$G$49)+G33+G37+G39+G40 -> -93086392 | J50: check figure-Contributions
I51: =+SUMIF($G$24:$G$49,">0",$G$24:$G$49)-G33-G37-G39-G40 -> 37317814 | J51: check figure-Distributions
C52: Total return | G52: =+XIRR(G24:G50,E24:E50,0.1) -> 0.37967424
...

Sheet EETF I-C hypo
B4: Financial Highlights EETF I-C
E8: 44561
G9: INPUT CELLS
C10: Net investment income/loss | E10: =I10/(J35) -> 0 | G10: =-6132648-J10 -> -6132648
C12: Expense ratios
C13: Operating expenses | E13: =I13/(J35) -> 0 | G13: =6225805-J13 -> 6225805
C14: Incentive allocation | E14: =(G14)/(J35) -> 0.15717178 | G14: 10300602
C15: Total expenses and incentive allocation | E15: =E13+E14 -> 0.15717178
C17: Internal rate of return
C18: Internal rate of return after incentive allocation | E18: =G52 -> 0.27906733
C19: ROI | E19: =-(G50+I51)/I50 -> 1.2835123
J20: INPUT CELLS
C24: Contributions 2020 | E24: 43857 | G24: -3877114.2
E25: 43985 | G25: -4151208.7
E26: 44076 | G26: -4739034.9
E27: 44117 | G27: -4725448.3
E28: 44141 | G28: -4219922.6
E29: 44148 | G29: -2201199.4
E30: 44187 | G30: -2007229.6 | J30: 23429675 | K30: PY NAV
