Workbook

Sheet Fund Performance Summary
B1: Fund Performance Summary
B2: As of July 31, 2024
D5: Fund | E5: ='Share Price'!B3 -> QQQ | H5: ='Share Price'!B4 -> SPY | K5: ='Share Price'!B5 -> XOP
C6: Vintage | D6: Net IRR | E6: PME IRR (1) | F6: Direct Alpha (2) | G6: KS-PME (3) | H6: PME IRR (1) | I6: Direct Alpha (2) | J6: KS-PME (3) | K6: PME IRR (1) | L6: Direct Alpha (2) | M6: KS-PME (3) | N6: Average
B7: Fund VI | D7: ='Fund VI'!F3 -> 0.32462801 | E7: ='Fund VI'!F4 -> 0.32462801 | F7: ='Fund VI'!F5 -> 0.21730986 | G7: ='Fund VI'!F6 -> 1.7534771 | H7: ='Fund VI'!G4 -> 0.32462801 | I7: ='Fund VI'!G5 -> 0.30923399 | J7: ='Fund VI'!G6 -> 2.1415444 | K7: ='Fund VI'!H4 -> 0.32462801 | L7: ='Fund VI'!H5 -> 0.24109132 | M7: ='Fund VI'!H6 -> 1.9764966 | N7: =AVERAGE(F7,I7,L7) -> 0.25587839
B8: Fund VII | D8: ='Fund VII'!F3 -> 0.24436759 | E8: ='Fund VII'!F4 -> 0.24436759 | F8: ='Fund VII'!F5 -> 0.081310822 | G8: ='Fund VII'!F6 -> 1.2152952 | H8: ='Fund VII'!G4 -> 0.24436759 | I8: ='Fund VII'!G5 -> 0.15234383 | J8: ='Fund VII'!G6 -> 1.4137469 | K8: ='Fund VII'!H4 -> 0.24436759 | L8: ='Fund VII'!H5 -> 0.16453523 | M8: ='Fund VII'!H6 -> 1.6027353 | N8: =AVERAGE(F8,I8,L8) -> 0.13272996
B9: Fund VIII | D9: ='Fund VIII'!F3 -> 0.023659725 | E9: ='Fund VIII'!F4 -> 0.18215999 | F9: ='Fund VIII'!F5 -> -0.13168127 | G9: ='Fund VIII'!F6 -> 0.52329248 | H9: ='Fund VIII'!G4 -> 0.11802168 | I9: ='Fund VIII'!G5 -> -0.083309886 | J9: ='Fund VIII'!G6 -> 0.64747542 | K9: ='Fund VIII'!H4 -> -0.036528256 | L9: ='Fund VIII'!H5 -> 0.062880971 | M9: ='Fund VIII'!H6 -> 1.3859008 | N9: =AVERAGE(F9,I9,L9) -> -0.050703395
B10: Fund IX | D10: ='Fund IX'!F3 -> 0.15310315 | E10: ='Fund IX'!F4 -> 0.16759952 | F10: ='Fund IX'!F5 -> -0.011538256 | G10: ='Fund IX'!F6 -> 0.95536431 | H10: ='Fund IX'!G4 -> 0.097506179 | I10: ='Fund IX'!G5 -> 0.046227242 | J10: ='Fund IX'!G6 -> 1.2114416 | K10: ='Fund IX'!H4 -> NA | L10: ='Fund IX'!H5 -> 0.24801998 | M10: ='Fund IX'!H6 -> 2.6225664 | N10: =AVERAGE(F10,I10,L10) -> 0.094236323
B11: Fund X | D11: ='Fund X'!F3 -> 0.21164303 | E11: ='Fund X'!F4 -> 0.19019977 | F11: ='Fund X'!F5 -> 0.017402668 | G11: ='Fund X'!F6 -> 1.096657 | H11: ='Fund X'!G4 -> 0.11435677 | I11: ='Fund X'!G5 -> 0.082901131 | J11: ='Fund X'!G6 -> 1.5384708 | K11: ='Fund X'!H4 -> NA | L11: ='Fund X'!H5 -> 0.22493974 | M11: ='Fund X'!H6 -> 2.8489337 | N11: =AVERAGE(F11,I11,L11) -> 0.10841451
B12: Fund XI | D12: ='Fund XI'!F3 -> 0.31047553 | E12: ='Fund XI'!F4 -> 0.31047553 | F12: ='Fund XI'!F5 -> 0.11373373 | G12: ='Fund XI'!F6 -> 1.5037103 | H12: ='Fund XI'!G4 -> 0.31047553 | I12: ='Fund XI'!G5 -> 0.17190406 | J12: ='Fund XI'!G6 -> 1.7954824 | K12: ='Fund XI'!H4 -> 0.31047553 | L12: ='Fund XI'!H5 -> 0.20389054 | M12: ='Fund XI'!H6 -> 1.8900904 | N12: =AVERAGE(F12,I12,L12) -> 0.16317611
B14: Notes
B15: (1) PME IRR is the IRR of the hypothetical public portfolio built with cash flows of the fund. It should be compared directly to the fund IRR.
B16: (2) Direct Alpha calculates the annualized return earned by the fund manager in excess of the benchmark (i.e., alpha of the fund manager). A positive number shows that the fund cash flows outperformed the benchmark.
B17: (3) KS-PME measures final wealth created by the fund manager compared to what would have been achieved by investing in the benchmark.

Sheet Fund VI
B1: Inputs | E1: Outputs | K1: Cash Flow Summary
B2: Fund Name | C2: Fund VI | F2: PME Index 1 | G2: PME Index 2 | H2: PME Index 3 | L2: Actual | M2: PME Index 1 | N2: PME Index 2 | O2: PME Index 3
B3: End Date | C3: =B152 -> 44834 | E3: Actual IRR | F3: =IFERROR(XIRR(C11:C152, B11:B152, IF(SUM(C11:C152) > 0, 0.15, -0.15)), "NA") -> 0.32462801 | G3: =IFERROR(XIRR(C11:C152, B11:B152, IF(SUM(C11:C152) > 0, 0.15, -0.15)), "NA") -> 0.32462801 | H3: =IFERROR(XIRR(C11:C152, B11:B152, IF(SUM(C11:C152) > 0, 0.15, -0.15)), "NA") -> 0.32462801 | K3: Distribution | L3: =SUMIFS(C11:C152, D11:D152, K3) -> 2909973.4 | M3: =SUMIFS(H11:H152, D11:D152, K3) -> 13119010 | N3: =SUMIFS(N11:N152, D11:D152, K3) -> 7755987.6 | O3: =SUMIFS(T11:T152, D11:D152, K3) -> 1794538.2
B4: Index 1 | C4: ='Share Price'!B3 -> QQQ | E4: PME IRR | F4: =IFERROR(XIRR(J11:J152, B11:B152, IF(SUM(J11:J152) > 0, 0.15, -0.15)), "NA") -> 0.32462801 | G4: =IFERROR(XIRR(P11:P152, B11:B152, IF(SUM(P11:P152) > 0, 0.15, -0.15)), "NA") -> 0.32462801 | H4: =IFERROR(XIRR(V11:V152, B11:B152, IF(SUM(V11:V152) > 0, 0.15, -0.15)), "NA") -> 0.32462801 | K4: Contribution | L4: =SUMIFS(C11:C152, D11:D152, K4) -> -1187575 | M4: =SUMIFS(H11:H152, D11:D152, K4) -> -7481711.6 | N4: =SUMIFS(N11:N152, D11:D152, K4) -> -3621679.6 | O4: =SUMIFS(T11:T152, D11:D152, K4) -> -907938.94
B5: Index 2 | C5: ='Share Price'!B4 -> SPY | E5: Direct Alpha IRR | F5: =IFERROR(XIRR(H11:H152, B11:B152, IF(SUM(H11:H152) > 0, 0.15, -0.15)), "NA") -> 0.21730986 | G5: =IFERROR(XIRR(N11:N152, B11:B152, IF(SUM(N11:N152) > 0, 0.15, -0.15)), "NA") -> 0.30923399 | H5: =IFERROR(XIRR(T11:T152, B11:B152, IF(SUM(T11:T152) > 0, 0.15, -0.15)), "NA") -> 0.24109132 | K5: Net Asset Value | L5: =SUMIFS(C11:C152, D11:D152, K5) -> 0 | M5: =SUMIFS(H11:H152, D11:D152, K5) -> 0 | N5: =SUMIFS(N11:N152, D11:D152, K5) -> 0 | O5: =SUMIFS(T11:T152, D11:D152, K5) -> 0
B6: Index 3 | C6: ='Share Price'!B5 -> XOP | E6: KS-PME | F6: =(M3 + M5) / -M4 -> 1.7534771 | G6: =(N3 + N5) / -N4 -> 2.1415444 | H6: =(O3 + O5) / -O4 -> 1.9764966
B8: Cash Flow Data | E8: Index 1 Portfolio | K8: Index 2 Portfolio | Q8: Index 3 Portfolio
E9: Index Value at | H9: NAV | I9: End Date | J9: PME | K9: Index Value at | N9: NAV | O9: End Date | P9: PME | Q9: Index Value at | T9: NAV | U9: End Date | V9: PME
B10: Date | C10: Amount | D10: Type | E10: CF Date | F10: End Date | G10: Factor | H10: Contribution | I10: NAV | J10: Cash Flow | K10: CF Date | L10: End Date | M10: Factor | N10: Contribution | O10: NAV | P10: Cash Flow | Q10: CF Date | R10: End Date | S10: Factor | T10: Contribution | U10: NAV | V10: Cash Flow
B11: 38960 | C11: -1000 | D11: Contribution | E11: =_xlfn.XLOOKUP(B11,'Share Price'!D:D,'Share Price'!E:E) -> 38.7093 | F11: =_xlfn.XLOOKUP(C3,'Share Price'!D:D,'Share Price'!E:E) -> 267.26 | G11: =F11/E11 -> 6.904284 | H11: =C11 * G11 -> -6904.284 | I11: =IF(D11="Net Asset Value",I10,-SUM(H11:H11)) -> 6904.284 | J11: =IF(D11="Net Asset Value", I11, C11) -> -1000 | K11: =_xlfn.XLOOKUP(B11,'Share Price'!D:D,'Share Price'!F:F) -> 130.64 | L11: =_xlfn.XLOOKUP(C3,'Share Price'!D:D,'Share Price'!F:F) -> 357.18 | M11: =L11/K11 -> 2.7340784 | N11: =C11 * M11 -> -2734.0784 | O11: =IF(D11="Net Asset Value",O10,-SUM(N11:N11)) -> 2734.0784 | P11: =IF(D11="Net Asset Value", O11, C11) -> -1000 | Q11: =_xlfn.XLOOKUP(B11,'Share Price'!D:D,'Share Price'!G:G) -> 154.56 | R11: =_xlfn.XLOOKUP(C3,'Share Price'!D:D,'Share Price'!G:G) -> 124.72 | S11: =R11/Q11 -> 0.80693582 | T11: =C11 * S11 -> -806.93582 | U11: =IF(D11="Net Asset Value",U10,-SUM(T11:T11)) -> 806.93582 | V11: =IF(D11="Net Asset Value", U11, C11) -> -1000
B12: 38990 | C12: -27828.819 | D12: Contribution | E12: =_xlfn.XLOOKUP(B12,'Share Price'!D:D,'Share Price'!E:E) -> 40.4819 | F12: =_xlfn.XLOOKUP(C3,'Share Price'!D:D,'Share Price'!E:E) -> 267.26 | G12: =F12/E12 -> 6.6019629 | H12: =C12 * G12 -> -183724.83 | I12: =IF(D12="Net Asset Value",I11,-SUM(H11:H12)) -> 190629.11 | J12: =IF(D12="Net Asset Value", I12, C12) -> -27828.819 | K12: =_xlfn.XLOOKUP(B12,'Share Price'!D:D,'Share Price'!F:F) -> 133.58 | L12: =_xlfn.XLOOKUP(C3,'Share Price'!D:D,'Share Price'!F:F) -> 357.18 | M12: =L12/K12 -> 2.6739033 | N12: =C12 * M12 -> -74411.57 | O12: =IF(D12="Net Asset Value",O11,-SUM(N11:N12)) -> 77145.648 | P12: =IF(D12="Net Asset Value", O12, C12) -> -27828.819 | Q12: =_xlfn.XLOOKUP(B12,'Share Price'!D:D,'Share Price'!G:G) -> 142.12 | R12: =_xlfn.XLOOKUP(C3,'Share Price'!D:D,'Share Price'!G:G) -> 124.72 | S12: =R12/Q12 -> 0.87756825 | T12: =C12 * S12 -> -24421.688 | U12: =IF(D12="Net Asset Value",U11,-SUM(T11:T12)) -> 25228.624 | V12: =IF(D12="Net Asset Value", U12, C12) -> -27828.819
B13: 39051 | C13: -52562.722 | D13: Contribution | E13: =_xlfn.XLOOKUP(B13,'Share Price'!D:D,'Share Price'!E:E) -> 43.8579 | F13: =_xlfn.XLOOKUP(C3,'Share Price'!D:D,'Share Price'!E:E) -> 267.26 | G13: =F13/E13 -> 6.093771 | H13: =C13 * G13 -> -320305.19 | I13: =IF(D13="Net Asset Value",I12,-SUM(H11:H13)) -> 510934.3 | J13: =IF(D13="Net Asset Value", I13, C13) -> -52562.722 | K13: =_xlfn.XLOOKUP(B13,'Share Price'!D:D,'Share Price'!F:F) -> 140.53 | L13: =_xlfn.XLOOKUP(C3,'Share Price'!D:D,'Share Price'!F:F) -> 357.18 | M13: =L13/K13 -> 2.5416637 | N13: =C13 * M13 -> -133596.76 | O13: =IF(D13="Net Asset Value",O12,-SUM(N11:N13)) -> 210742.41 | P13: =IF(D13="Net Asset Value", O13, C13) -> -52562.722 | Q13: =_xlfn.XLOOKUP(B13,'Share Price'!D:D,'Share Price'!G:G) -> 164.84 | R13: =_xlfn.XLOOKUP(C3,'Share Price'!D:D,'Share Price'!G:G) -> 124.72 | S13: =R13/Q13 -> 0.75661247 | T13: =C13 * S13 -> -39769.611 | U13: =IF(D13="Net Asset Value",U12,-SUM(T11:T13)) -> 64998.234 | V13: =IF(D13="Net Asset Value", U13, C13) -> -52562.722
B14: 39082 | C14: -2816.7793 | D14: Contribution | E14: =_xlfn.XLOOKUP(B14,'Share Price'!D:D,'Share Price'!E:E) -> 42.9815 | F14: =_xlfn.XLOOKUP(C3,'Share Price'!D:D,'Share Price'!E:E) -> 267.26 | G14: =F14/E14 -> 6.218024 | H14: =C14 * G14 -> -17514.802 | I14: =IF(D14="Net Asset Value",I13,-SUM(H11:H14)) -> 528449.1 | J14: =IF(D14="Net Asset Value", I14, C14) -> -2816.7793 | K14: =_xlfn.XLOOKUP(B14,'Share Price'!D:D,'Share Price'!F:F) -> 141.62 | L14: =_xlfn.XLOOKUP(C3,'Share Price'!D:D,'Share Price'!F:F) -> 357.18 | M14: =L14/K14 -> 2.5221014 | N14: =C14 * M14 -> -7104.2031 | O14: =IF(D14="Net Asset Value",O13,-SUM(N11:N14)) -> 217846.61 | P14: =IF(D14="Net Asset Value", O14, C14) -> -2816.7793 | Q14: =_xlfn.XLOOKUP(B14,'Share Price'!D:D,'Share Price'!G:G) -> 152.28 | R14: =_xlfn.XLOOKUP(C3,'Share Price'!D:D,'Share Price'!G:G) -> 124.72 | S14: =R14/Q14 -> 0.8190176 | T14: =C14 * S14 -> -2306.9919 | U14: =IF(D14="Net Asset Value",U13,-SUM(T11:T14)) -> 67305.226 | V14: =IF(D14="Net Asset Value", U14, C14) -> -2816.7793
B15: 39113 | C15: -4295.7939 | D15: Contribution | E15: =_xlfn.XLOOKUP(B15,'Share Price'!D:D,'Share Price'!E:E) -> 43.8878 | F15: =_xlfn.XLOOKUP(C3,'Share Price'!D:D,'Share Price'!E:E) -> 267.26 | G15: =F15/E15 -> 6.0896194 | H15: =C15 * G15 -> -26159.75 | I15: =IF(D15="Net Asset Value",I14,-SUM(H11:H15)) -> 554608.85 | J15: =IF(D15="Net Asset Value", I15, C15) -> -4295.7939 | K15: =_xlfn.XLOOKUP(B15,'Share Price'!D:D,'Share Price'!F:F) -> 143.75 | L15: =_xlfn.XLOOKUP(C3,'Share Price'!D:D,'Share Price'!F:F) -> 357.18 | M15: =L15/K15 -> 2.4847304 | N15: =C15 * M15 -> -10673.89 | O15: =IF(D15="Net Asset Value",O14,-SUM(N11:N15)) -> 228520.5 | P15: =IF(D15="Net Asset Value", O15, C15) -> -4295.7939 | Q15: =_xlfn.XLOOKUP(B15,'Share Price'!D:D,'Share Price'!G:G) -> 156.88 | R15: =_xlfn.XLOOKUP(C3,'Share Price'!D:D,'Share Price'!G:G) -> 124.72 | S15: =R15/Q15 -> 0.79500255 | T15: =C15 * S15 -> -3415.1671 | U15: =IF(D15="Net Asset Value",U14,-SUM(T11:T15)) -> 70720.393 | V15: =IF(D15="Net Asset Value", U15, C15) -> -4295.7939
B16: 39141 | C16: -13222.388 | D16: Contribution | E16: =_xlfn.XLOOKUP(B16,'Share Price'!D:D,'Share Price'!E:E) -> 43.1508 | F16: =_xlfn.XLOOKUP(C3,'Share Price'!D:D,'Share Price'!E:E) -> 267.26 | G16: =F16/E16 -> 6.1936279 | H16: =C16 * G16 -> -81894.554 | I16: =IF(D16="Net Asset Value",I15,-SUM(H11:H16)) -> 636503.41 | J16: =IF(D16="Net Asset Value", I16, C16) -> -13222.388 | K16: =_xlfn.XLOOKUP(B16,'Share Price'!D:D,'Share Price'!F:F) -> 140.93 | L16: =_xlfn.XLOOKUP(C3,'Share Price'!D:D,'Share Price'!F:F) -> 357.18 | M16: =L16/K16 -> 2.5344497 | N16: =C16 * M16 -> -33511.479 | O16: =IF(D16="Net Asset Value",O15,-SUM(N11:N16)) -> 262031.98 | P16: =IF(D16="Net Asset Value", O16, C16) -> -13222.388 | Q16: =_xlfn.XLOOKUP(B16,'Share Price'!D:D,'Share Price'!G:G) -> 154.64 | R16: =_xlfn.XLOOKUP(C3,'Share Price'!D:D,'Share Price'!G:G) -> 124.72 | S16: =R16/Q16 -> 0.80651837 | T16: =C16 * S16 -> -10664.099 | U16: =IF(D16="Net Asset Value",U15,-SUM(T11:T16)) -> 81384.492 | V16: =IF(D16="Net Asset Value", U16, C16) -> -13222.388
B17: 39172 | C17: -3338.4201 | D17: Contribution | E17: =_xlfn.XLOOKUP(B17,'Share Price'!D:D,'Share Price'!E:E) -> 43.35 | F17: =_xlfn.XLOOKUP(C3,'Share Price'!D:D,'Share Price'!E:E) -> 267.26 | G17: =F17/E17 -> 6.1651672 | H17: =C17 * G17 -> -20581.918 | I17: =IF(D17="Net Asset Value",I16,-SUM(H11:H17)) -> 657085.33 | J17: =IF(D17="Net Asset Value", I17, C17) -> -3338.4201 | K17: =_xlfn.XLOOKUP(B17,'Share Price'!D:D,'Share Price'!F:F) -> 142 | L17: =_xlfn.XLOOKUP(C3,'Share Price'!D:D,'Share Price'!F:F) -> 357.18 | M17: =L17/K17 -> 2.5153521 | N17: =C17 * M17 -> -8397.3021 | O17: =IF(D17="Net Asset Value",O16,-SUM(N11:N17)) -> 270429.28 | P17: =IF(D17="Net Asset Value", O17, C17) -> -3338.4201 | Q17: =_xlfn.XLOOKUP(B17,'Share Price'!D:D,'Share Price'!G:G) -> 162.92 | R17: =_xlfn.XLOOKUP(C3,'Share Price'!D:D,'Share Price'!G:G) -> 124.72 | S17: =R17/Q17 -> 0.76552909 | T17: =C17 * S17 -> -2555.6577 | U17: =IF(D17="Net Asset Value",U16,-SUM(T11:T17)) -> 83940.15 | V17: =IF(D17="Net Asset Value", U17, C17) -> -3338.4201
B18: 39202 | C18: -33321.393 | D18: Contribution | E18: =_xlfn.XLOOKUP(B18,'Share Price'!D:D,'Share Price'!E:E) -> 45.77 | F18: =_xlfn.XLOOKUP(C3,'Share Price'!D:D,'Share Price'!E:E) -> 267.26 | G18: =F18/E18 -> 5.839196 | H18: =C18 * G18 -> -194570.14 | I18: =IF(D18="Net Asset Value",I17,-SUM(H11:H18)) -> 851655.47 | J18: =IF(D18="Net Asset Value", I18, C18) -> -33321.393 | K18: =_xlfn.XLOOKUP(B18,'Share Price'!D:D,'Share Price'!F:F) -> 148.29 | L18: =_xlfn.XLOOKUP(C3,'Share Price'!D:D,'Share Price'!F:F) -> 357.18 | M18: =L18/K18 -> 2.4086587 | N18: =C18 * M18 -> -80259.862 | O18: =IF(D18="Net Asset Value",O17,-SUM(N11:N18)) -> 350689.15 | P18: =IF(D18="Net Asset Value", O18, C18) -> -33321.393 | Q18: =_xlfn.XLOOKUP(B18,'Share Price'!D:D,'Share Price'!G:G) -> 173 | R18: =_xlfn.XLOOKUP(C3,'Share Price'!D:D,'Share Price'!G:G) -> 124.72 | S18: =R18/Q18 -> 0.72092486 | T18: =C18 * S18 -> -24022.22 | U18: =IF(D18="Net Asset Value",U17,-SUM(T11:T18)) -> 107962.37 | V18: =IF(D18="Net Asset Value", U18, C18) -> -33321.393
B19: 39233 | C19: -26212.894 | D19: Contribution | E19: =_xlfn.XLOOKUP(B19,'Share Price'!D:D,'Share Price'!E:E) -> 47.214 | F19: =_xlfn.XLOOKUP(C3,'Share Price'!D:D,'Share Price'!E:E) -> 267.26 | G19: =F19/E19 -> 5.6606091 | H19: =C19 * G19 -> -148380.95 | I19: =IF(D19="Net Asset Value",I18,-SUM(H11:H19)) -> 1000036.4 | J19: =IF(D19="Net Asset Value", I19, C19) -> -26212.894 | K19: =_xlfn.XLOOKUP(B19,'Share Price'!D:D,'Share Price'!F:F) -> 153.32 | L19: =_xlfn.XLOOKUP(C3,'Share Price'!D:D,'Share Price'!F:F) -> 357.18 | M19: =L19/K19 -> 2.3296374 | N19: =C19 * M19 -> -61066.537 | O19: =IF(D19="Net Asset Value",O18,-SUM(N11:N19)) -> 411755.68 | P19: =IF(D19="Net Asset Value", O19, C19) -> -26212.894 | Q19: =_xlfn.XLOOKUP(B19,'Share Price'!D:D,'Share Price'!G:G) -> 186 | R19: =_xlfn.XLOOKUP(C3,'Share Price'!D:D,'Share Price'!G:G) -> 124.72 | S19: =R19/Q19 -> 0.67053763 | T19: =C19 * S19 -> -17576.732 | U19: =IF(D19="Net Asset Value",U18,-SUM(T11:T19)) -> 125539.1 | V19: =IF(D19="Net Asset Value", U19, C19) -> -26212.894
B20: 39263 | C20: -82161.834 | D20: Contribution | E20: =_xlfn.XLOOKUP(B20,'Share Price'!D:D,'Share Price'!E:E) -> 47.4032 | F20: =_xlfn.XLOOKUP(C3,'Share Price'!D:D,'Share Price'!E:E) -> 267.26 | G20: =F20/E20 -> 5.638016 | H20: =C20 * G20 -> -463229.74 | I20: =IF(D20="Net Asset Value",I19,-SUM(H11:H20)) -> 1463266.2 | J20: =IF(D20="Net Asset Value", I20, C20) -> -82161.834 | K20: =_xlfn.XLOOKUP(B20,'Share Price'!D:D,'Share Price'!F:F) -> 150.43 | L20: =_xlfn.XLOOKUP(C3,'Share Price'!D:D,'Share Price'!F:F) -> 357.18 | M20: =L20/K20 -> 2.3743934 | N20: =C20 * M20 -> -195084.52 | O20: =IF(D20="Net Asset Value",O19,-SUM(N11:N20)) -> 606840.2 | P20: =IF(D20="Net Asset Value", O20, C20) -> -82161.834 | Q20: =_xlfn.XLOOKUP(B20,'Share Price'!D:D,'Share Price'!G:G) -> 183.4796 | R20: =_xlfn.XLOOKUP(C3,'Share Price'!D:D,'Share Price'!G:G) -> 124.72 | S20: =R20/Q20 -> 0.67974859 | T20: =C20 * S20 -> -55849.391 | U20: =IF(D20="Net Asset Value",U19,-SUM(T11:T20)) -> 181388.49 | V20: =IF(D20="Net Asset Value", U20, C20) -> -82161.834
B21: 39294 | C21: -16106.633 | D21: Contribution | E21: =_xlfn.XLOOKUP(B21,'Share Price'!D:D,'Share Price'!E:E) -> 47.3335 | F21: =_xlfn.XLOOKUP(C3,'Share Price'!D:D,'Share Price'!E:E) -> 267.26 | G21: =F21/E21 -> 5.6463181 | H21: =C21 * G21 -> -90943.173 | I21: =IF(D21="Net Asset Value",I20,-SUM(H11:H21)) -> 1554209.3 | J21: =IF(D21="Net Asset Value", I21, C21) -> -16106.633 | K21: =_xlfn.XLOOKUP(B21,'Share Price'!D:D,'Share Price'!F:F) -> 145.72 | L21: =_xlfn.XLOOKUP(C3,'Share Price'!D:D,'Share Price'!F:F) -> 357.18 | M21: =L21/K21 -> 2.4511392 | N21: =C21 * M21 -> -39479.599 | O21: =IF(D21="Net Asset Value",O20,-SUM(N11:N21)) -> 646319.8 | P21: =IF(D21="Net Asset Value", O21, C21) -> -16106.633 | Q21: =_xlfn.XLOOKUP(B21,'Share Price'!D:D,'Share Price'!G:G) -> 175.72 | R21: =_xlfn.XLOOKUP(C3,'Share Price'!D:D,'Share Price'!G:G) -> 124.72 | S21: =R21/Q21 -> 0.70976554 | T21: =C21 * S21 -> -11431.933 | U21: =IF(D21="Net Asset Value",U20,-SUM(T11:T21)) -> 192820.43 | V21: =IF(D21="Net Asset Value", U21, C21) -> -16106.633
B22: 39325 | C22: -57051.775 | D22: Contribution | E22: =_xlfn.XLOOKUP(B22,'Share Price'!D:D,'Share Price'!E:E) -> 48.6679 | F22: =_xlfn.XLOOKUP(C3,'Share Price'!D:D,'Share Price'!E:E) -> 267.26 | G22: =F22/E22 -> 5.4915047 | H22: =C22 * G22 -> -313300.09 | I22: =IF(D22="Net Asset Value",I21,-SUM(H11:H22)) -> 1867509.4 | J22: =IF(D22="Net Asset Value", I22, C22) -> -57051.775 | K22: =_xlfn.XLOOKUP(B22,'Share Price'!D:D,'Share Price'!F:F) -> 147.59 | L22: =_xlfn.XLOOKUP(C3,'Share Price'!D:D,'Share Price'!F:F) -> 357.18 | M22: =L22/K22 -> 2.4200827 | N22: =C22 * M22 -> -138070.01 | O22: =IF(D22="Net Asset Value",O21,-SUM(N11:N22)) -> 784389.81 | P22: =IF(D22="Net Asset Value", O22, C22) -> -57051.775 | Q22: =_xlfn.XLOOKUP(B22,'Share Price'!D:D,'Share Price'!G:G) -> 172.44 | R22: =_xlfn.XLOOKUP(C3,'Share Price'!D:D,'Share Price'!G:G) -> 124.72 | S22: =R22/Q22 -> 0.72326606 | T22: =C22 * S22 -> -41263.612 | U22: =IF(D22="Net Asset Value",U21,-SUM(T11:T22)) -> 234084.04 | V22: =IF(D22="Net Asset Value", U22, C22) -> -57051.775
B23: 39355 | C23: -9917.9641 | D23: Contribution | E23: =_xlfn.XLOOKUP(B23,'Share Price'!D:D,'Share Price'!E:E) -> 51.1974 | F23: =_xlfn.XLOOKUP(C3,'Share Price'!D:D,'Share Price'!E:E) -> 267.26 | G23: =F23/E23 -> 5.220187 | H23: =C23 * G23 -> -51773.627 | I23: =IF(D23="Net Asset Value",I22,-SUM(H11:H23)) -> 1919283 | J23: =IF(D23="Net Asset Value", I23, C23) -> -9917.9641 | K23: =_xlfn.XLOOKUP(B23,'Share Price'!D:D,'Share Price'!F:F) -> 152.58 | L23: =_xlfn.XLOOKUP(C3,'Share Price'!D:D,'Share Price'!F:F) -> 357.18 | M23: =L23/K23 -> 2.3409359 | N23: =C23 * M23 -> -23217.318 | O23: =IF(D23="Net Asset Value",O22,-SUM(N11:N23)) -> 807607.13 | P23: =IF(D23="Net Asset Value", O23, C23) -> -9917.9641 | Q23: =_xlfn.XLOOKUP(B23,'Share Price'!D:D,'Share Price'!G:G) -> 188.12 | R23: =_xlfn.XLOOKUP(C3,'Share Price'!D:D,'Share Price'!G:G) -> 124.72 | S23: =R23/Q23 -> 0.66298108 | T23: =C23 * S23 -> -6575.4225 | U23: =IF(D23="Net Asset Value",U22,-SUM(T11:T23)) -> 240659.46 | V23: =IF(D23="Net Asset Value", U23, C23) -> -9917.9641
B24: 39386 | C24: -20441.058 | D24: Contribution | E24: =_xlfn.XLOOKUP(B24,'Share Price'!D:D,'Share Price'!E:E) -> 54.8025 | F24: =_xlfn.XLOOKUP(C3,'Share Price'!D:D,'Share Price'!E:E) -> 267.26 | G24: =F24/E24 -> 4.8767848 | H24: =C24 * G24 -> -99686.64 | I24: =IF(D24="Net Asset Value",I23,-SUM(H11:H24)) -> 2018969.7 | J24: =IF(D24="Net Asset Value", I24, C24) -> -20441.058 | K24: =_xlfn.XLOOKUP(B24,'Share Price'!D:D,'Share Price'!F:F) -> 154.65 | L24: =_xlfn.XLOOKUP(C3,'Share Price'!D:D,'Share Price'!F:F) -> 357.18 | M24: =L24/K24 -> 2.3096023 | N24: =C24 * M24 -> -47210.714 | O24: =IF(D24="Net Asset Value",O23,-SUM(N11:N24)) -> 854817.84 | P24: =IF(D24="Net Asset Value", O24, C24) -> -20441.058 | Q24: =_xlfn.XLOOKUP(B24,'Share Price'!D:D,'Share Price'!G:G) -> 211.64 | R24: =_xlfn.XLOOKUP(C3,'Share Price'!D:D,'Share Price'!G:G) -> 124.72 | S24: =R24/Q24 -> 0.58930259 | T24: =C24 * S24 -> -12045.968 | U24: =IF(D24="Net Asset Value",U23,-SUM(T11:T24)) -> 252705.43 | V24: =IF(D24="Net Asset Value", U24, C24) -> -20441.058
B25: 39416 | C25: -50808.142 | D25: Contribution | E25: =_xlfn.XLOOKUP(B25,'Share Price'!D:D,'Share Price'!E:E) -> 51.0978 | F25: =_xlfn.XLOOKUP(C3,'Share Price'!D:D,'Share Price'!E:E) -> 267.26 | G25: =F25/E25 -> 5.2303622 | H25: =C25 * G25 -> -265744.98 | I25: =IF(D25="Net Asset Value",I24,-SUM(H11:H25)) -> 2284714.7 | J25: =IF(D25="Net Asset Value", I25, C25) -> -50808.142 | K25: =_xlfn.XLOOKUP(B25,'Share Price'!D:D,'Share Price'!F:F) -> 148.66 | L25: =_xlfn.XLOOKUP(C3,'Share Price'!D:D,'Share Price'!F:F) -> 357.18 | M25: =L25/K25 -> 2.4026638 | N25: =C25 * M25 -> -122074.88 | O25: =IF(D25="Net Asset Value",O24,-SUM(N11:N25)) -> 976892.73 | P25: =IF(D25="Net Asset Value", O25, C25) -> -50808.142 | Q25: =_xlfn.XLOOKUP(B25,'Share Price'!D:D,'Share Price'!G:G) -> 194.08 | R25: =_xlfn.XLOOKUP(C3,'Share Price'!D:D,'Share Price'!G:G) -> 124.72 | S25: =R25/Q25 -> 0.6426216 | T25: =C25 * S25 -> -32650.41 | U25: =IF(D25="Net Asset Value",U24,-SUM(T11:T25)) -> 285355.84 | V25: =IF(D25="Net Asset Value", U25, C25) -> -50808.142
B26: 39447 | C26: -41812.195 | D26: Contribution | E26: =_xlfn.XLOOKUP(B26,'Share Price'!D:D,'Share Price'!E:E) -> 51.0082 | F26: =_xlfn.XLOOKUP(C3,'Share Price'!D:D,'Share Price'!E:E) -> 267.26 | G26: =F26/E26 -> 5.2395497 | H26: =C26 * G26 -> -219077.07 | I26: =IF(D26="Net Asset Value",I25,-SUM(H11:H26)) -> 2503791.7 | J26: =IF(D26="Net Asset Value", I26, C26) -> -41812.195 | K26: =_xlfn.XLOOKUP(B26,'Share Price'!D:D,'Share Price'!F:F) -> 146.21 | L26: =_xlfn.XLOOKUP(C3,'Share Price'!D:D,'Share Price'!F:F) -> 357.18 | M26: =L26/K26 -> 2.4429246 | N26: =C26 * M26 -> -102144.04 | O26: =IF(D26="Net Asset Value",O25,-SUM(N11:N26)) -> 1079036.8 | P26: =IF(D26="Net Asset Value", O26, C26) -> -41812.195 | Q26: =_xlfn.XLOOKUP(B26,'Share Price'!D:D,'Share Price'!G:G) -> 208 | R26: =_xlfn.XLOOKUP(C3,'Share Price'!D:D,'Share Price'!G:G) -> 124.72 | S26: =R26/Q26 -> 0.59961538 | T26: =C26 * S26 -> -25071.235 | U26: =IF(D26="Net Asset Value",U25,-SUM(T11:T26)) -> 310427.07 | V26: =IF(D26="Net Asset Value", U26, C26) -> -41812.195
B27: 39478 | C27: -6612.6642 | D27: Contribution | E27: =_xlfn.XLOOKUP(B27,'Share Price'!D:D,'Share Price'!E:E) -> 44.9434 | F27: =_xlfn.XLOOKUP(C3,'Share Price'!D:D,'Share Price'!E:E) -> 267.26 | G27: =F27/E27 -> 5.9465906 | H27: =C27 * G27 -> -39322.807 | I27: =IF(D27="Net Asset Value",I26,-SUM(H11:H27)) -> 2543114.5 | J27: =IF(D27="Net Asset Value", I27, C27) -> -6612.6642 | K27: =_xlfn.XLOOKUP(B27,'Share Price'!D:D,'Share Price'!F:F) -> 137.37 | L27: =_xlfn.XLOOKUP(C3,'Share Price'!D:D,'Share Price'!F:F) -> 357.18 | M27: =L27/K27 -> 2.600131 | N27: =C27 * M27 -> -17193.793 | O27: =IF(D27="Net Asset Value",O26,-SUM(N11:N27)) -> 1096230.6 | P27: =IF(D27="Net Asset Value", O27, C27) -> -6612.6642 | Q27: =_xlfn.XLOOKUP(B27,'Share Price'!D:D,'Share Price'!G:G) -> 192.16 | R27: =_xlfn.XLOOKUP(C3,'Share Price'!D:D,'Share Price'!G:G) -> 124.72 | S27: =R27/Q27 -> 0.64904246 | T27: =C27 * S27 -> -4291.8999 | U27: =IF(D27="Net Asset Value",U26,-SUM(T11:T27)) -> 314718.97 | V27: =IF(D27="Net Asset Value", U27, C27) -> -6612.6642
B28: 39507 | C28: 44960.843 | D28: Distribution | E28: =_xlfn.XLOOKUP(B28,'Share Price'!D:D,'Share Price'!E:E) -> 42.7724 | F28: =_xlfn.XLOOKUP(C3,'Share Price'!D:D,'Share Price'!E:E) -> 267.26 | G28: =F28/E28 -> 6.2484219 | H28: =C28 * G28 -> 280934.31 | I28: =IF(D28="Net Asset Value",I27,-SUM(H11:H28)) -> 2262180.2 | J28: =IF(D28="Net Asset Value", I28, C28) -> 44960.843 | K28: =_xlfn.XLOOKUP(B28,'Share Price'!D:D,'Share Price'!F:F) -> 133.82 | L28: =_xlfn.XLOOKUP(C3,'Share Price'!D:D,'Share Price'!F:F) -> 357.18 | M28: =L28/K28 -> 2.6691078 | N28: =C28 * M28 -> 120005.33 | O28: =IF(D28="Net Asset Value",O27,-SUM(N11:N28)) -> 976225.22 | P28: =IF(D28="Net Asset Value", O28, C28) -> 44960.843 | Q28: =_xlfn.XLOOKUP(B28,'Share Price'!D:D,'Share Price'!G:G) -> 217.9196 | R28: =_xlfn.XLOOKUP(C3,'Share Price'!D:D,'Share Price'!G:G) -> 124.72 | S28: =R28/Q28 -> 0.57232117 | T28: =C28 * S28 -> 25732.042 | U28: =IF(D28="Net Asset Value",U27,-SUM(T11:T28)) -> 288986.93 | V28: =IF(D28="Net Asset Value", U28, C28) -> 44960.843
B29: 39538 | C29: -10755.949 | D29: Contribution | E29: =_xlfn.XLOOKUP(B29,'Share Price'!D:D,'Share Price'!E:E) -> 43.5392 | F29: =_xlfn.XLOOKUP(C3,'Share Price'!D:D,'Share Price'!E:E) -> 267.26 | G29: =F29/E29 -> 6.1383765 | H29: =C29 * G29 -> -66024.066 | I29: =IF(D29="Net Asset Value",I28,-SUM(H11:H29)) -> 2328204.3 | J29: =IF(D29="Net Asset Value", I29, C29) -> -10755.949 | K29: =_xlfn.XLOOKUP(B29,'Share Price'!D:D,'Share Price'!F:F) -> 131.97 | L29: =_xlfn.XLOOKUP(C3,'Share Price'!D:D,'Share Price'!F:F) -> 357.18 | M29: =L29/K29 -> 2.7065242 | N29: =C29 * M29 -> -29111.237 | O29: =IF(D29="Net Asset Value",O28,-SUM(N11:N29)) -> 1005336.5 | P29: =IF(D29="Net Asset Value", O29, C29) -> -10755.949 | Q29: =_xlfn.XLOOKUP(B29,'Share Price'!D:D,'Share Price'!G:G) -> 215 | R29: =_xlfn.XLOOKUP(C3,'Share Price'!D:D,'Share Price'!G:G) -> 124.72 | S29: =R29/Q29 -> 0.58009302 | T29: =C29 * S29 -> -6239.4511 | U29: =IF(D29="Net Asset Value",U28,-SUM(T11:T29)) -> 295226.38 | V29: =IF(D29="Net Asset Value", U29, C29) -> -10755.949
B30: 39568 | C30: 9343.6776 | D30: Distribution | E30: =_xlfn.XLOOKUP(B30,'Share Price'!D:D,'Share Price'!E:E) -> 47.0148 | F30: =_xlfn.XLOOKUP(C3,'Share Price'!D:D,'Share Price'!E:E) -> 267.26 | G30: =F30/E30 -> 5.6845929 | H30: =C30 * G30 -> 53115.004 | I30: =IF(D30="Net Asset Value",I29,-SUM(H11:H30)) -> 2275089.3 | J30: =IF(D30="Net Asset Value", I30, C30) -> 9343.6776 | K30: =_xlfn.XLOOKUP(B30,'Share Price'!D:D,'Share Price'!F:F) -> 138.26 | L30: =_xlfn.XLOOKUP(C3,'Share Price'!D:D,'Share Price'!F:F) -> 357.18 | M30: =L30/K30 -> 2.5833936 | N30: =C30 * M30 -> 24138.397 | O30: =IF(D30="Net Asset Value",O29,-SUM(N11:N30)) -> 981198.06 | P30: =IF(D30="Net Asset Value", O30, C30) -> 9343.6776 | Q30: =_xlfn.XLOOKUP(B30,'Share Price'!D:D,'Share Price'!G:G) -> 235.56 | R30: =_xlfn.XLOOKUP(C3,'Share Price'!D:D,'Share Price'!G:G) -> 124.72 | S30: =R30/Q30 -> 0.52946171 | T30: =C30 * S30 -> 4947.1195 | U30: =IF(D30="Net Asset Value",U29,-SUM(T11:T30)) -> 290279.26 | V30: =IF(D30="Net Asset Value", U30, C30) -> 9343.6776
B31: 39599 | C31: -45647.186 | D31: Contribution | E31: =_xlfn.XLOOKUP(B31,'Share Price'!D:D,'Share Price'!E:E) -> 49.8032 | F31: =_xlfn.XLOOKUP(C3,'Share Price'!D:D,'Share Price'!E:E) -> 267.26 | G31: =F31/E31 -> 5.3663218 | H31: =C31 * G31 -> -244957.49 | I31: =IF(D31="Net Asset Value",I30,-SUM(H11:H31)) -> 2520046.8 | J31: =IF(D31="Net Asset Value", I31, C31) -> -45647.186 | K31: =_xlfn.XLOOKUP(B31,'Share Price'!D:D,'Share Price'!F:F) -> 140.35 | L31: =_xlfn.XLOOKUP(C3,'Share Price'!D:D,'Share Price'!F:F) -> 357.18 | M31: =L31/K31 -> 2.5449234 | N31: =C31 * M31 -> -116168.59 | O31: =IF(D31="Net Asset Value",O30,-SUM(N11:N31)) -> 1097366.7 | P31: =IF(D31="Net Asset Value", O31, C31) -> -45647.186 | Q31: =_xlfn.XLOOKUP(B31,'Share Price'!D:D,'Share Price'!G:G) -> 259.08 | R31: =_xlfn.XLOOKUP(C3,'Share Price'!D:D,'Share Price'!G:G) -> 124.72 | S31: =R31/Q31 -> 0.48139571 | T31: =C31 * S31 -> -21974.359 | U31: =IF(D31="Net Asset Value",U30,-SUM(T11:T31)) -> 312253.62 | V31: =IF(D31="Net Asset Value", U31, C31) -> -45647.186
B32: 39629 | C32: -24462.446 | D32: Contribution | E32: =_xlfn.XLOOKUP(B32,'Share Price'!D:D,'Share Price'!E:E) -> 44.9832 | F32: =_xlfn.XLOOKUP(C3,'Share Price'!D:D,'Share Price'!E:E) -> 267.26 | G32: =F32/E32 -> 5.9413292 | H32: =C32 * G32 -> -145339.44 | I32: =IF(D32="Net Asset Value",I31,-SUM(H11:H32)) -> 2665386.2 | J32: =IF(D32="Net Asset Value", I32, C32) -> -24462.446 | K32: =_xlfn.XLOOKUP(B32,'Share Price'!D:D,'Share Price'!F:F) -> 127.98 | L32: =_xlfn.XLOOKUP(C3,'Share Price'!D:D,'Share Price'!F:F) -> 357.18 | M32: =L32/K32 -> 2.7909048 | N32: =C32 * M32 -> -68272.358 | O32: =IF(D32="Net Asset Value",O31,-SUM(N11:N32)) -> 1165639 | P32: =IF(D32="Net Asset Value", O32, C32) -> -24462.446 | Q32: =_xlfn.XLOOKUP(B32,'Share Price'!D:D,'Share Price'!G:G) -> 281.12 | R32: =_xlfn.XLOOKUP(C3,'Share Price'!D:D,'Share Price'!G:G) -> 124.72 | S32: =R32/Q32 -> 0.44365396 | T32: =C32 * S32 -> -10852.861 | U32: =IF(D32="Net Asset Value",U31,-SUM(T11:T32)) -> 323106.48 | V32: =IF(D32="Net Asset Value", U32, C32) -> -24462.446
B33: 39660 | C33: -8388.337 | D33: Contribution | E33: =_xlfn.XLOOKUP(B33,'Share Price'!D:D,'Share Price'!E:E) -> 45.272 | F33: =_xlfn.XLOOKUP(C3,'Share Price'!D:D,'Share Price'!E:E) -> 267.26 | G33: =F33/E33 -> 5.9034282 | H33: =C33 * G33 -> -49519.945 | I33: =IF(D33="Net Asset Value",I32,-SUM(H11:H33)) -> 2714906.2 | J33: =IF(D33="Net Asset Value", I33, C33) -> -8388.337 | K33: =_xlfn.XLOOKUP(B33,'Share Price'!D:D,'Share Price'!F:F) -> 126.83 | L33: =_xlfn.XLOOKUP(C3,'Share Price'!D:D,'Share Price'!F:F) -> 357.18 | M33: =L33/K33 -> 2.8162107 | N33: =C33 * M33 -> -23623.324 | O33: =IF(D33="Net Asset Value",O32,-SUM(N11:N33)) -> 1189262.3 | P33: =IF(D33="Net Asset Value", O33, C33) -> -8388.337 | Q33: =_xlfn.XLOOKUP(B33,'Share Price'!D:D,'Share Price'!G:G) -> 216.32 | R33: =_xlfn.XLOOKUP(C3,'Share Price'!D:D,'Share Price'!G:G) -> 124.72 | S33: =R33/Q33 -> 0.57655325 | T33: =C33 * S33 -> -4836.323 | U33: =IF(D33="Net Asset Value",U32,-SUM(T11:T33)) -> 327942.81 | V33: =IF(D33="Net Asset Value", U33, C33) -> -8388.337
B34: 39691 | C34: -50070.06 | D34: Contribution | E34: =_xlfn.XLOOKUP(B34,'Share Price'!D:D,'Share Price'!E:E) -> 45.9293 | F34: =_xlfn.XLOOKUP(C3,'Share Price'!D:D,'Share Price'!E:E) -> 267.26 | G34: =F34/E34 -> 5.8189435 | H34: =C34 * G34 -> -291354.85 | I34: =IF(D34="Net Asset Value",I33,-SUM(H11:H34)) -> 3006261 | J34: =IF(D34="Net Asset Value", I34, C34) -> -50070.06 | K34: =_xlfn.XLOOKUP(B34,'Share Price'!D:D,'Share Price'!F:F) -> 128.79 | L34: =_xlfn.XLOOKUP(C3,'Share Price'!D:D,'Share Price'!F:F) -> 357.18 | M34: =L34/K34 -> 2.773352 | N34: =C34 * M34 -> -138861.9 | O34: =IF(D34="Net Asset Value",O33,-SUM(N11:N34)) -> 1328124.2 | P34: =IF(D34="Net Asset Value", O34, C34) -> -50070.06 | Q34: =_xlfn.XLOOKUP(B34,'Share Price'!D:D,'Share Price'!G:G) -> 220.12 | R34: =_xlfn.XLOOKUP(C3,'Share Price'!D:D,'Share Price'!G:G) -> 124.72 | S34: =R34/Q34 -> 0.56660004 | T34: =C34 * S34 -> -28369.698 | U34: =IF(D34="Net Asset Value",U33,-SUM(T11:T34)) -> 356312.5 | V34: =IF(D34="Net Asset Value", U34, C34) -> -50070.06
B35: 39721 | C35: -11172.275 | D35: Contribution | E35: =_xlfn.XLOOKUP(B35,'Share Price'!D:D,'Share Price'!E:E) -> 38.7491 | F35: =_xlfn.XLOOKUP(C3,'Share Price'!D:D,'Share Price'!E:E) -> 267.26 | G35: =F35/E35 -> 6.8971925 | H35: =C35 * G35 -> -77057.333 | I35: =IF(D35="Net Asset Value",I34,-SUM(H11:H35)) -> 3083318.4 | J35: =IF(D35="Net Asset Value", I35, C35) -> -11172.275 | K35: =_xlfn.XLOOKUP(B35,'Share Price'!D:D,'Share Price'!F:F) -> 115.99 | L35: =_xlfn.XLOOKUP(C3,'Share Price'!D:D,'Share Price'!F:F) -> 357.18 | M35: =L35/K35 -> 3.0794034 | N35: =C35 * M35 -> -34403.943 | O35: =IF(D35="Net Asset Value",O34,-SUM(N11:N35)) -> 1362528.2 | P35: =IF(D35="Net Asset Value", O35, C35) -> -11172.275 | Q35: =_xlfn.XLOOKUP(B35,'Share Price'!D:D,'Share Price'!G:G) -> 179.32 | R35: =_xlfn.XLOOKUP(C3,'Share Price'!D:D,'Share Price'!G:G) -> 124.72 | S35: =R35/Q35 -> 0.6955164 | T35: =C35 * S35 -> -7770.5007 | U35: =IF(D35="Net Asset Value",U34,-SUM(T11:T35)) -> 364083.01 | V35: =IF(D35="Net Asset Value", U35, C35) -> -11172.275
B36: 39752 | C36: -20435.805 | D36: Contribution | E36: =_xlfn.XLOOKUP(B36,'Share Price'!D:D,'Share Price'!E:E) -> 32.754 | F36: =_xlfn.XLOOKUP(C3,'Share Price'!D:D,'Share Price'!E:E) -> 267.26 | G36: =F36/E36 -> 8.1596141 | H36: =C36 * G36 -> -166748.28 | I36: =IF(D36="Net Asset Value",I35,-SUM(H11:H36)) -> 3250066.6 | J36: =IF(D36="Net Asset Value", I36, C36) -> -20435.805 | K36: =_xlfn.XLOOKUP(B36,'Share Price'!D:D,'Share Price'!F:F) -> 96.83 | L36: =_xlfn.XLOOKUP(C3,'Share Price'!D:D,'Share Price'!F:F) -> 357.18 | M36: =L36/K36 -> 3.6887328 | N36: =C36 * M36 -> -75382.224 | O36: =IF(D36="Net Asset Value",O35,-SUM(N11:N36)) -> 1437910.4 | P36: =IF(D36="Net Asset Value", O36, C36) -> -20435.805 | Q36: =_xlfn.XLOOKUP(B36,'Share Price'!D:D,'Share Price'!G:G) -> 136.04 | R36: =_xlfn.XLOOKUP(C3,'Share Price'!D:D,'Share Price'!G:G) -> 124.72 | S36: =R36/Q36 -> 0.91678918 | T36: =C36 * S36 -> -18735.325 | U36: =IF(D36="Net Asset Value",U35,-SUM(T11:T36)) -> 382818.33 | V36: =IF(D36="Net Asset Value", U36, C36) -> -20435.805
B37: 39782 | C37: -18180.183 | D37: Contribution | E37: =_xlfn.XLOOKUP(B37,'Share Price'!D:D,'Share Price'!E:E) -> 28.9996 | F37: =_xlfn.XLOOKUP(C3,'Share Price'!D:D,'Share Price'!E:E) -> 267.26 | G37: =F37/E37 -> 9.2159892 | H37: =C37 * G37 -> -167548.37 | I37: =IF(D37="Net Asset Value",I36,-SUM(H11:H37)) -> 3417615 | J37: =IF(D37="Net Asset Value", I37, C37) -> -18180.183 | K37: =_xlfn.XLOOKUP(B37,'Share Price'!D:D,'Share Price'!F:F) -> 90.09 | L37: =_xlfn.XLOOKUP(C3,'Share Price'!D:D,'Share Price'!F:F) -> 357.18 | M37: =L37/K37 -> 3.964702 | N37: =C37 * M37 -> -72079.007 | O37: =IF(D37="Net Asset Value",O36,-SUM(N11:N37)) -> 1509989.4 | P37: =IF(D37="Net Asset Value", O37, C37) -> -18180.183 | Q37: =_xlfn.XLOOKUP(B37,'Share Price'!D:D,'Share Price'!G:G) -> 124.32 | R37: =_xlfn.XLOOKUP(C3,'Share Price'!D:D,'Share Price'!G:G) -> 124.72 | S37: =R37/Q37 -> 1.0032175 | T37: =C37 * S37 -> -18238.678 | U37: =IF(D37="Net Asset Value",U36,-SUM(T11:T37)) -> 401057.01 | V37: =IF(D37="Net Asset Value", U37, C37) -> -18180.183
B38: 39813 | C38: -15674.56 | D38: Contribution | E38: =_xlfn.XLOOKUP(B38,'Share Price'!D:D,'Share Price'!E:E) -> 29.617 | F38: =_xlfn.XLOOKUP(C3,'Share Price'!D:D,'Share Price'!E:E) -> 267.26 | G38: =F38/E38 -> 9.0238714 | H38: =C38 * G38 -> -141445.22 | I38: =IF(D38="Net Asset Value",I37,-SUM(H11:H38)) -> 3559060.2 | J38: =IF(D38="Net Asset Value", I38, C38) -> -15674.56 | K38: =_xlfn.XLOOKUP(B38,'Share Price'!D:D,'Share Price'!F:F) -> 90.24 | L38: =_xlfn.XLOOKUP(C3,'Share Price'!D:D,'Share Price'!F:F) -> 357.18 | M38: =L38/K38 -> 3.9581117 | N38: =C38 * M38 -> -62041.66 | O38: =IF(D38="Net Asset Value",O37,-SUM(N11:N38)) -> 1572031.1 | P38: =IF(D38="Net Asset Value", O38, C38) -> -15674.56 | Q38: =_xlfn.XLOOKUP(B38,'Share Price'!D:D,'Share Price'!G:G) -> 118.56 | R38: =_xlfn.XLOOKUP(C3,'Share Price'!D:D,'Share Price'!G:G) -> 124.72 | S38: =R38/Q38 -> 1.0519568 | T38: =C38 * S38 -> -16488.96 | U38: =IF(D38="Net Asset Value",U37,-SUM(T11:T38)) -> 417545.97 | V38: =IF(D38="Net Asset Value", U38, C38) -> -15674.56
B39: 39844 | C39: -35731.622 | D39: Contribution | E39: =_xlfn.XLOOKUP(B39,'Share Price'!D:D,'Share Price'!E:E) -> 28.9398 | F39: =_xlfn.XLOOKUP(C3,'Share Price'!D:D,'Share Price'!E:E) -> 267.26 | G39: =F39/E39 -> 9.2350327 | H39: =C39 * G39 -> -329982.7 | I39: =IF(D39="Net Asset Value",I38,-SUM(H11:H39)) -> 3889042.9 | J39: =IF(D39="Net Asset Value", I39, C39) -> -35731.622 | K39: =_xlfn.XLOOKUP(B39,'Share Price'!D:D,'Share Price'!F:F) -> 82.83 | L39: =_xlfn.XLOOKUP(C3,'Share Price'!D:D,'Share Price'!F:F) -> 357.18 | M39: =L39/K39 -> 4.3122057 | N39: =C39 * M39 -> -154082.1 | O39: =IF(D39="Net Asset Value",O38,-SUM(N11:N39)) -> 1726113.2 | P39: =IF(D39="Net Asset Value", O39, C39) -> -35731.622 | Q39: =_xlfn.XLOOKUP(B39,'Share Price'!D:D,'Share Price'!G:G) -> 119.64 | R39: =_xlfn.XLOOKUP(C3,'Share Price'!D:D,'Share Price'!G:G) -> 124.72 | S39: =R39/Q39 -> 1.0424607 | T39: =C39 * S39 -> -37248.812 | U39: =IF(D39="Net Asset Value",U38,-SUM(T11:T39)) -> 454794.78 | V39: =IF(D39="Net Asset Value", U39, C39) -> -35731.622
B40: 39872 | C40: -9630.1874 | D40: Contribution | E40: =_xlfn.XLOOKUP(B40,'Share Price'!D:D,'Share Price'!E:E) -> 27.4162 | F40: =_xlfn.XLOOKUP(C3,'Share Price'!D:D,'Share Price'!E:E) -> 267.26 | G40: =F40/E40 -> 9.748251 | H40: =C40 * G40 -> -93877.485 | I40: =IF(D40="Net Asset Value",I39,-SUM(H11:H40)) -> 3982920.4 | J40: =IF(D40="Net Asset Value", I40, C40) -> -9630.1874 | K40: =_xlfn.XLOOKUP(B40,'Share Price'!D:D,'Share Price'!F:F) -> 73.93 | L40: =_xlfn.XLOOKUP(C3,'Share Price'!D:D,'Share Price'!F:F) -> 357.18 | M40: =L40/K40 -> 4.8313269 | N40: =C40 * M40 -> -46526.584 | O40: =IF(D40="Net Asset Value",O39,-SUM(N11:N40)) -> 1772639.8 | P40: =IF(D40="Net Asset Value", O40, C40) -> -9630.1874 | Q40: =_xlfn.XLOOKUP(B40,'Share Price'!D:D,'Share Price'!G:G) -> 104.04 | R40: =_xlfn.XLOOKUP(C3,'Share Price'!D:D,'Share Price'!G:G) -> 124.72 | S40: =R40/Q40 -> 1.1987697 | T40: =C40 * S40 -> -11544.377 | U40: =IF(D40="Net Asset Value",U39,-SUM(T11:T40)) -> 466339.16 | V40: =IF(D40="Net Asset Value", U40, C40) -> -9630.1874
B41: 39903 | C41: -22454.967 | D41: Contribution | E41: =_xlfn.XLOOKUP(B41,'Share Price'!D:D,'Share Price'!E:E) -> 30.1946 | F41: =_xlfn.XLOOKUP(C3,'Share Price'!D:D,'Share Price'!E:E) -> 267.26 | G41: =F41/E41 -> 8.8512515 | H41: =C41 * G41 -> -198754.56 | I41: =IF(D41="Net Asset Value",I40,-SUM(H11:H41)) -> 4181675 | J41: =IF(D41="Net Asset Value", I41, C41) -> -22454.967 | K41: =_xlfn.XLOOKUP(B41,'Share Price'!D:D,'Share Price'!F:F) -> 79.52 | L41: =_xlfn.XLOOKUP(C3,'Share Price'!D:D,'Share Price'!F:F) -> 357.18 | M41: =L41/K41 -> 4.4917002 | N41: =C41 * M41 -> -100860.98 | O41: =IF(D41="Net Asset Value",O40,-SUM(N11:N41)) -> 1873500.7 | P41: =IF(D41="Net Asset Value", O41, C41) -> -22454.967 | Q41: =_xlfn.XLOOKUP(B41,'Share Price'!D:D,'Share Price'!G:G) -> 106.4 | R41: =_xlfn.XLOOKUP(C3,'Share Price'!D:D,'Share Price'!G:G) -> 124.72 | S41: =R41/Q41 -> 1.1721805 | T41: =C41 * S41 -> -26321.273 | U41: =IF(D41="Net Asset Value",U40,-SUM(T11:T41)) -> 492660.43 | V41: =IF(D41="Net Asset Value", U41, C41) -> -22454.967
...

Sheet Fund VII
B1: Inputs | E1: Outputs | K1: Cash Flow Summary
B2: Fund Name | C2: Fund VII | F2: PME Index 1 | G2: PME Index 2 | H2: PME Index 3 | L2: Actual | M2: PME Index 1 | N2: PME Index 2 | O2: PME Index 3
B3: End Date | C3: =B183 -> 45077 | E3: Actual IRR | F3: =IFERROR(XIRR(C11:C183, B11:B183, IF(SUM(C11:C183) > 0, 0.15, -0.15)), "NA") -> 0.24436759 | G3: =IFERROR(XIRR(C11:C183, B11:B183, IF(SUM(C11:C183) > 0, 0.15, -0.15)), "NA") -> 0.24436759 | H3: =IFERROR(XIRR(C11:C183, B11:B183, IF(SUM(C11:C183) > 0, 0.15, -0.15)), "NA") -> 0.24436759 | K3: Distribution | L3: =SUMIFS(C11:C183, D11:D183, K3) -> 3433106.2 | M3: =SUMIFS(H11:H183, D11:D183, K3) -> 16815328 | N3: =SUMIFS(N11:N183, D11:D183, K3) -> 9396881.7 | O3: =SUMIFS(T11:T183, D11:D183, K3) -> 2030075.8
B4: Index 1 | C4: ='Share Price'!B3 -> QQQ | E4: PME IRR | F4: =IFERROR(XIRR(J11:J183, B11:B183, IF(SUM(J11:J183) > 0, 0.15, -0.15)), "NA") -> 0.24436759 | G4: =IFERROR(XIRR(P11:P183, B11:B183, IF(SUM(P11:P183) > 0, 0.15, -0.15)), "NA") -> 0.24436759 | H4: =IFERROR(XIRR(V11:V183, B11:B183, IF(SUM(V11:V183) > 0, 0.15, -0.15)), "NA") -> 0.24436759 | K4: Contribution | L4: =SUMIFS(C11:C183, D11:D183, K4) -> -1921130.5 | M4: =SUMIFS(H11:H183, D11:D183, K4) -> -13836414 | N4: =SUMIFS(N11:N183, D11:D183, K4) -> -6646792.2 | O4: =SUMIFS(T11:T183, D11:D183, K4) -> -1266632.1
B5: Index 2 | C5: ='Share Price'!B4 -> SPY | E5: Direct Alpha IRR | F5: =IFERROR(XIRR(H11:H183, B11:B183, IF(SUM(H11:H183) > 0, 0.15, -0.15)), "NA") -> 0.081310822 | G5: =IFERROR(XIRR(N11:N183, B11:B183, IF(SUM(N11:N183) > 0, 0.15, -0.15)), "NA") -> 0.15234383 | H5: =IFERROR(XIRR(T11:T183, B11:B183, IF(SUM(T11:T183) > 0, 0.15, -0.15)), "NA") -> 0.16453523 | K5: Net Asset Value | L5: =SUMIFS(C11:C183, D11:D183, K5) -> 0 | M5: =SUMIFS(H11:H183, D11:D183, K5) -> 0 | N5: =SUMIFS(N11:N183, D11:D183, K5) -> 0 | O5: =SUMIFS(T11:T183, D11:D183, K5) -> 0
B6: Index 3 | C6: ='Share Price'!B5 -> XOP | E6: KS-PME | F6: =(M3 + M5) / -M4 -> 1.2152952 | G6: =(N3 + N5) / -N4 -> 1.4137469 | H6: =(O3 + O5) / -O4 -> 1.6027353
B8: Cash Flow Data | E8: Index 1 Portfolio | K8: Index 2 Portfolio | Q8: Index 3 Portfolio
E9: Index Value at | H9: NAV | I9: End Date | J9: PME | K9: Index Value at | N9: NAV | O9: End Date | P9: PME | Q9: Index Value at | T9: NAV | U9: End Date | V9: PME
B10: Date | C10: Amount | D10: Type | E10: CF Date | F10: End Date | G10: Factor | H10: Contribution | I10: NAV | J10: Cash Flow | K10: CF Date | L10: End Date | M10: Factor | N10: Contribution | O10: NAV | P10: Cash Flow | Q10: CF Date | R10: End Date | S10: Factor | T10: Contribution | U10: NAV | V10: Cash Flow
B11: 39355 | C11: -11834.62 | D11: Contribution | E11: =_xlfn.XLOOKUP(B11,'Share Price'!D:D,'Share Price'!E:E) -> 51.1974 | F11: =_xlfn.XLOOKUP(C3,'Share Price'!D:D,'Share Price'!E:E) -> 347.99 | G11: =F11/E11 -> 6.7970248 | H11: =C11 * G11 -> -80440.204 | I11: =IF(D11="Net Asset Value",I10,-SUM(H11:H11)) -> 80440.204 | J11: =IF(D11="Net Asset Value", I11, C11) -> -11834.62 | K11: =_xlfn.XLOOKUP(B11,'Share Price'!D:D,'Share Price'!F:F) -> 152.58 | L11: =_xlfn.XLOOKUP(C3,'Share Price'!D:D,'Share Price'!F:F) -> 417.85 | M11: =L11/K11 -> 2.7385634 | N11: =C11 * M11 -> -32409.856 | O11: =IF(D11="Net Asset Value",O10,-SUM(N11:N11)) -> 32409.856 | P11: =IF(D11="Net Asset Value", O11, C11) -> -11834.62 | Q11: =_xlfn.XLOOKUP(B11,'Share Price'!D:D,'Share Price'!G:G) -> 188.12 | R11: =_xlfn.XLOOKUP(C3,'Share Price'!D:D,'Share Price'!G:G) -> 118.09 | S11: =R11/Q11 -> 0.62773761 | T11: =C11 * S11 -> -7429.0359 | U11: =IF(D11="Net Asset Value",U10,-SUM(T11:T11)) -> 7429.0359 | V11: =IF(D11="Net Asset Value", U11, C11) -> -11834.62
B12: 39386 | C12: -36858.827 | D12: Contribution | E12: =_xlfn.XLOOKUP(B12,'Share Price'!D:D,'Share Price'!E:E) -> 54.8025 | F12: =_xlfn.XLOOKUP(C3,'Share Price'!D:D,'Share Price'!E:E) -> 347.99 | G12: =F12/E12 -> 6.3498928 | H12: =C12 * G12 -> -234049.6 | I12: =IF(D12="Net Asset Value",I11,-SUM(H11:H12)) -> 314489.8 | J12: =IF(D12="Net Asset Value", I12, C12) -> -36858.827 | K12: =_xlfn.XLOOKUP(B12,'Share Price'!D:D,'Share Price'!F:F) -> 154.65 | L12: =_xlfn.XLOOKUP(C3,'Share Price'!D:D,'Share Price'!F:F) -> 417.85 | M12: =L12/K12 -> 2.7019075 | N12: =C12 * M12 -> -99589.142 | O12: =IF(D12="Net Asset Value",O11,-SUM(N11:N12)) -> 131999 | P12: =IF(D12="Net Asset Value", O12, C12) -> -36858.827 | Q12: =_xlfn.XLOOKUP(B12,'Share Price'!D:D,'Share Price'!G:G) -> 211.64 | R12: =_xlfn.XLOOKUP(C3,'Share Price'!D:D,'Share Price'!G:G) -> 118.09 | S12: =R12/Q12 -> 0.55797581 | T12: =C12 * S12 -> -20566.334 | U12: =IF(D12="Net Asset Value",U11,-SUM(T11:T12)) -> 27995.37 | V12: =IF(D12="Net Asset Value", U12, C12) -> -36858.827
B13: 39416 | C13: 7854.55 | D13: Distribution | E13: =_xlfn.XLOOKUP(B13,'Share Price'!D:D,'Share Price'!E:E) -> 51.0978 | F13: =_xlfn.XLOOKUP(C3,'Share Price'!D:D,'Share Price'!E:E) -> 347.99 | G13: =F13/E13 -> 6.8102736 | H13: =C13 * G13 -> 53491.635 | I13: =IF(D13="Net Asset Value",I12,-SUM(H11:H13)) -> 260998.17 | J13: =IF(D13="Net Asset Value", I13, C13) -> 7854.55 | K13: =_xlfn.XLOOKUP(B13,'Share Price'!D:D,'Share Price'!F:F) -> 148.66 | L13: =_xlfn.XLOOKUP(C3,'Share Price'!D:D,'Share Price'!F:F) -> 417.85 | M13: =L13/K13 -> 2.8107763 | N13: =C13 * M13 -> 22077.383 | O13: =IF(D13="Net Asset Value",O12,-SUM(N11:N13)) -> 109921.62 | P13: =IF(D13="Net Asset Value", O13, C13) -> 7854.55 | Q13: =_xlfn.XLOOKUP(B13,'Share Price'!D:D,'Share Price'!G:G) -> 194.08 | R13: =_xlfn.XLOOKUP(C3,'Share Price'!D:D,'Share Price'!G:G) -> 118.09 | S13: =R13/Q13 -> 0.60846043 | T13: =C13 * S13 -> 4779.1829 | U13: =IF(D13="Net Asset Value",U12,-SUM(T11:T13)) -> 23216.187 | V13: =IF(D13="Net Asset Value", U13, C13) -> 7854.55
B14: 39447 | C14: -10049.244 | D14: Contribution | E14: =_xlfn.XLOOKUP(B14,'Share Price'!D:D,'Share Price'!E:E) -> 51.0082 | F14: =_xlfn.XLOOKUP(C3,'Share Price'!D:D,'Share Price'!E:E) -> 347.99 | G14: =F14/E14 -> 6.8222364 | H14: =C14 * G14 -> -68558.318 | I14: =IF(D14="Net Asset Value",I13,-SUM(H11:H14)) -> 329556.49 | J14: =IF(D14="Net Asset Value", I14, C14) -> -10049.244 | K14: =_xlfn.XLOOKUP(B14,'Share Price'!D:D,'Share Price'!F:F) -> 146.21 | L14: =_xlfn.XLOOKUP(C3,'Share Price'!D:D,'Share Price'!F:F) -> 417.85 | M14: =L14/K14 -> 2.8578757 | N14: =C14 * M14 -> -28719.489 | O14: =IF(D14="Net Asset Value",O13,-SUM(N11:N14)) -> 138641.1 | P14: =IF(D14="Net Asset Value", O14, C14) -> -10049.244 | Q14: =_xlfn.XLOOKUP(B14,'Share Price'!D:D,'Share Price'!G:G) -> 208 | R14: =_xlfn.XLOOKUP(C3,'Share Price'!D:D,'Share Price'!G:G) -> 118.09 | S14: =R14/Q14 -> 0.56774038 | T14: =C14 * S14 -> -5705.3616 | U14: =IF(D14="Net Asset Value",U13,-SUM(T11:T14)) -> 28921.548 | V14: =IF(D14="Net Asset Value", U14, C14) -> -10049.244
B15: 39478 | C15: -465.35324 | D15: Contribution | E15: =_xlfn.XLOOKUP(B15,'Share Price'!D:D,'Share Price'!E:E) -> 44.9434 | F15: =_xlfn.XLOOKUP(C3,'Share Price'!D:D,'Share Price'!E:E) -> 347.99 | G15: =F15/E15 -> 7.7428499 | H15: =C15 * G15 -> -3603.1603 | I15: =IF(D15="Net Asset Value",I14,-SUM(H11:H15)) -> 333159.65 | J15: =IF(D15="Net Asset Value", I15, C15) -> -465.35324 | K15: =_xlfn.XLOOKUP(B15,'Share Price'!D:D,'Share Price'!F:F) -> 137.37 | L15: =_xlfn.XLOOKUP(C3,'Share Price'!D:D,'Share Price'!F:F) -> 417.85 | M15: =L15/K15 -> 3.041785 | N15: =C15 * M15 -> -1415.5045 | O15: =IF(D15="Net Asset Value",O14,-SUM(N11:N15)) -> 140056.61 | P15: =IF(D15="Net Asset Value", O15, C15) -> -465.35324 | Q15: =_xlfn.XLOOKUP(B15,'Share Price'!D:D,'Share Price'!G:G) -> 192.16 | R15: =_xlfn.XLOOKUP(C3,'Share Price'!D:D,'Share Price'!G:G) -> 118.09 | S15: =R15/Q15 -> 0.61453997 | T15: =C15 * S15 -> -285.97817 | U15: =IF(D15="Net Asset Value",U14,-SUM(T11:T15)) -> 29207.526 | V15: =IF(D15="Net Asset Value", U15, C15) -> -465.35324
B16: 39507 | C16: -13137.586 | D16: Contribution | E16: =_xlfn.XLOOKUP(B16,'Share Price'!D:D,'Share Price'!E:E) -> 42.7724 | F16: =_xlfn.XLOOKUP(C3,'Share Price'!D:D,'Share Price'!E:E) -> 347.99 | G16: =F16/E16 -> 8.135854 | H16: =C16 * G16 -> -106885.48 | I16: =IF(D16="Net Asset Value",I15,-SUM(H11:H16)) -> 440045.12 | J16: =IF(D16="Net Asset Value", I16, C16) -> -13137.586 | K16: =_xlfn.XLOOKUP(B16,'Share Price'!D:D,'Share Price'!F:F) -> 133.82 | L16: =_xlfn.XLOOKUP(C3,'Share Price'!D:D,'Share Price'!F:F) -> 417.85 | M16: =L16/K16 -> 3.122478 | N16: =C16 * M16 -> -41021.822 | O16: =IF(D16="Net Asset Value",O15,-SUM(N11:N16)) -> 181078.43 | P16: =IF(D16="Net Asset Value", O16, C16) -> -13137.586 | Q16: =_xlfn.XLOOKUP(B16,'Share Price'!D:D,'Share Price'!G:G) -> 217.9196 | R16: =_xlfn.XLOOKUP(C3,'Share Price'!D:D,'Share Price'!G:G) -> 118.09 | S16: =R16/Q16 -> 0.5418971 | T16: =C16 * S16 -> -7119.2197 | U16: =IF(D16="Net Asset Value",U15,-SUM(T11:T16)) -> 36326.746 | V16: =IF(D16="Net Asset Value", U16, C16) -> -13137.586
B17: 39538 | C17: -19990.477 | D17: Contribution | E17: =_xlfn.XLOOKUP(B17,'Share Price'!D:D,'Share Price'!E:E) -> 43.5392 | F17: =_xlfn.XLOOKUP(C3,'Share Price'!D:D,'Share Price'!E:E) -> 347.99 | G17: =F17/E17 -> 7.9925676 | H17: =C17 * G17 -> -159775.24 | I17: =IF(D17="Net Asset Value",I16,-SUM(H11:H17)) -> 599820.36 | J17: =IF(D17="Net Asset Value", I17, C17) -> -19990.477 | K17: =_xlfn.XLOOKUP(B17,'Share Price'!D:D,'Share Price'!F:F) -> 131.97 | L17: =_xlfn.XLOOKUP(C3,'Share Price'!D:D,'Share Price'!F:F) -> 417.85 | M17: =L17/K17 -> 3.1662499 | N17: =C17 * M17 -> -63294.846 | O17: =IF(D17="Net Asset Value",O16,-SUM(N11:N17)) -> 244373.28 | P17: =IF(D17="Net Asset Value", O17, C17) -> -19990.477 | Q17: =_xlfn.XLOOKUP(B17,'Share Price'!D:D,'Share Price'!G:G) -> 215 | R17: =_xlfn.XLOOKUP(C3,'Share Price'!D:D,'Share Price'!G:G) -> 118.09 | S17: =R17/Q17 -> 0.54925581 | T17: =C17 * S17 -> -10979.886 | U17: =IF(D17="Net Asset Value",U16,-SUM(T11:T17)) -> 47306.632 | V17: =IF(D17="Net Asset Value", U17, C17) -> -19990.477
B18: 39568 | C18: -22116.806 | D18: Contribution | E18: =_xlfn.XLOOKUP(B18,'Share Price'!D:D,'Share Price'!E:E) -> 47.0148 | F18: =_xlfn.XLOOKUP(C3,'Share Price'!D:D,'Share Price'!E:E) -> 347.99 | G18: =F18/E18 -> 7.4017118 | H18: =C18 * G18 -> -163702.22 | I18: =IF(D18="Net Asset Value",I17,-SUM(H11:H18)) -> 763522.59 | J18: =IF(D18="Net Asset Value", I18, C18) -> -22116.806 | K18: =_xlfn.XLOOKUP(B18,'Share Price'!D:D,'Share Price'!F:F) -> 138.26 | L18: =_xlfn.XLOOKUP(C3,'Share Price'!D:D,'Share Price'!F:F) -> 417.85 | M18: =L18/K18 -> 3.0222045 | N18: =C18 * M18 -> -66841.512 | O18: =IF(D18="Net Asset Value",O17,-SUM(N11:N18)) -> 311214.79 | P18: =IF(D18="Net Asset Value", O18, C18) -> -22116.806 | Q18: =_xlfn.XLOOKUP(B18,'Share Price'!D:D,'Share Price'!G:G) -> 235.56 | R18: =_xlfn.XLOOKUP(C3,'Share Price'!D:D,'Share Price'!G:G) -> 118.09 | S18: =R18/Q18 -> 0.50131601 | T18: =C18 * S18 -> -11087.509 | U18: =IF(D18="Net Asset Value",U17,-SUM(T11:T18)) -> 58394.141 | V18: =IF(D18="Net Asset Value", U18, C18) -> -22116.806
B19: 39599 | C19: -46459.994 | D19: Contribution | E19: =_xlfn.XLOOKUP(B19,'Share Price'!D:D,'Share Price'!E:E) -> 49.8032 | F19: =_xlfn.XLOOKUP(C3,'Share Price'!D:D,'Share Price'!E:E) -> 347.99 | G19: =F19/E19 -> 6.987302 | H19: =C19 * G19 -> -324630.01 | I19: =IF(D19="Net Asset Value",I18,-SUM(H11:H19)) -> 1088152.6 | J19: =IF(D19="Net Asset Value", I19, C19) -> -46459.994 | K19: =_xlfn.XLOOKUP(B19,'Share Price'!D:D,'Share Price'!F:F) -> 140.35 | L19: =_xlfn.XLOOKUP(C3,'Share Price'!D:D,'Share Price'!F:F) -> 417.85 | M19: =L19/K19 -> 2.9771999 | N19: =C19 * M19 -> -138320.69 | O19: =IF(D19="Net Asset Value",O18,-SUM(N11:N19)) -> 449535.48 | P19: =IF(D19="Net Asset Value", O19, C19) -> -46459.994 | Q19: =_xlfn.XLOOKUP(B19,'Share Price'!D:D,'Share Price'!G:G) -> 259.08 | R19: =_xlfn.XLOOKUP(C3,'Share Price'!D:D,'Share Price'!G:G) -> 118.09 | S19: =R19/Q19 -> 0.45580516 | T19: =C19 * S19 -> -21176.705 | U19: =IF(D19="Net Asset Value",U18,-SUM(T11:T19)) -> 79570.846 | V19: =IF(D19="Net Asset Value", U19, C19) -> -46459.994
B20: 39629 | C20: -62158.13 | D20: Contribution | E20: =_xlfn.XLOOKUP(B20,'Share Price'!D:D,'Share Price'!E:E) -> 44.9832 | F20: =_xlfn.XLOOKUP(C3,'Share Price'!D:D,'Share Price'!E:E) -> 347.99 | G20: =F20/E20 -> 7.7359992 | H20: =C20 * G20 -> -480855.25 | I20: =IF(D20="Net Asset Value",I19,-SUM(H11:H20)) -> 1569007.8 | J20: =IF(D20="Net Asset Value", I20, C20) -> -62158.13 | K20: =_xlfn.XLOOKUP(B20,'Share Price'!D:D,'Share Price'!F:F) -> 127.98 | L20: =_xlfn.XLOOKUP(C3,'Share Price'!D:D,'Share Price'!F:F) -> 417.85 | M20: =L20/K20 -> 3.2649633 | N20: =C20 * M20 -> -202944.01 | O20: =IF(D20="Net Asset Value",O19,-SUM(N11:N20)) -> 652479.49 | P20: =IF(D20="Net Asset Value", O20, C20) -> -62158.13 | Q20: =_xlfn.XLOOKUP(B20,'Share Price'!D:D,'Share Price'!G:G) -> 281.12 | R20: =_xlfn.XLOOKUP(C3,'Share Price'!D:D,'Share Price'!G:G) -> 118.09 | S20: =R20/Q20 -> 0.42006972 | T20: =C20 * S20 -> -26110.748 | U20: =IF(D20="Net Asset Value",U19,-SUM(T11:T20)) -> 105681.59 | V20: =IF(D20="Net Asset Value", U20, C20) -> -62158.13
B21: 39660 | C21: -37011.148 | D21: Contribution | E21: =_xlfn.XLOOKUP(B21,'Share Price'!D:D,'Share Price'!E:E) -> 45.272 | F21: =_xlfn.XLOOKUP(C3,'Share Price'!D:D,'Share Price'!E:E) -> 347.99 | G21: =F21/E21 -> 7.6866496 | H21: =C21 * G21 -> -284491.72 | I21: =IF(D21="Net Asset Value",I20,-SUM(H11:H21)) -> 1853499.6 | J21: =IF(D21="Net Asset Value", I21, C21) -> -37011.148 | K21: =_xlfn.XLOOKUP(B21,'Share Price'!D:D,'Share Price'!F:F) -> 126.83 | L21: =_xlfn.XLOOKUP(C3,'Share Price'!D:D,'Share Price'!F:F) -> 417.85 | M21: =L21/K21 -> 3.2945675 | N21: =C21 * M21 -> -121935.73 | O21: =IF(D21="Net Asset Value",O20,-SUM(N11:N21)) -> 774415.21 | P21: =IF(D21="Net Asset Value", O21, C21) -> -37011.148 | Q21: =_xlfn.XLOOKUP(B21,'Share Price'!D:D,'Share Price'!G:G) -> 216.32 | R21: =_xlfn.XLOOKUP(C3,'Share Price'!D:D,'Share Price'!G:G) -> 118.09 | S21: =R21/Q21 -> 0.54590422 | T21: =C21 * S21 -> -20204.542 | U21: =IF(D21="Net Asset Value",U20,-SUM(T11:T21)) -> 125886.14 | V21: =IF(D21="Net Asset Value", U21, C21) -> -37011.148
B22: 39691 | C22: -77435.159 | D22: Contribution | E22: =_xlfn.XLOOKUP(B22,'Share Price'!D:D,'Share Price'!E:E) -> 45.9293 | F22: =_xlfn.XLOOKUP(C3,'Share Price'!D:D,'Share Price'!E:E) -> 347.99 | G22: =F22/E22 -> 7.576645 | H22: =C22 * G22 -> -586698.71 | I22: =IF(D22="Net Asset Value",I21,-SUM(H11:H22)) -> 2440198.3 | J22: =IF(D22="Net Asset Value", I22, C22) -> -77435.159 | K22: =_xlfn.XLOOKUP(B22,'Share Price'!D:D,'Share Price'!F:F) -> 128.79 | L22: =_xlfn.XLOOKUP(C3,'Share Price'!D:D,'Share Price'!F:F) -> 417.85 | M22: =L22/K22 -> 3.2444289 | N22: =C22 * M22 -> -251232.87 | O22: =IF(D22="Net Asset Value",O21,-SUM(N11:N22)) -> 1025648.1 | P22: =IF(D22="Net Asset Value", O22, C22) -> -77435.159 | Q22: =_xlfn.XLOOKUP(B22,'Share Price'!D:D,'Share Price'!G:G) -> 220.12 | R22: =_xlfn.XLOOKUP(C3,'Share Price'!D:D,'Share Price'!G:G) -> 118.09 | S22: =R22/Q22 -> 0.5364801 | T22: =C22 * S22 -> -41542.422 | U22: =IF(D22="Net Asset Value",U21,-SUM(T11:T22)) -> 167428.56 | V22: =IF(D22="Net Asset Value", U22, C22) -> -77435.159
B23: 39721 | C23: -11036.716 | D23: Contribution | E23: =_xlfn.XLOOKUP(B23,'Share Price'!D:D,'Share Price'!E:E) -> 38.7491 | F23: =_xlfn.XLOOKUP(C3,'Share Price'!D:D,'Share Price'!E:E) -> 347.99 | G23: =F23/E23 -> 8.9805957 | H23: =C23 * G23 -> -99116.283 | I23: =IF(D23="Net Asset Value",I22,-SUM(H11:H23)) -> 2539314.6 | J23: =IF(D23="Net Asset Value", I23, C23) -> -11036.716 | K23: =_xlfn.XLOOKUP(B23,'Share Price'!D:D,'Share Price'!F:F) -> 115.99 | L23: =_xlfn.XLOOKUP(C3,'Share Price'!D:D,'Share Price'!F:F) -> 417.85 | M23: =L23/K23 -> 3.6024657 | N23: =C23 * M23 -> -39759.391 | O23: =IF(D23="Net Asset Value",O22,-SUM(N11:N23)) -> 1065407.5 | P23: =IF(D23="Net Asset Value", O23, C23) -> -11036.716 | Q23: =_xlfn.XLOOKUP(B23,'Share Price'!D:D,'Share Price'!G:G) -> 179.32 | R23: =_xlfn.XLOOKUP(C3,'Share Price'!D:D,'Share Price'!G:G) -> 118.09 | S23: =R23/Q23 -> 0.65854339 | T23: =C23 * S23 -> -7268.1563 | U23: =IF(D23="Net Asset Value",U22,-SUM(T11:T23)) -> 174696.71 | V23: =IF(D23="Net Asset Value", U23, C23) -> -11036.716
B24: 39752 | C24: -19038.491 | D24: Contribution | E24: =_xlfn.XLOOKUP(B24,'Share Price'!D:D,'Share Price'!E:E) -> 32.754 | F24: =_xlfn.XLOOKUP(C3,'Share Price'!D:D,'Share Price'!E:E) -> 347.99 | G24: =F24/E24 -> 10.624351 | H24: =C24 * G24 -> -202271.61 | I24: =IF(D24="Net Asset Value",I23,-SUM(H11:H24)) -> 2741586.2 | J24: =IF(D24="Net Asset Value", I24, C24) -> -19038.491 | K24: =_xlfn.XLOOKUP(B24,'Share Price'!D:D,'Share Price'!F:F) -> 96.83 | L24: =_xlfn.XLOOKUP(C3,'Share Price'!D:D,'Share Price'!F:F) -> 417.85 | M24: =L24/K24 -> 4.3152948 | N24: =C24 * M24 -> -82156.701 | O24: =IF(D24="Net Asset Value",O23,-SUM(N11:N24)) -> 1147564.2 | P24: =IF(D24="Net Asset Value", O24, C24) -> -19038.491 | Q24: =_xlfn.XLOOKUP(B24,'Share Price'!D:D,'Share Price'!G:G) -> 136.04 | R24: =_xlfn.XLOOKUP(C3,'Share Price'!D:D,'Share Price'!G:G) -> 118.09 | S24: =R24/Q24 -> 0.86805351 | T24: =C24 * S24 -> -16526.429 | U24: =IF(D24="Net Asset Value",U23,-SUM(T11:T24)) -> 191223.14 | V24: =IF(D24="Net Asset Value", U24, C24) -> -19038.491
B25: 39782 | C25: -44797.408 | D25: Contribution | E25: =_xlfn.XLOOKUP(B25,'Share Price'!D:D,'Share Price'!E:E) -> 28.9996 | F25: =_xlfn.XLOOKUP(C3,'Share Price'!D:D,'Share Price'!E:E) -> 347.99 | G25: =F25/E25 -> 11.999821 | H25: =C25 * G25 -> -537560.87 | I25: =IF(D25="Net Asset Value",I24,-SUM(H11:H25)) -> 3279147 | J25: =IF(D25="Net Asset Value", I25, C25) -> -44797.408 | K25: =_xlfn.XLOOKUP(B25,'Share Price'!D:D,'Share Price'!F:F) -> 90.09 | L25: =_xlfn.XLOOKUP(C3,'Share Price'!D:D,'Share Price'!F:F) -> 417.85 | M25: =L25/K25 -> 4.6381396 | N25: =C25 * M25 -> -207776.63 | O25: =IF(D25="Net Asset Value",O24,-SUM(N11:N25)) -> 1355340.8 | P25: =IF(D25="Net Asset Value", O25, C25) -> -44797.408 | Q25: =_xlfn.XLOOKUP(B25,'Share Price'!D:D,'Share Price'!G:G) -> 124.32 | R25: =_xlfn.XLOOKUP(C3,'Share Price'!D:D,'Share Price'!G:G) -> 118.09 | S25: =R25/Q25 -> 0.94988739 | T25: =C25 * S25 -> -42552.493 | U25: =IF(D25="Net Asset Value",U24,-SUM(T11:T25)) -> 233775.64 | V25: =IF(D25="Net Asset Value", U25, C25) -> -44797.408
B26: 39813 | C26: -37446.28 | D26: Contribution | E26: =_xlfn.XLOOKUP(B26,'Share Price'!D:D,'Share Price'!E:E) -> 29.617 | F26: =_xlfn.XLOOKUP(C3,'Share Price'!D:D,'Share Price'!E:E) -> 347.99 | G26: =F26/E26 -> 11.749671 | H26: =C26 * G26 -> -439981.46 | I26: =IF(D26="Net Asset Value",I25,-SUM(H11:H26)) -> 3719128.5 | J26: =IF(D26="Net Asset Value", I26, C26) -> -37446.28 | K26: =_xlfn.XLOOKUP(B26,'Share Price'!D:D,'Share Price'!F:F) -> 90.24 | L26: =_xlfn.XLOOKUP(C3,'Share Price'!D:D,'Share Price'!F:F) -> 417.85 | M26: =L26/K26 -> 4.63043 | N26: =C26 * M26 -> -173392.38 | O26: =IF(D26="Net Asset Value",O25,-SUM(N11:N26)) -> 1528733.2 | P26: =IF(D26="Net Asset Value", O26, C26) -> -37446.28 | Q26: =_xlfn.XLOOKUP(B26,'Share Price'!D:D,'Share Price'!G:G) -> 118.56 | R26: =_xlfn.XLOOKUP(C3,'Share Price'!D:D,'Share Price'!G:G) -> 118.09 | S26: =R26/Q26 -> 0.99603576 | T26: =C26 * S26 -> -37297.834 | U26: =IF(D26="Net Asset Value",U25,-SUM(T11:T26)) -> 271073.47 | V26: =IF(D26="Net Asset Value", U26, C26) -> -37446.28
B27: 39844 | C27: -49394.592 | D27: Contribution | E27: =_xlfn.XLOOKUP(B27,'Share Price'!D:D,'Share Price'!E:E) -> 28.9398 | F27: =_xlfn.XLOOKUP(C3,'Share Price'!D:D,'Share Price'!E:E) -> 347.99 | G27: =F27/E27 -> 12.024617 | H27: =C27 * G27 -> -593951.03 | I27: =IF(D27="Net Asset Value",I26,-SUM(H11:H27)) -> 4313079.5 | J27: =IF(D27="Net Asset Value", I27, C27) -> -49394.592 | K27: =_xlfn.XLOOKUP(B27,'Share Price'!D:D,'Share Price'!F:F) -> 82.83 | L27: =_xlfn.XLOOKUP(C3,'Share Price'!D:D,'Share Price'!F:F) -> 417.85 | M27: =L27/K27 -> 5.0446698 | N27: =C27 * M27 -> -249179.41 | O27: =IF(D27="Net Asset Value",O26,-SUM(N11:N27)) -> 1777912.6 | P27: =IF(D27="Net Asset Value", O27, C27) -> -49394.592 | Q27: =_xlfn.XLOOKUP(B27,'Share Price'!D:D,'Share Price'!G:G) -> 119.64 | R27: =_xlfn.XLOOKUP(C3,'Share Price'!D:D,'Share Price'!G:G) -> 118.09 | S27: =R27/Q27 -> 0.98704447 | T27: =C27 * S27 -> -48754.659 | U27: =IF(D27="Net Asset Value",U26,-SUM(T11:T27)) -> 319828.13 | V27: =IF(D27="Net Asset Value", U27, C27) -> -49394.592
B28: 39872 | C28: -24805.729 | D28: Contribution | E28: =_xlfn.XLOOKUP(B28,'Share Price'!D:D,'Share Price'!E:E) -> 27.4162 | F28: =_xlfn.XLOOKUP(C3,'Share Price'!D:D,'Share Price'!E:E) -> 347.99 | G28: =F28/E28 -> 12.69286 | H28: =C28 * G28 -> -314855.65 | I28: =IF(D28="Net Asset Value",I27,-SUM(H11:H28)) -> 4627935.2 | J28: =IF(D28="Net Asset Value", I28, C28) -> -24805.729 | K28: =_xlfn.XLOOKUP(B28,'Share Price'!D:D,'Share Price'!F:F) -> 73.93 | L28: =_xlfn.XLOOKUP(C3,'Share Price'!D:D,'Share Price'!F:F) -> 417.85 | M28: =L28/K28 -> 5.6519681 | N28: =C28 * M28 -> -140201.19 | O28: =IF(D28="Net Asset Value",O27,-SUM(N11:N28)) -> 1918113.8 | P28: =IF(D28="Net Asset Value", O28, C28) -> -24805.729 | Q28: =_xlfn.XLOOKUP(B28,'Share Price'!D:D,'Share Price'!G:G) -> 104.04 | R28: =_xlfn.XLOOKUP(C3,'Share Price'!D:D,'Share Price'!G:G) -> 118.09 | S28: =R28/Q28 -> 1.1350442 | T28: =C28 * S28 -> -28155.599 | U28: =IF(D28="Net Asset Value",U27,-SUM(T11:T28)) -> 347983.73 | V28: =IF(D28="Net Asset Value", U28, C28) -> -24805.729
