Workbook

Sheet Fund-Level Alpha
B2: EnCap Investments - Fund-level Alpha Analysis
B4: Fund | C4: Vintage | D4: Net IRR | E4: MSCI Natural Resources | F4: Alpha | G4: Pitchbook O&G | H4: Alpha | I4: Average Fund Alpha
B5: Upstream Fund XI | C5: 2017 | D5: 22.2% | E5: =VLOOKUP(C5,'MSCI Natural Resources'!B4:C19,2) -> 0.092 | F5: =$D5-E5 -> 0.13 | G5: =VLOOKUP(C5,'Pitchbook O&G'!$B$3:$C$22,2) -> 0.0974 | H5: =$D5-G5 -> 0.1246 | I5: =AVERAGE(F5,H5) -> 0.1273
B6: Upstream Fund X | C6: 2015 | D6: 16.4% | E6: =VLOOKUP(C6,'MSCI Natural Resources'!B5:C20,2) -> 0.08 | F6: =$D6-E6 -> 0.084 | G6: =VLOOKUP(C6,'Pitchbook O&G'!$B$3:$C$22,2) -> 0.093 | H6: =$D6-G6 -> 0.071 | I6: =AVERAGE(F6,H6) -> 0.0775
B7: Upstream Fund IX | C7: 2013 | D7: 10.9% | E7: =VLOOKUP(C7,'MSCI Natural Resources'!B6:C21,2) -> 0.037 | F7: =$D7-E7 -> 0.072 | G7: =VLOOKUP(C7,'Pitchbook O&G'!$B$3:$C$22,2) -> 0.013 | H7: =$D7-G7 -> 0.096 | I7: =AVERAGE(F7,H7) -> 0.084
B8: Upstream Fund VIII | C8: 2010 | D8: 0.6% | E8: =VLOOKUP(C8,'MSCI Natural Resources'!B4:C19,2) -> 0.012 | F8: =$D8-E8 -> -0.006 | G8: =VLOOKUP(C8,'Pitchbook O&G'!$B$3:$C$22,2) -> -0.148 | H8: =$D8-G8 -> 0.154 | I8: =AVERAGE(F8,H8) -> 0.074
B9: Upstream Fund VII | C9: 2007 | D9: 14.5% | G9: =VLOOKUP(C9,'Pitchbook O&G'!$B$3:$C$22,2) -> 0.011 | H9: =$D9-G9 -> 0.134 | I9: =AVERAGE(F9,H9) -> 0.134
B10: Upstream Fund VI | C10: 2006 | D10: 23.4% | G10: =VLOOKUP(C10,'Pitchbook O&G'!$B$3:$C$22,2) -> 0.0189 | H10: =$D10-G10 -> 0.2151 | I10: =AVERAGE(F10,H10) -> 0.2151
B11: Upstream Fund V | C11: 2004 | D11: 26.9% | G11: =VLOOKUP(C11,'Pitchbook O&G'!$B$3:$C$22,2) -> 0.1858 | H11: =$D11-G11 -> 0.0832 | I11: =AVERAGE(F11,H11) -> 0.0832
B12: Upstream Fund IV | C12: 2001 | D12: 68.4% | G12: =VLOOKUP(C12,'Pitchbook O&G'!$B$3:$C$22,2) -> 0.5053 | H12: =$D12-G12 -> 0.1787 | I12: =AVERAGE(F12,H12) -> 0.1787
B13: Upstream Fund III | C13: 1997 | D13: 23.5%
B14: Upstream Fund II | C14: 1996 | D14: 3.6%
B15: Upstream Fund I | C15: 1994 | D15: 24.8%
B17: Average | F17: =AVERAGE(F5:F8) -> 0.07 | H17: =AVERAGE(H5:H12) -> 0.132075

Sheet Company-Level Alpha
B2: Fund | C2: Company | D2: Year | E2: IRR | F2: MSCI Natural Resources | G2: Alpha | H2: Pitchbook O&G | I2: Alpha | J2: MSCI PE | K2: Alpha | M2: Company Level Alpha Summary
B3: Fund XII | C3: Grayson Mill III | D3: 2023 | E3: 1.0174752 | F3: 0.092 | G3: 0.92547521 | H3: 0 | I3: 1.0174752 | J3: 0.012 | K3: 1.0054752
B4: Fund XII | C4: Double Eagle IV | D4: 2023 | E4: 1.1155497 | F4: 0.092 | G4: 1.0235497 | H4: 0 | I4: 1.1155497 | J4: 0.012 | K4: 1.1035497
B5: Fund XII | C5: Ridge Runner (at Cost) | D5: 2023 | E5: 2.9802322e-09 | F5: 0.092 | G5: -0.091999997 | H5: 0 | I5: 2.9802322e-09 | J5: 0.012 | K5: -0.011999997 | O5: MSCI Natural | P5: Pitchbook | R5: Fund
B6: Fund XII | C6: Black Swan II (at Cost) | D6: 2023 | E6: 2.9802322e-09 | F6: 0.092 | G6: -0.091999997 | H6: 0 | I6: 2.9802322e-09 | J6: 0.012 | K6: -0.011999997 | M6: Fund | N6: Vintage | O6: Resources | P6: Oil & Gas | Q6: MSCI PE | R6: Average
B7: Fund XII | C7: Paloma VII (at Cost) | D7: 2024 | E7: 2.9802322e-09 | F7: 0.04 | G7: -0.039999997 | H7: 0 | I7: 2.9802322e-09 | J7: -0.076 | K7: 0.076000003 | M7: Fund XII | N7: 20.23 | O7: =AVERAGEIF($B:$B,$M7,F:F) -> 0.066 | P7: =AVERAGEIF($B:$B,$M7,I:I) -> 0.26662812 | Q7: =AVERAGEIF(B:B,$M7,K:K) -> 0.29862812 | R7: =AVERAGE(O7:Q7) -> 0.21041874
B8: Fund XII | C8: Novo II (at Cost) | D8: 2024 | E8: 2.9802322e-09 | F8: 0.04 | G8: -0.039999997 | H8: 0 | I8: 2.9802322e-09 | J8: -0.076 | K8: 0.076000003 | M8: Fund XI | N8: 2017 | O8: =AVERAGEIF($B:$B,$M8,F:F) -> 0.123 | P8: =AVERAGEIF($B:$B,$M8,I:I) -> 0.25048618 | Q8: =AVERAGEIF(B:B,$M8,K:K) -> 0.18276118 | R8: =AVERAGE(O8:Q8) -> 0.18541579
B9: Fund XII | C9: Pegasus III (at Cost) | D9: 2024 | E9: 2.9802322e-09 | F9: 0.04 | G9: -0.039999997 | H9: 0 | I9: 2.9802322e-09 | J9: -0.076 | K9: 0.076000003 | M9: Fund X | N9: 2015 | O9: =AVERAGEIF($B:$B,$M9,F:F) -> 0.087846154 | P9: =AVERAGEIF($B:$B,$M9,I:I) -> 0.28090058 | Q9: =AVERAGEIF(B:B,$M9,K:K) -> 0.21796981 | R9: =AVERAGE(O9:Q9) -> 0.19557218
B10: Fund XII | C10: Verdun III (at Cost) | D10: 2024 | E10: 0 | F10: 0.04 | G10: -0.04 | H10: 0 | I10: 0 | J10: -0.076 | K10: 0.076 | M10: Fund IX | N10: 2013 | O10: =AVERAGEIF($B:$B,$M10,F:F) -> 0.048047619 | P10: =AVERAGEIF($B:$B,$M10,I:I) -> 0.093887465 | Q10: =AVERAGEIF(B:B,$M10,K:K) -> 0.012430322 | R10: =AVERAGE(O10:Q10) -> 0.051455135
B11: Fund XI | C11: Sable Bay | D11: 2017 | E11: N/A | F11: 0.092 | G11: 0 | H11: 0.0974 | I11: 0 | J11: 0.171 | K11: 0 | M11: Fund VIII | N11: 2010 | O11: =AVERAGEIF($B:$B,$M11,F:F) -> -0.028521739 | P11: =AVERAGEIF($B:$B,$M11,I:I) -> 0.037136926 | Q11: =AVERAGEIF(B:B,$M11,K:K) -> -0.057989161 | R11: =AVERAGE(O11:Q11) -> -0.016457991
B12: Fund XI | C12: Black Swan | D12: 2017 | E12: 0.50300847 | F12: 0.092 | G12: 0.41100847 | H12: 0.0974 | I12: 0.40560847 | J12: 0.171 | K12: 0.33200847
B13: Fund XI | C13: Piedra IV | D13: 2018 | E13: 0.22318929 | F13: 0.086 | G13: 0.13718929 | H13: 0 | I13: 0.22318929 | J13: 0.142 | K13: 0.081189288 | M13: Limited Benchmark Data, exclude
B14: Fund XI | C14: Silverado | D14: 2019 | E14: -0.559 | F14: 0.12 | G14: -0.679 | H14: 0 | I14: -0.559 | J14: 0.112 | K14: -0.671 | M14: Fund VII | N14: 2007 | O14: =AVERAGEIF($B:$B,$M14,F:F) -> -0.00775 | P14: =AVERAGEIF($B:$B,$M14,I:I) -> 1.9114052 | Q14: =AVERAGEIF(B:B,$M14,K:K) -> 0.14498212 | R14: =AVERAGE(O14:Q14) -> 0.68287912
B15: Fund XI | C15: Forge II | D15: 2018 | E15: 0.15750422 | F15: 0.086 | G15: 0.071504219 | H15: 0 | I15: 0.15750422 | J15: 0.142 | K15: 0.015504219 | M15: Fund VI | N15: 2006 | P15: =AVERAGEIF($B:$B,$M15,I:I) -> 0.28515624 | R15: =AVERAGE(O15:Q15) -> 0.28515624
B16: Fund XI | C16: XCL | D16: 2018 | E16: 0.26769766 | F16: 0.086 | G16: 0.18169766 | H16: 0 | I16: 0.26769766 | J16: 0.142 | K16: 0.12569766 | M16: Fund V | N16: 2004 | O16: =AVERAGEIF($B:$B,$M16,F:F) -> -0.067 | P16: =AVERAGEIF($B:$B,$M16,I:I) -> 0.54412988 | Q16: =AVERAGEIF(B:B,$M16,K:K) -> -0.013178571 | R16: =AVERAGE(O16:Q16) -> 0.15465044
B17: Fund XI | C17: Raisa III | D17: 2019 | E17: -0.198 | F17: 0.12 | G17: -0.318 | H17: 0 | I17: -0.198 | J17: 0.112 | K17: -0.31 | M17: Fund IV | N17: 2001 | P17: =AVERAGEIF($B:$B,$M17,I:I) -> 0.57840286 | R17: =AVERAGE(O17:Q17) -> 0.57840286
B18: Fund XI | C18: Paloma V (Solar & Wind) | D18: 2020 | E18: 0.12959318 | F18: 0.069 | G18: 0.060593176 | H18: 0 | I18: 0.12959318 | J18: 0.096 | K18: 0.033593176 | M18: Fund III | N18: 1997 | P18: =AVERAGEIF($B:$B,$M18,I:I) -> -0.015584879 | R18: =AVERAGE(O18:Q18) -> -0.015584879
B19: Fund XI | C19: Special Opportunities | D19: 2020 | E19: 1.3644676 | F19: 0.069 | G19: 1.2954676 | H19: 0 | I19: 1.3644676 | J19: 0.096 | K19: 1.2684676 | M19: Fund II | N19: 1996 | P19: =AVERAGEIF($B:$B,$M19,I:I) -> 0 | R19: =AVERAGE(O19:Q19) -> 0
B20: Fund XI | C20: Grayson Mill II | D20: 2021 | E20: 1.0639263 | F20: 0.188 | G20: 0.87592633 | H20: 0 | I20: 1.0639263 | J20: 0.055 | K20: 1.0089263 | M20: Fund I | N20: 1994 | P20: =AVERAGEIF($B:$B,$M20,I:I) -> 0 | R20: =AVERAGE(O20:Q20) -> 0
B21: Fund XI | C21: Grayson Mill III | D21: 2023 | E21: 0.93797346 | F21: 0.092 | G21: 0.84597346 | H21: 0 | I21: 0.93797346 | J21: 0.012 | K21: 0.92597346
B22: Fund XI | C22: Silverback II | D22: 2017 | E22: -0.046 | F22: 0.092 | G22: -0.138 | H22: 0.0974 | I22: -0.1434 | J22: 0.171 | K22: -0.217
B23: Fund XI | C23: Enduring IV | D23: 2017 | E23: 0.032610252 | F23: 0.092 | G23: -0.059389748 | H23: 0.0974 | I23: -0.064789748 | J23: 0.171 | K23: -0.13838975
B24: Fund XI | C24: EnCap Minerals | D24: 2017 | E24: 0.21583549 | F24: 0.092 | G24: 0.12383549 | H24: 0.0974 | I24: 0.11843549 | J24: 0.171 | K24: 0.044835494
B25: Fund XI | C25: Arbor Gas | D25: 2021 | E25: -0.265 | F25: 0.188 | G25: -0.453 | H25: 0 | I25: -0.265 | J25: 0.055 | K25: -0.32
B26: Fund XI | C26: Grenadier III (at Cost) | D26: 2021 | E26: 2.9802322e-09 | F26: 0.188 | G26: -0.188 | H26: 0 | I26: 2.9802322e-09 | J26: 0.055 | K26: -0.054999997
B27: Fund XI | C27: Pegasus II | D27: 2021 | E27: 0.29104708 | F27: 0.188 | G27: 0.10304708 | H27: 0 | I27: 0.29104708 | J27: 0.055 | K27: 0.23604708
B28: Fund XI | C28: Verdun II | D28: 2021 | E28: 0.67269831 | F28: 0.188 | G28: 0.48469831 | H28: 0 | I28: 0.67269831 | J28: 0.055 | K28: 0.61769831
B29: Fund XI | C29: Sabalo II (at Cost) | D29: 2021 | E29: 0 | F29: 0.188 | G29: -0.188 | H29: 0 | I29: 0 | J29: 0.055 | K29: -0.055
B30: Fund XI | C30: Paloma VI | D30: 2021 | E30: 0.01320059 | F30: 0.188 | G30: -0.17479941 | H30: 0 | I30: 0.01320059 | J30: 0.055 | K30: -0.04179941
B31: Fund XI | C31: Double Eagle IV | D31: 2022 | E31: 0.63827073 | F31: 0.112 | G31: 0.52627073 | H31: 0 | I31: 0.63827073 | J31: 0.023 | K31: 0.61527073
B32: Fund XI | C32: Tumbleweed IV | D32: 2022 | E32: 0.28240415 | F32: 0.112 | G32: 0.17040415 | H32: 0 | I32: 0.28240415 | J32: 0.023 | K32: 0.25940415
... B34: Fund XI | C34: M6 | D34: 2022 | E34: 0.25542266 | F34: 0.112 | G34: 0.14342266 | H34: 0 | I34: 0.25542266 | J34: 0.023 | K34: 0.23242266
B35: Fund X | C35: Southland | D35: 2015 | E35: N/A | F35: 0.08 | G35: 0 | H35: 0.093 | I35: 0 | J35: 0.144 | K35: 0
B36: Fund X | C36: Ameredev | D36: 2015 | E36: 2.7324644 | F36: 0.08 | G36: 2.6524644 | H36: 0.093 | I36: 2.6394644 | J36: 0.144 | K36: 2.5884644
B37: Fund X | C37: Talon III | D37: 2015 | E37: 2.4348221 | F37: 0.08 | G37: 2.3548221 | H37: 0.093 | I37: 2.3418221 | J37: 0.144 | K37: 2.2908221
B38: Fund X | C38: Grenadier II | D38: 2015 | E38: 0.085849246 | F38: 0.08 | G38: 0.0058492464 | H38: 0.093 | I38: -0.0071507536 | J38: 0.144 | K38: -0.058150754
B39: Fund X | C39: Moda | D39: 2015 | E39: 0.17043261 | F39: 0.08 | G39: 0.090432609 | H39: 0.093 | I39: 0.077432609 | J39: 0.144 | K39: 0.026432609
B40: Fund X | C40: Staghorn II | D40: 2015 | E40: 1.5487023 | F40: 0.08 | G40: 1.4687023 | H40: 0.093 | I40: 1.4557023 | J40: 0.144 | K40: 1.4047023
B41: Fund X | C41: Felix II | D41: 2015 | E41: 0.46304989 | F41: 0.08 | G41: 0.38304989 | H41: 0.093 | I41: 0.37004989 | J41: 0.144 | K41: 0.31904989
B42: Fund X | C42: Raisa | D42: 2016 | E42: 0.014658883 | F42: 0.068 | G42: -0.053341117 | H42: 0.082 | I42: -0.067341117 | J42: 0.159 | K42: -0.14434112
...

Sheet Pitchbook O&G
B2: Vintage | C2: IRR
B3: 1998 | C3: 0.209
B4: 1999 | C4: 0.24
B5: 2000 | C5: 0.7259
B6: 2001 | C6: 0.5053
B7: 2002 | C7: 0.3605
B8: 2003 | C8: 0.247
B9: 2004 | C9: 0.1858
B10: 2005 | C10: 0.0784
B11: 2006 | C11: 0.0189
B12: 2007 | C12: 0.011
B13: 2008 | C13: 0.0835
B14: 2009 | C14: -0.0016
... B22: 2017 | C22: 0.0974

Sheet MSCI Natural Resources
C3: Natural Resources
B4: 2010 | C4: 0.012
B5: 2011 | C5: -0.067
B6: 2012 | C6: 0.005
B7: 2013 | C7: 0.037
B8: 2014 | C8: 0.038
B9: 2015 | C9: 0.08
B10: 2016 | C10: 0.068
B11: 2017 | C11: 0.092
B12: 2018 | C12: 0.086
B13: 2019 | C13: 0.12
B14: 2020 | C14: 0.069
B15: 2021 | C15: 0.188
... B18: 2024 | C18: 0.04
B19: All | C19: 0.062
