Workbook

Sheet Funds
A1: Fund Name | B1: Vintage Year
A2: Fund I | B2: 1994
A3: Fund II | B3: 1996
A4: Fund III | B4: 1997
A5: Fund IV | B5: 2001
A6: Fund V | B6: 2004
A7: Fund VI | B7: 2006
A8: Fund VII | B8: 2007
A9: Fund VIII | B9: 2010
A10: Fund IX | B10: 2013
A11: Fund X | B11: 2015
A12: Fund XI | B12: 2017
A13: Fund XII | B13: 2023

Sheet Portfolios
A1: Portfolio Name | B1: Fund Name | C1: Committed Capital (M) | D1: Invested Capital (M) | E1: Total Value (M) | F1: Realized | G1: MOIC | H1: Held at 0.0x | I1: Between 0.0x to 1.0x | J1: Held at 1.0x (cost) | K1: Between 1.0x to 2.0x | L1: Between 2.0x to 3.0x | M1: Above 3.0x | N1: Impaired Capital (M)
A2: Duck Lake | B2: =Funds!A2 -> Fund I | C2: 15.2 | D2: 15.2 | E2: 28 | F2: TRUE | G2: =E2/D2 -> 1.8421053 | H2: =G2=0 -> FALSE | I2: =AND(G2>0, G2<1) -> FALSE | J2: =G2=1 -> FALSE | K2: =AND(G2>1, G2<2) -> TRUE | L2: =AND(G2>=2, G2<3) -> FALSE | M2: =G2>3 -> FALSE | N2: =IF(OR(H2, I2), -D2 * (G2 - 1), 0) -> 0
A3: Paloma | B3: =Funds!A2 -> Fund I | C3: 3.6 | D3: 3.6 | E3: 7.2 | F3: TRUE | G3: =E3/D3 -> 2 | H3: =G3=0 -> FALSE | I3: =AND(G3>0, G3<1) -> FALSE | J3: =G3=1 -> FALSE | K3: =AND(G3>1, G3<2) -> FALSE | L3: =AND(G3>=2, G3<3) -> TRUE | M3: =G3>3 -> FALSE | N3: =IF(OR(H3, I3), -D3 * (G3 - 1), 0) -> 0
A4: Sierra 94 | B4: =Funds!A2 -> Fund I | C4: 6.6 | D4: 6.6 | E4: 8.2 | F4: TRUE | G4: =E4/D4 -> 1.2424242 | H4: =G4=0 -> FALSE | I4: =AND(G4>0, G4<1) -> FALSE | J4: =G4=1 -> FALSE | K4: =AND(G4>1, G4<2) -> TRUE | L4: =AND(G4>=2, G4<3) -> FALSE | M4: =G4>3 -> FALSE | N4: =IF(OR(H4, I4), -D4 * (G4 - 1), 0) -> 0
A5: ATP | B5: =Funds!A2 -> Fund I | C5: 9.6 | D5: 9.6 | E5: 11.5 | F5: TRUE | G5: =E5/D5 -> 1.1979167 | H5: =G5=0 -> FALSE | I5: =AND(G5>0, G5<1) -> FALSE | J5: =G5=1 -> FALSE | K5: =AND(G5>1, G5<2) -> TRUE | L5: =AND(G5>=2, G5<3) -> FALSE | M5: =G5>3 -> FALSE | N5: =IF(OR(H5, I5), -D5 * (G5 - 1), 0) -> 0
A6: Future | B6: =Funds!A2 -> Fund I | C6: 9.6 | D6: 9.6 | E6: 14.5 | F6: TRUE | G6: =E6/D6 -> 1.5104167 | H6: =G6=0 -> FALSE | I6: =AND(G6>0, G6<1) -> FALSE | J6: =G6=1 -> FALSE | K6: =AND(G6>1, G6<2) -> TRUE | L6: =AND(G6>=2, G6<3) -> FALSE | M6: =G6>3 -> FALSE | N6: =IF(OR(H6, I6), -D6 * (G6 - 1), 0) -> 0
A7: TAP | B7: =Funds!A2 -> Fund I | C7: 0.4 | D7: 0.4 | E7: 0 | F7: TRUE | G7: =E7/D7 -> 0 | H7: =G7=0 -> TRUE | I7: =AND(G7>0, G7<1) -> FALSE | J7: =G7=1 -> FALSE | K7: =AND(G7>1, G7<2) -> FALSE | L7: =AND(G7>=2, G7<3) -> FALSE | M7: =G7>3 -> FALSE | N7: =IF(OR(H7, I7), -D7 * (G7 - 1), 0) -> 0.4
A8: EnerVest | B8: =Funds!A2 -> Fund I | C8: 11.5 | D8: 11.5 | E8: 16.8 | F8: TRUE | G8: =E8/D8 -> 1.4608696 | H8: =G8=0 -> FALSE | I8: =AND(G8>0, G8<1) -> FALSE | J8: =G8=1 -> FALSE | K8: =AND(G8>1, G8<2) -> TRUE | L8: =AND(G8>=2, G8<3) -> FALSE | M8: =G8>3 -> FALSE | N8: =IF(OR(H8, I8), -D8 * (G8 - 1), 0) -> 0
A9: Sotex Frio | B9: =Funds!A2 -> Fund I | C9: 9.2 | D9: 9.2 | E9: 14.8 | F9: TRUE | G9: =E9/D9 -> 1.6086957 | H9: =G9=0 -> FALSE | I9: =AND(G9>0, G9<1) -> FALSE | J9: =G9=1 -> FALSE | K9: =AND(G9>1, G9<2) -> TRUE | L9: =AND(G9>=2, G9<3) -> FALSE | M9: =G9>3 -> FALSE | N9: =IF(OR(H9, I9), -D9 * (G9 - 1), 0) -> 0
A10: Matrix I | B10: =Funds!A2 -> Fund I | C10: 7.4 | D10: 7.4 | E10: 12.1 | F10: TRUE | G10: =E10/D10 -> 1.6351351 | H10: =G10=0 -> FALSE | I10: =AND(G10>0, G10<1) -> FALSE | J10: =G10=1 -> FALSE | K10: =AND(G10>1, G10<2) -> TRUE | L10: =AND(G10>=2, G10<3) -> FALSE | M10: =G10>3 -> FALSE | N10: =IF(OR(H10, I10), -D10 * (G10 - 1), 0) -> 0
A11: Double Diamond | B11: =Funds!A2 -> Fund I | C11: 3.1 | D11: 3.1 | E11: 4.8 | F11: TRUE | G11: =E11/D11 -> 1.5483871 | H11: =G11=0 -> FALSE | I11: =AND(G11>0, G11<1) -> FALSE | J11: =G11=1 -> FALSE | K11: =AND(G11>1, G11<2) -> TRUE | L11: =AND(G11>=2, G11<3) -> FALSE | M11: =G11>3 -> FALSE | N11: =IF(OR(H11, I11), -D11 * (G11 - 1), 0) -> 0
A12: MPAC I | B12: =Funds!A2 -> Fund I | C12: 13.1 | D12: 13.1 | E12: 18.4 | F12: TRUE | G12: =E12/D12 -> 1.4045802 | H12: =G12=0 -> FALSE | I12: =AND(G12>0, G12<1) -> FALSE | J12: =G12=1 -> FALSE | K12: =AND(G12>1, G12<2) -> TRUE | L12: =AND(G12>=2, G12<3) -> FALSE | M12: =G12>3 -> FALSE | N12: =IF(OR(H12, I12), -D12 * (G12 - 1), 0) -> 0
A13: Sierra 96 | B13: =Funds!A2 -> Fund I | C13: 14.8 | D13: 14.8 | E13: 59.7 | F13: TRUE | G13: =E13/D13 -> 4.0337838 | H13: =G13=0 -> FALSE | I13: =AND(G13>0, G13<1) -> FALSE | J13: =G13=1 -> FALSE | K13: =AND(G13>1, G13<2) -> FALSE | L13: =AND(G13>=2, G13<3) -> FALSE | M13: =G13>3 -> TRUE | N13: =IF(OR(H13, I13), -D13 * (G13 - 1), 0) -> 0
A14: MPAC II | B14: =Funds!A3 -> Fund II | C14: 96.7 | D14: 96.7 | E14: 114.5 | F14: TRUE | G14: =E14/D14 -> 1.1840745 | H14: =G14=0 -> FALSE | I14: =AND(G14>0, G14<1) -> FALSE | J14: =G14=1 -> FALSE | K14: =AND(G14>1, G14<2) -> TRUE | L14: =AND(G14>=2, G14<3) -> FALSE | M14: =G14>3 -> FALSE | N14: =IF(OR(H14, I14), -D14 * (G14 - 1), 0) -> 0
A15: Cliffwood | B15: =Funds!A3 -> Fund II | C15: 7.1 | D15: 7.1 | E15: 13.6 | F15: TRUE | G15: =E15/D15 -> 1.915493 | H15: =G15=0 -> FALSE | I15: =AND(G15>0, G15<1) -> FALSE | J15: =G15=1 -> FALSE | K15: =AND(G15>1, G15<2) -> TRUE | L15: =AND(G15>=2, G15<3) -> FALSE | M15: =G15>3 -> FALSE | N15: =IF(OR(H15, I15), -D15 * (G15 - 1), 0) -> 0
A16: Sierra-Harris | B16: =Funds!A3 -> Fund II | C16: 2.3 | D16: 2.3 | E16: 3.4 | F16: TRUE | G16: =E16/D16 -> 1.4782609 | H16: =G16=0 -> FALSE | I16: =AND(G16>0, G16<1) -> FALSE | J16: =G16=1 -> FALSE | K16: =AND(G16>1, G16<2) -> TRUE | L16: =AND(G16>=2, G16<3) -> FALSE | M16: =G16>3 -> FALSE | N16: =IF(OR(H16, I16), -D16 * (G16 - 1), 0) -> 0
A17: Matrix II | B17: =Funds!A3 -> Fund II | C17: 8.5 | D17: 8.5 | E17: 10.5 | F17: TRUE | G17: =E17/D17 -> 1.2352941 | H17: =G17=0 -> FALSE | I17: =AND(G17>0, G17<1) -> FALSE | J17: =G17=1 -> FALSE | K17: =AND(G17>1, G17<2) -> TRUE | L17: =AND(G17>=2, G17<3) -> FALSE | M17: =G17>3 -> FALSE | N17: =IF(OR(H17, I17), -D17 * (G17 - 1), 0) -> 0
A18: Benz | B18: =Funds!A4 -> Fund III | C18: 24.9 | D18: 24.9 | E18: 33.3 | F18: TRUE | G18: =E18/D18 -> 1.3373494 | H18: =G18=0 -> FALSE | I18: =AND(G18>0, G18<1) -> FALSE | J18: =G18=1 -> FALSE | K18: =AND(G18>1, G18<2) -> TRUE | L18: =AND(G18>=2, G18<3) -> FALSE | M18: =G18>3 -> FALSE | N18: =IF(OR(H18, I18), -D18 * (G18 - 1), 0) -> 0
A19: Harken | B19: =Funds!A4 -> Fund III | C19: 25 | D19: 25 | E19: 21.3 | F19: TRUE | G19: =E19/D19 -> 0.852 | H19: =G19=0 -> FALSE | I19: =AND(G19>0, G19<1) -> TRUE | J19: =G19=1 -> FALSE | K19: =AND(G19>1, G19<2) -> FALSE | L19: =AND(G19>=2, G19<3) -> FALSE | M19: =G19>3 -> FALSE | N19: =IF(OR(H19, I19), -D19 * (G19 - 1), 0) -> 3.7
A20: San Juan | B20: =Funds!A4 -> Fund III | C20: 15.6 | D20: 15.6 | E20: 27.7 | F20: TRUE | G20: =E20/D20 -> 1.775641 | H20: =G20=0 -> FALSE | I20: =AND(G20>0, G20<1) -> FALSE | J20: =G20=1 -> FALSE | K20: =AND(G20>1, G20<2) -> TRUE | L20: =AND(G20>=2, G20<3) -> FALSE | M20: =G20>3 -> FALSE | N20: =IF(OR(H20, I20), -D20 * (G20 - 1), 0) -> 0
A21: Sharpe | B21: =Funds!A4 -> Fund III | C21: 3 | D21: 3 | E21: 3.7 | F21: TRUE | G21: =E21/D21 -> 1.2333333 | H21: =G21=0 -> FALSE | I21: =AND(G21>0, G21<1) -> FALSE | J21: =G21=1 -> FALSE | K21: =AND(G21>1, G21<2) -> TRUE | L21: =AND(G21>=2, G21<3) -> FALSE | M21: =G21>3 -> FALSE | N21: =IF(OR(H21, I21), -D21 * (G21 - 1), 0) -> 0
A22: BreitBurn | B22: =Funds!A4 -> Fund III | C22: 30 | D22: 30 | E22: 58.4 | F22: TRUE | G22: =E22/D22 -> 1.9466667 | H22: =G22=0 -> FALSE | I22: =AND(G22>0, G22<1) -> FALSE | J22: =G22=1 -> FALSE | K22: =AND(G22>1, G22<2) -> TRUE | L22: =AND(G22>=2, G22<3) -> FALSE | M22: =G22>3 -> FALSE | N22: =IF(OR(H22, I22), -D22 * (G22 - 1), 0) -> 0
A23: Plains Resources | B23: =Funds!A4 -> Fund III | C23: 48.5 | D23: 48.5 | E23: 115.6 | F23: TRUE | G23: =E23/D23 -> 2.3835052 | H23: =G23=0 -> FALSE | I23: =AND(G23>0, G23<1) -> FALSE | J23: =G23=1 -> FALSE | K23: =AND(G23>1, G23<2) -> FALSE | L23: =AND(G23>=2, G23<3) -> TRUE | M23: =G23>3 -> FALSE | N23: =IF(OR(H23, I23), -D23 * (G23 - 1), 0) -> 0
A24: CERES | B24: =Funds!A4 -> Fund III | C24: 14.6 | D24: 14.6 | E24: 26.1 | F24: TRUE | G24: =E24/D24 -> 1.7876712 | H24: =G24=0 -> FALSE | I24: =AND(G24>0, G24<1) -> FALSE | J24: =G24=1 -> FALSE | K24: =AND(G24>1, G24<2) -> TRUE | L24: =AND(G24>=2, G24<3) -> FALSE | M24: =G24>3 -> FALSE | N24: =IF(OR(H24, I24), -D24 * (G24 - 1), 0) -> 0
A25: Matrix III | B25: =Funds!A4 -> Fund III | C25: 28.6 | D25: 28.6 | E25: 99.4 | F25: TRUE | G25: =E25/D25 -> 3.4755245 | H25: =G25=0 -> FALSE | I25: =AND(G25>0, G25<1) -> FALSE | J25: =G25=1 -> FALSE | K25: =AND(G25>1, G25<2) -> FALSE | L25: =AND(G25>=2, G25<3) -> FALSE | M25: =G25>3 -> TRUE | N25: =IF(OR(H25, I25), -D25 * (G25 - 1), 0) -> 0
A26: 3TEC | B26: =Funds!A4 -> Fund III | C26: 48.4 | D26: 48.4 | E26: 104.2 | F26: TRUE | G26: =E26/D26 -> 2.1528926 | H26: =G26=0 -> FALSE | I26: =AND(G26>0, G26<1) -> FALSE | J26: =G26=1 -> FALSE | K26: =AND(G26>1, G26<2) -> FALSE | L26: =AND(G26>=2, G26<3) -> TRUE | M26: =G26>3 -> FALSE | N26: =IF(OR(H26, I26), -D26 * (G26 - 1), 0) -> 0
A27: Bargo | B27: =Funds!A4 -> Fund III | C27: 15 | D27: 15 | E27: 26.7 | F27: TRUE | G27: =E27/D27 -> 1.78 | H27: =G27=0 -> FALSE | I27: =AND(G27>0, G27<1) -> FALSE | J27: =G27=1 -> FALSE | K27: =AND(G27>1, G27<2) -> TRUE | L27: =AND(G27>=2, G27<3) -> FALSE | M27: =G27>3 -> FALSE | N27: =IF(OR(H27, I27), -D27 * (G27 - 1), 0) -> 0
A28: Cordillera | B28: =Funds!A4 -> Fund III | C28: 48.5 | D28: 48.5 | E28: 133.7 | F28: TRUE | G28: =E28/D28 -> 2.756701 | H28: =G28=0 -> FALSE | I28: =AND(G28>0, G28<1) -> FALSE | J28: =G28=1 -> FALSE | K28: =AND(G28>1, G28<2) -> FALSE | L28: =AND(G28>=2, G28<3) -> TRUE | M28: =G28>3 -> FALSE | N28: =IF(OR(H28, I28), -D28 * (G28 - 1), 0) -> 0
A29: Cheniere | B29: =Funds!A4 -> Fund III | C29: 3.7 | D29: 3.7 | E29: 4.6 | F29: TRUE | G29: =E29/D29 -> 1.2432432 | H29: =G29=0 -> FALSE | I29: =AND(G29>0, G29<1) -> FALSE | J29: =G29=1 -> FALSE | K29: =AND(G29>1, G29<2) -> TRUE | L29: =AND(G29>=2, G29<3) -> FALSE | M29: =G29>3 -> FALSE | N29: =IF(OR(H29, I29), -D29 * (G29 - 1), 0) -> 0
A30: First Permian | B30: =Funds!A4 -> Fund III | C30: 16 | D30: 16 | E30: 27.2 | F30: TRUE | G30: =E30/D30 -> 1.7 | H30: =G30=0 -> FALSE | I30: =AND(G30>0, G30<1) -> FALSE | J30: =G30=1 -> FALSE | K30: =AND(G30>1, G30<2) -> TRUE | L30: =AND(G30>=2, G30<3) -> FALSE | M30: =G30>3 -> FALSE | N30: =IF(OR(H30, I30), -D30 * (G30 - 1), 0) -> 0
A31: American Coastal | B31: =Funds!A4 -> Fund III | C31: 12 | D31: 12 | E31: 14.3 | F31: TRUE | G31: =E31/D31 -> 1.1916667 | H31: =G31=0 -> FALSE | I31: =AND(G31>0, G31<1) -> FALSE | J31: =G31=1 -> FALSE | K31: =AND(G31>1, G31<2) -> TRUE | L31: =AND(G31>=2, G31<3) -> FALSE | M31: =G31>3 -> FALSE | N31: =IF(OR(H31, I31), -D31 * (G31 - 1), 0) -> 0
A32: Dallas Production | B32: =Funds!A4 -> Fund III | C32: 22.3 | D32: 22.3 | E32: 37.3 | F32: TRUE | G32: =E32/D32 -> 1.6726457 | H32: =G32=0 -> FALSE | I32: =AND(G32>0, G32<1) -> FALSE | J32: =G32=1 -> FALSE | K32: =AND(G32>1, G32<2) -> TRUE | L32: =AND(G32>=2, G32<3) -> FALSE | M32: =G32>3 -> FALSE | N32: =IF(OR(H32, I32), -D32 * (G32 - 1), 0) -> 0
A33: PetroQuest | B33: =Funds!A4 -> Fund III | C33: 7.5 | D33: 7.5 | E33: 8.9 | F33: TRUE | G33: =E33/D33 -> 1.1866667 | H33: =G33=0 -> FALSE | I33: =AND(G33>0, G33<1) -> FALSE | J33: =G33=1 -> FALSE | K33: =AND(G33>1, G33<2) -> TRUE | L33: =AND(G33>=2, G33<3) -> FALSE | M33: =G33>3 -> FALSE | N33: =IF(OR(H33, I33), -D33 * (G33 - 1), 0) -> 0
A34: Plains All-American LP Units | B34: =Funds!A4 -> Fund III | C34: 19.9 | D34: 19.9 | E34: 33.3 | F34: TRUE | G34: =E34/D34 -> 1.6733668 | H34: =G34=0 -> FALSE | I34: =AND(G34>0, G34<1) -> FALSE | J34: =G34=1 -> FALSE | K34: =AND(G34>1, G34<2) -> TRUE | L34: =AND(G34>=2, G34<3) -> FALSE | M34: =G34>3 -> FALSE | N34: =IF(OR(H34, I34), -D34 * (G34 - 1), 0) -> 0
A35: Copano | B35: =Funds!A4 -> Fund III | C35: 30 | D35: 30 | E35: 103 | F35: TRUE | G35: =E35/D35 -> 3.4333333 | H35: =G35=0 -> FALSE | I35: =AND(G35>0, G35<1) -> FALSE | J35: =G35=1 -> FALSE | K35: =AND(G35>1, G35<2) -> FALSE | L35: =AND(G35>=2, G35<3) -> FALSE | M35: =G35>3 -> TRUE | N35: =IF(OR(H35, I35), -D35 * (G35 - 1), 0) -> 0
A36: NCX | B36: =Funds!A4 -> Fund III | C36: 18.2 | D36: 18.2 | E36: 88.6 | F36: TRUE | G36: =E36/D36 -> 4.8681319 | H36: =G36=0 -> FALSE | I36: =AND(G36>0, G36<1) -> FALSE | J36: =G36=1 -> FALSE | K36: =AND(G36>1, G36<2) -> FALSE | L36: =AND(G36>=2, G36<3) -> FALSE | M36: =G36>3 -> TRUE | N36: =IF(OR(H36, I36), -D36 * (G36 - 1), 0) -> 0
A37: Plains All-American GP & LP Units | B37: =Funds!A4 -> Fund III | C37: 36.9 | D37: 36.9 | E37: 338.5 | F37: TRUE | G37: =E37/D37 -> 9.1734417 | H37: =G37=0 -> FALSE | I37: =AND(G37>0, G37<1) -> FALSE | J37: =G37=1 -> FALSE | K37: =AND(G37>1, G37<2) -> FALSE | L37: =AND(G37>=2, G37<3) -> FALSE | M37: =G37>3 -> TRUE | N37: =IF(OR(H37, I37), -D37 * (G37 - 1), 0) -> 0
A38: Laredo I | B38: =Funds!A5 -> Fund IV | C38: 14 | D38: 14 | E38: 70.4 | F38: TRUE | G38: =E38/D38 -> 5.0285714 | H38: =G38=0 -> FALSE | I38: =AND(G38>0, G38<1) -> FALSE | J38: =G38=1 -> FALSE | K38: =AND(G38>1, G38<2) -> FALSE | L38: =AND(G38>=2, G38<3) -> FALSE | M38: =G38>3 -> TRUE | N38: =IF(OR(H38, I38), -D38 * (G38 - 1), 0) -> 0
A39: Ovation I | B39: =Funds!A5 -> Fund IV | C39: 17.8 | D39: 17.8 | E39: 40.4 | F39: TRUE | G39: =E39/D39 -> 2.2696629 | H39: =G39=0 -> FALSE | I39: =AND(G39>0, G39<1) -> FALSE | J39: =G39=1 -> FALSE | K39: =AND(G39>1, G39<2) -> FALSE | L39: =AND(G39>=2, G39<3) -> TRUE | M39: =G39>3 -> FALSE | N39: =IF(OR(H39, I39), -D39 * (G39 - 1), 0) -> 0
A40: Sawtooth | B40: =Funds!A5 -> Fund IV | C40: 6.7 | D40: 6.7 | E40: 22.8 | F40: TRUE | G40: =E40/D40 -> 3.4029851 | H40: =G40=0 -> FALSE | I40: =AND(G40>0, G40<1) -> FALSE | J40: =G40=1 -> FALSE | K40: =AND(G40>1, G40<2) -> FALSE | L40: =AND(G40>=2, G40<3) -> FALSE | M40: =G40>3 -> TRUE | N40: =IF(OR(H40, I40), -D40 * (G40 - 1), 0) -> 0
...

Sheet Loss Ratio Analysis
B2: Loss Ratio Analysis
B3: Encap Upstream Fund XII
B4: (millions) | C4: =Funds!A2 -> Fund I | F4: =Funds!A3 -> Fund II | I4: =Funds!A4 -> Fund III | L4: =Funds!A5 -> Fund IV | O4: =Funds!A6 -> Fund V | R4: =Funds!A7 -> Fund VI | U4: =Funds!A8 -> Fund VII | X4: =Funds!A9 -> Fund VIII | AA4: =Funds!A10 -> Fund IX | AD4: =Funds!A11 -> Fund X | AG4: =Funds!A12 -> Fund XI | AK4: Total
B5: Vintage Year | C5: =Funds!B2 -> 1994 | F5: =Funds!B3 -> 1996 | I5: =Funds!B4 -> 1997 | L5: =Funds!B5 -> 2001 | O5: =Funds!B6 -> 2004 | R5: =Funds!B7 -> 2006 | U5: =Funds!B8 -> 2007 | X5: =Funds!B9 -> 2010 | AA5: =Funds!B10 -> 2013 | AD5: =Funds!B11 -> 2015 | AG5: =Funds!B12 -> 2017
B6: Committed Capital | C6: =SUMIFS(Portfolios!C:C, Portfolios!B:B, Funds!A2) -> 104.1 | F6: =SUMIFS(Portfolios!C:C, Portfolios!B:B, Funds!A3) -> 114.6 | I6: =SUMIFS(Portfolios!C:C, Portfolios!B:B, Funds!A4) -> 468.6 | L6: =SUMIFS(Portfolios!C:C, Portfolios!B:B, Funds!A5) -> 570.4 | O6: =SUMIFS(Portfolios!C:C, Portfolios!B:B, Funds!A6) -> 922.3 | R6: =SUMIFS(Portfolios!C:C, Portfolios!B:B, Funds!A7) -> 1564.2 | U6: =SUMIFS(Portfolios!C:C, Portfolios!B:B, Funds!A8) -> 2553.1 | X6: =SUMIFS(Portfolios!C:C, Portfolios!B:B, Funds!A9) -> 3761.7 | AA6: =SUMIFS(Portfolios!C:C, Portfolios!B:B, Funds!A10) -> 5442 | AD6: =SUMIFS(Portfolios!C:C, Portfolios!B:B, Funds!A11) -> 6914.8 | AG6: =SUMIFS(Portfolios!C:C, Portfolios!B:B, Funds!A12) -> 7539
B8: Number of realized inv. | C8: =COUNTIFS(Portfolios!F:F, TRUE, Portfolios!B:B, Funds!A2) -> 12 | F8: =COUNTIFS(Portfolios!F:F, TRUE, Portfolios!B:B, Funds!A3) -> 4 | I8: =COUNTIFS(Portfolios!F:F, TRUE, Portfolios!B:B, Funds!A4) -> 20 | L8: =COUNTIFS(Portfolios!F:F, TRUE, Portfolios!B:B, Funds!A5) -> 19 | O8: =COUNTIFS(Portfolios!F:F, TRUE, Portfolios!B:B, Funds!A6) -> 28 | R8: =COUNTIFS(Portfolios!F:F, TRUE, Portfolios!B:B, Funds!A7) -> 27 | U8: =COUNTIFS(Portfolios!F:F, TRUE, Portfolios!B:B, Funds!A8) -> 33 | X8: =COUNTIFS(Portfolios!F:F, TRUE, Portfolios!B:B, Funds!A9) -> 17 | AA8: =COUNTIFS(Portfolios!F:F, TRUE, Portfolios!B:B, Funds!A10) -> 11 | AD8: =COUNTIFS(Portfolios!F:F, TRUE, Portfolios!B:B, Funds!A11) -> 10 | AG8: =COUNTIFS(Portfolios!F:F, TRUE, Portfolios!B:B, Funds!A12) -> 3 | AK8: =COUNTIFS(Portfolios!F:F, TRUE) -> 184
B9: Number of unrealized inv. | C9: =COUNTIFS(Portfolios!F:F, FALSE, Portfolios!B:B, Funds!A2) -> 0 | F9: =COUNTIFS(Portfolios!F:F, FALSE, Portfolios!B:B, Funds!A3) -> 0 | I9: =COUNTIFS(Portfolios!F:F, FALSE, Portfolios!B:B, Funds!A4) -> 0 | L9: =COUNTIFS(Portfolios!F:F, FALSE, Portfolios!B:B, Funds!A5) -> 0 | O9: =COUNTIFS(Portfolios!F:F, FALSE, Portfolios!B:B, Funds!A6) -> 0 | R9: =COUNTIFS(Portfolios!F:F, FALSE, Portfolios!B:B, Funds!A7) -> 0 | U9: =COUNTIFS(Portfolios!F:F, FALSE, Portfolios!B:B, Funds!A8) -> 0 | X9: =COUNTIFS(Portfolios!F:F, FALSE, Portfolios!B:B, Funds!A9) -> 4 | AA9: =COUNTIFS(Portfolios!F:F, FALSE, Portfolios!B:B, Funds!A10) -> 8 | AD9: =COUNTIFS(Portfolios!F:F, FALSE, Portfolios!B:B, Funds!A11) -> 15 | AG9: =COUNTIFS(Portfolios!F:F, FALSE, Portfolios!B:B, Funds!A12) -> 20 | AK9: =COUNTIFS(Portfolios!F:F, FALSE) -> 55
B10: Number of Investments | C10: =C8 + C9 -> 12 | F10: =F8 + F9 -> 4 | I10: =I8 + I9 -> 20 | L10: =L8 + L9 -> 19 | O10: =O8 + O9 -> 28 | R10: =R8 + R9 -> 27 | U10: =U8 + U9 -> 33 | X10: =X8 + X9 -> 21 | AA10: =AA8 + AA9 -> 19 | AD10: =AD8 + AD9 -> 25 | AG10: =AG8 + AG9 -> 23 | AK10: =AK8 + AK9 -> 239
B12: Number of Investments
B13: Held at 0.0x | C13: =COUNTIFS(Portfolios!H:H, TRUE, Portfolios!B:B, Funds!A2) -> 1 | D13: =C13 / C19 -> 0.083333333 | F13: =COUNTIFS(Portfolios!H:H, TRUE, Portfolios!B:B, Funds!A3) -> 0 | G13: =F13 / F19 -> 0 | I13: =COUNTIFS(Portfolios!H:H, TRUE, Portfolios!B:B, Funds!A4) -> 0 | J13: =I13 / I19 -> 0 | L13: =COUNTIFS(Portfolios!H:H, TRUE, Portfolios!B:B, Funds!A5) -> 0 | M13: =L13 / L19 -> 0 | O13: =COUNTIFS(Portfolios!H:H, TRUE, Portfolios!B:B, Funds!A6) -> 0 | P13: =O13 / O19 -> 0 | R13: =COUNTIFS(Portfolios!H:H, TRUE, Portfolios!B:B, Funds!A7) -> 0 | S13: =R13 / R19 -> 0 | U13: =COUNTIFS(Portfolios!H:H, TRUE, Portfolios!B:B, Funds!A8) -> 0 | V13: =U13 / U19 -> 0 | X13: =COUNTIFS(Portfolios!H:H, TRUE, Portfolios!B:B, Funds!A9) -> 2 | Y13: =X13 / X19 -> 0.086956522 | AA13: =COUNTIFS(Portfolios!H:H, TRUE, Portfolios!B:B, Funds!A10) -> 2 | AB13: =AA13 / AA19 -> 0.095238095 | AD13: =COUNTIFS(Portfolios!H:H, TRUE, Portfolios!B:B, Funds!A11) -> 1 | AE13: =AD13 / AD19 -> 0.038461538 | AG13: =COUNTIFS(Portfolios!H:H, TRUE, Portfolios!B:B, Funds!A12) -> 1 | AH13: =AG13 / AG19 -> 0.041666667 | AK13: =COUNTIFS(Portfolios!H:H, TRUE) -> 7 | AL13: =AK13 / AK19 -> 0.028571429
B14: Between 0.0x to 1.0x | C14: =COUNTIFS(Portfolios!I:I, TRUE, Portfolios!B:B, Funds!A2) -> 0 | D14: =C14 / C19 -> 0 | F14: =COUNTIFS(Portfolios!I:I, TRUE, Portfolios!B:B, Funds!A3) -> 0 | G14: =F14 / F19 -> 0 | I14: =COUNTIFS(Portfolios!I:I, TRUE, Portfolios!B:B, Funds!A4) -> 1 | J14: =I14 / I19 -> 0.05 | L14: =COUNTIFS(Portfolios!I:I, TRUE, Portfolios!B:B, Funds!A5) -> 3 | M14: =L14 / L19 -> 0.15789474 | O14: =COUNTIFS(Portfolios!I:I, TRUE, Portfolios!B:B, Funds!A6) -> 5 | P14: =O14 / O19 -> 0.17857143 | R14: =COUNTIFS(Portfolios!I:I, TRUE, Portfolios!B:B, Funds!A7) -> 6 | S14: =R14 / R19 -> 0.22222222 | U14: =COUNTIFS(Portfolios!I:I, TRUE, Portfolios!B:B, Funds!A8) -> 10 | V14: =U14 / U19 -> 0.3030303 | X14: =COUNTIFS(Portfolios!I:I, TRUE, Portfolios!B:B, Funds!A9) -> 12 | Y14: =X14 / X19 -> 0.52173913 | AA14: =COUNTIFS(Portfolios!I:I, TRUE, Portfolios!B:B, Funds!A10) -> 5 | AB14: =AA14 / AA19 -> 0.23809524 | AD14: =COUNTIFS(Portfolios!I:I, TRUE, Portfolios!B:B, Funds!A11) -> 5 | AE14: =AD14 / AD19 -> 0.19230769 | AG14: =COUNTIFS(Portfolios!I:I, TRUE, Portfolios!B:B, Funds!A12) -> 4 | AH14: =AG14 / AG19 -> 0.16666667 | AK14: =COUNTIFS(Portfolios!I:I, TRUE) -> 51 | AL14: =AK14 / AK19 -> 0.20816327
B15: Held at 1.0x (cost) | C15: =COUNTIFS(Portfolios!J:J, TRUE, Portfolios!B:B, Funds!A2) -> 0 | D15: =C15 / C19 -> 0 | F15: =COUNTIFS(Portfolios!J:J, TRUE, Portfolios!B:B, Funds!A3) -> 0 | G15: =F15 / F19 -> 0 | I15: =COUNTIFS(Portfolios!J:J, TRUE, Portfolios!B:B, Funds!A4) -> 0 | J15: =I15 / I19 -> 0 | L15: =COUNTIFS(Portfolios!J:J, TRUE, Portfolios!B:B, Funds!A5) -> 0 | M15: =L15 / L19 -> 0 | O15: =COUNTIFS(Portfolios!J:J, TRUE, Portfolios!B:B, Funds!A6) -> 1 | P15: =O15 / O19 -> 0.035714286 | R15: =COUNTIFS(Portfolios!J:J, TRUE, Portfolios!B:B, Funds!A7) -> 0 | S15: =R15 / R19 -> 0 | U15: =COUNTIFS(Portfolios!J:J, TRUE, Portfolios!B:B, Funds!A8) -> 0 | V15: =U15 / U19 -> 0 | X15: =COUNTIFS(Portfolios!J:J, TRUE, Portfolios!B:B, Funds!A9) -> 0 | Y15: =X15 / X19 -> 0 | AA15: =COUNTIFS(Portfolios!J:J, TRUE, Portfolios!B:B, Funds!A10) -> 0 | AB15: =AA15 / AA19 -> 0 | AD15: =COUNTIFS(Portfolios!J:J, TRUE, Portfolios!B:B, Funds!A11) -> 0 | AE15: =AD15 / AD19 -> 0 | AG15: =COUNTIFS(Portfolios!J:J, TRUE, Portfolios!B:B, Funds!A12) -> 2 | AH15: =AG15 / AG19 -> 0.083333333 | AK15: =COUNTIFS(Portfolios!J:J, TRUE) -> 9 | AL15: =AK15 / AK19 -> 0.036734694
B16: Between 1.0x to 2.0x | C16: =COUNTIFS(Portfolios!K:K, TRUE, Portfolios!B:B, Funds!A2) -> 9 | D16: =C16 / C19 -> 0.75 | F16: =COUNTIFS(Portfolios!K:K, TRUE, Portfolios!B:B, Funds!A3) -> 4 | G16: =F16 / F19 -> 1 | I16: =COUNTIFS(Portfolios!K:K, TRUE, Portfolios!B:B, Funds!A4) -> 12 | J16: =I16 / I19 -> 0.6 | L16: =COUNTIFS(Portfolios!K:K, TRUE, Portfolios!B:B, Funds!A5) -> 3 | M16: =L16 / L19 -> 0.15789474 | O16: =COUNTIFS(Portfolios!K:K, TRUE, Portfolios!B:B, Funds!A6) -> 7 | P16: =O16 / O19 -> 0.25 | R16: =COUNTIFS(Portfolios!K:K, TRUE, Portfolios!B:B, Funds!A7) -> 10 | S16: =R16 / R19 -> 0.37037037 | U16: =COUNTIFS(Portfolios!K:K, TRUE, Portfolios!B:B, Funds!A8) -> 7 | V16: =U16 / U19 -> 0.21212121 | X16: =COUNTIFS(Portfolios!K:K, TRUE, Portfolios!B:B, Funds!A9) -> 4 | Y16: =X16 / X19 -> 0.17391304 | AA16: =COUNTIFS(Portfolios!K:K, TRUE, Portfolios!B:B, Funds!A10) -> 3 | AB16: =AA16 / AA19 -> 0.14285714 | AD16: =COUNTIFS(Portfolios!K:K, TRUE, Portfolios!B:B, Funds!A11) -> 8 | AE16: =AD16 / AD19 -> 0.30769231 | AG16: =COUNTIFS(Portfolios!K:K, TRUE, Portfolios!B:B, Funds!A12) -> 8 | AH16: =AG16 / AG19 -> 0.33333333 | AK16: =COUNTIFS(Portfolios!K:K, TRUE) -> 75 | AL16: =AK16 / AK19 -> 0.30612245
B17: Between 2.0x to 3.0x | C17: =COUNTIFS(Portfolios!L:L, TRUE, Portfolios!B:B, Funds!A2) -> 1 | D17: =C17 / C19 -> 0.083333333 | F17: =COUNTIFS(Portfolios!L:L, TRUE, Portfolios!B:B, Funds!A3) -> 0 | G17: =F17 / F19 -> 0 | I17: =COUNTIFS(Portfolios!L:L, TRUE, Portfolios!B:B, Funds!A4) -> 3 | J17: =I17 / I19 -> 0.15 | L17: =COUNTIFS(Portfolios!L:L, TRUE, Portfolios!B:B, Funds!A5) -> 4 | M17: =L17 / L19 -> 0.21052632 | O17: =COUNTIFS(Portfolios!L:L, TRUE, Portfolios!B:B, Funds!A6) -> 12 | P17: =O17 / O19 -> 0.42857143 | R17: =COUNTIFS(Portfolios!L:L, TRUE, Portfolios!B:B, Funds!A7) -> 7 | S17: =R17 / R19 -> 0.25925926 | U17: =COUNTIFS(Portfolios!L:L, TRUE, Portfolios!B:B, Funds!A8) -> 7 | V17: =U17 / U19 -> 0.21212121 | X17: =COUNTIFS(Portfolios!L:L, TRUE, Portfolios!B:B, Funds!A9) -> 3 | Y17: =X17 / X19 -> 0.13043478 | AA17: =COUNTIFS(Portfolios!L:L, TRUE, Portfolios!B:B, Funds!A10) -> 6 | AB17: =AA17 / AA19 -> 0.28571429 | AD17: =COUNTIFS(Portfolios!L:L, TRUE, Portfolios!B:B, Funds!A11) -> 5 | AE17: =AD17 / AD19 -> 0.19230769 | AG17: =COUNTIFS(Portfolios!L:L, TRUE, Portfolios!B:B, Funds!A12) -> 7 | AH17: =AG17 / AG19 -> 0.29166667 | AK17: =COUNTIFS(Portfolios!L:L, TRUE) -> 57 | AL17: =AK17 / AK19 -> 0.23265306
B18: Above 3.0x | C18: =COUNTIFS(Portfolios!M:M, TRUE, Portfolios!B:B, Funds!A2) -> 1 | D18: =C18 / C19 -> 0.083333333 | F18: =COUNTIFS(Portfolios!M:M, TRUE, Portfolios!B:B, Funds!A3) -> 0 | G18: =F18 / F19 -> 0 | I18: =COUNTIFS(Portfolios!M:M, TRUE, Portfolios!B:B, Funds!A4) -> 4 | J18: =I18 / I19 -> 0.2 | L18: =COUNTIFS(Portfolios!M:M, TRUE, Portfolios!B:B, Funds!A5) -> 9 | M18: =L18 / L19 -> 0.47368421 | O18: =COUNTIFS(Portfolios!M:M, TRUE, Portfolios!B:B, Funds!A6) -> 3 | P18: =O18 / O19 -> 0.10714286 | R18: =COUNTIFS(Portfolios!M:M, TRUE, Portfolios!B:B, Funds!A7) -> 4 | S18: =R18 / R19 -> 0.14814815 | U18: =COUNTIFS(Portfolios!M:M, TRUE, Portfolios!B:B, Funds!A8) -> 9 | V18: =U18 / U19 -> 0.27272727 | X18: =COUNTIFS(Portfolios!M:M, TRUE, Portfolios!B:B, Funds!A9) -> 2 | Y18: =X18 / X19 -> 0.086956522 | AA18: =COUNTIFS(Portfolios!M:M, TRUE, Portfolios!B:B, Funds!A10) -> 5 | AB18: =AA18 / AA19 -> 0.23809524 | AD18: =COUNTIFS(Portfolios!M:M, TRUE, Portfolios!B:B, Funds!A11) -> 7 | AE18: =AD18 / AD19 -> 0.26923077 | AG18: =COUNTIFS(Portfolios!M:M, TRUE, Portfolios!B:B, Funds!A12) -> 2 | AH18: =AG18 / AG19 -> 0.083333333 | AK18: =COUNTIFS(Portfolios!M:M, TRUE) -> 46 | AL18: =AK18 / AK19 -> 0.1877551
B19: Total | C19: =SUM(C13:C18) -> 12 | D19: =SUM(D13:D18) -> 1 | F19: =SUM(F13:F18) -> 4 | G19: =SUM(G13:G18) -> 1 | I19: =SUM(I13:I18) -> 20 | J19: =SUM(J13:J18) -> 1 | L19: =SUM(L13:L18) -> 19 | M19: =SUM(M13:M18) -> 1 | O19: =SUM(O13:O18) -> 28 | P19: =SUM(P13:P18) -> 1 | R19: =SUM(R13:R18) -> 27 | S19: =SUM(S13:S18) -> 1 | U19: =SUM(U13:U18) -> 33 | V19: =SUM(V13:V18) -> 1 | X19: =SUM(X13:X18) -> 23 | Y19: =SUM(Y13:Y18) -> 1 | AA19: =SUM(AA13:AA18) -> 21 | AB19: =SUM(AB13:AB18) -> 1 | AD19: =SUM(AD13:AD18) -> 26 | AE19: =SUM(AE13:AE18) -> 1 | AG19: =SUM(AG13:AG18) -> 24 | AH19: =SUM(AH13:AH18) -> 1 | AK19: =SUM(AK13:AK18) -> 245 | AL19: =SUM(AL13:AL18) -> 1
B21: Capital Invested
B22: Held at 0.0x | C22: =SUMIFS(Portfolios!D:D, Portfolios!H:H, TRUE, Portfolios!B:B, Funds!A2) -> 0.4 | D22: =C22 / C28 -> 0.0038424592 | F22: =SUMIFS(Portfolios!D:D, Portfolios!H:H, TRUE, Portfolios!B:B, Funds!A3) -> 0 | G22: =F22 / F28 -> 0 | I22: =SUMIFS(Portfolios!D:D, Portfolios!H:H, TRUE, Portfolios!B:B, Funds!A4) -> 0 | J22: =I22 / I28 -> 0 | L22: =SUMIFS(Portfolios!D:D, Portfolios!H:H, TRUE, Portfolios!B:B, Funds!A5) -> 0 | M22: =L22 / L28 -> 0 | O22: =SUMIFS(Portfolios!D:D, Portfolios!H:H, TRUE, Portfolios!B:B, Funds!A6) -> 0 | P22: =O22 / O28 -> 0 | R22: =SUMIFS(Portfolios!D:D, Portfolios!H:H, TRUE, Portfolios!B:B, Funds!A7) -> 0 | S22: =R22 / R28 -> 0 | U22: =SUMIFS(Portfolios!D:D, Portfolios!H:H, TRUE, Portfolios!B:B, Funds!A8) -> 0 | V22: =U22 / U28 -> 0 | X22: =SUMIFS(Portfolios!D:D, Portfolios!H:H, TRUE, Portfolios!B:B, Funds!A9) -> 247.5 | Y22: =X22 / X28 -> 0.06579472 | AA22: =SUMIFS(Portfolios!D:D, Portfolios!H:H, TRUE, Portfolios!B:B, Funds!A10) -> 445 | AB22: =AA22 / AA28 -> 0.083531996 | AD22: =SUMIFS(Portfolios!D:D, Portfolios!H:H, TRUE, Portfolios!B:B, Funds!A11) -> 465.5 | AE22: =AD22 / AD28 -> 0.074607728 | AG22: =SUMIFS(Portfolios!D:D, Portfolios!H:H, TRUE, Portfolios!B:B, Funds!A12) -> 5.9 | AH22: =AG22 / AG28 -> 0.00099422004 | AK22: =SUMIFS(Portfolios!D:D, Portfolios!H:H, TRUE) -> 1164.3 | AL22: =AK22 / AK28 -> 0.040985727
B23: Between 0.0x to 1.0x | C23: =SUMIFS(Portfolios!D:D, Portfolios!I:I, TRUE, Portfolios!B:B, Funds!A2) -> 0 | D23: =C23 / C28 -> 0 | F23: =SUMIFS(Portfolios!D:D, Portfolios!I:I, TRUE, Portfolios!B:B, Funds!A3) -> 0 | G23: =F23 / F28 -> 0 | I23: =SUMIFS(Portfolios!D:D, Portfolios!I:I, TRUE, Portfolios!B:B, Funds!A4) -> 25 | J23: =I23 / I28 -> 0.053350405 | L23: =SUMIFS(Portfolios!D:D, Portfolios!I:I, TRUE, Portfolios!B:B, Funds!A5) -> 95.15 | M23: =L23 / L28 -> 0.16679814 | O23: =SUMIFS(Portfolios!D:D, Portfolios!I:I, TRUE, Portfolios!B:B, Funds!A6) -> 110.9 | P23: =O23 / O28 -> 0.12024287 | R23: =SUMIFS(Portfolios!D:D, Portfolios!I:I, TRUE, Portfolios!B:B, Funds!A7) -> 358.4 | S23: =R23 / R28 -> 0.22912671 | U23: =SUMIFS(Portfolios!D:D, Portfolios!I:I, TRUE, Portfolios!B:B, Funds!A8) -> 1180 | V23: =U23 / U28 -> 0.46216513 | X23: =SUMIFS(Portfolios!D:D, Portfolios!I:I, TRUE, Portfolios!B:B, Funds!A9) -> 2115.5 | Y23: =X23 / X28 -> 0.56237871 | AA23: =SUMIFS(Portfolios!D:D, Portfolios!I:I, TRUE, Portfolios!B:B, Funds!A10) -> 1295.1 | AB23: =AA23 / AA28 -> 0.24310626 | AD23: =SUMIFS(Portfolios!D:D, Portfolios!I:I, TRUE, Portfolios!B:B, Funds!A11) -> 574.4 | AE23: =AD23 / AD28 -> 0.092061609 | AG23: =SUMIFS(Portfolios!D:D, Portfolios!I:I, TRUE, Portfolios!B:B, Funds!A12) -> 272.9 | AH23: =AG23 / AG28 -> 0.04598689 | AK23: =SUMIFS(Portfolios!D:D, Portfolios!I:I, TRUE) -> 6027.35 | AL23: =AK23 / AK28 -> 0.21217498
B24: Held at 1.0x (cost) | C24: =SUMIFS(Portfolios!D:D, Portfolios!J:J, TRUE, Portfolios!B:B, Funds!A2) -> 0 | D24: =C24 / C28 -> 0 | F24: =SUMIFS(Portfolios!D:D, Portfolios!J:J, TRUE, Portfolios!B:B, Funds!A3) -> 0 | G24: =F24 / F28 -> 0 | I24: =SUMIFS(Portfolios!D:D, Portfolios!J:J, TRUE, Portfolios!B:B, Funds!A4) -> 0 | J24: =I24 / I28 -> 0 | L24: =SUMIFS(Portfolios!D:D, Portfolios!J:J, TRUE, Portfolios!B:B, Funds!A5) -> 0 | M24: =L24 / L28 -> 0 | O24: =SUMIFS(Portfolios!D:D, Portfolios!J:J, TRUE, Portfolios!B:B, Funds!A6) -> 12.7 | P24: =O24 / O28 -> 0.013769923 | R24: =SUMIFS(Portfolios!D:D, Portfolios!J:J, TRUE, Portfolios!B:B, Funds!A7) -> 0 | S24: =R24 / R28 -> 0 | U24: =SUMIFS(Portfolios!D:D, Portfolios!J:J, TRUE, Portfolios!B:B, Funds!A8) -> 0 | V24: =U24 / U28 -> 0 | X24: =SUMIFS(Portfolios!D:D, Portfolios!J:J, TRUE, Portfolios!B:B, Funds!A9) -> 0 | Y24: =X24 / X28 -> 0 | AA24: =SUMIFS(Portfolios!D:D, Portfolios!J:J, TRUE, Portfolios!B:B, Funds!A10) -> 0 | AB24: =AA24 / AA28 -> 0 | AD24: =SUMIFS(Portfolios!D:D, Portfolios!J:J, TRUE, Portfolios!B:B, Funds!A11) -> 0 | AE24: =AD24 / AD28 -> 0 | AG24: =SUMIFS(Portfolios!D:D, Portfolios!J:J, TRUE, Portfolios!B:B, Funds!A12) -> 135.9 | AH24: =AG24 / AG28 -> 0.022900763 | AK24: =SUMIFS(Portfolios!D:D, Portfolios!J:J, TRUE) -> 515.4 | AL24: =AK24 / AK28 -> 0.018143128
B25: Between 1.0x to 2.0x | C25: =SUMIFS(Portfolios!D:D, Portfolios!K:K, TRUE, Portfolios!B:B, Funds!A2) -> 85.3 | D25: =C25 / C28 -> 0.81940442 | F25: =SUMIFS(Portfolios!D:D, Portfolios!K:K, TRUE, Portfolios!B:B, Funds!A3) -> 114.6 | G25: =F25 / F28 -> 1 | I25: =SUMIFS(Portfolios!D:D, Portfolios!K:K, TRUE, Portfolios!B:B, Funds!A4) -> 184.5 | J25: =I25 / I28 -> 0.39372599 | L25: =SUMIFS(Portfolios!D:D, Portfolios!K:K, TRUE, Portfolios!B:B, Funds!A5) -> 87.8 | M25: =L25 / L28 -> 0.15391358 | O25: =SUMIFS(Portfolios!D:D, Portfolios!K:K, TRUE, Portfolios!B:B, Funds!A6) -> 270.3 | P25: =O25 / O28 -> 0.29307167 | R25: =SUMIFS(Portfolios!D:D, Portfolios!K:K, TRUE, Portfolios!B:B, Funds!A7) -> 512 | S25: =R25 / R28 -> 0.32732387 | U25: =SUMIFS(Portfolios!D:D, Portfolios!K:K, TRUE, Portfolios!B:B, Funds!A8) -> 461.7 | V25: =U25 / U28 -> 0.1808319 | X25: =SUMIFS(Portfolios!D:D, Portfolios!K:K, TRUE, Portfolios!B:B, Funds!A9) -> 482.8 | Y25: =X25 / X28 -> 0.12834623 | AA25: =SUMIFS(Portfolios!D:D, Portfolios!K:K, TRUE, Portfolios!B:B, Funds!A10) -> 1027.2 | AB25: =AA25 / AA28 -> 0.19281813 | AD25: =SUMIFS(Portfolios!D:D, Portfolios!K:K, TRUE, Portfolios!B:B, Funds!A11) -> 1537.4 | AE25: =AD25 / AD28 -> 0.24640585 | AG25: =SUMIFS(Portfolios!D:D, Portfolios!K:K, TRUE, Portfolios!B:B, Funds!A12) -> 2052.8 | AH25: =AG25 / AG28 -> 0.34592117 | AK25: =SUMIFS(Portfolios!D:D, Portfolios!K:K, TRUE) -> 6816.4 | AL25: =AK25 / AK28 -> 0.23995114
B26: Between 2.0x to 3.0x | C26: =SUMIFS(Portfolios!D:D, Portfolios!L:L, TRUE, Portfolios!B:B, Funds!A2) -> 3.6 | D26: =C26 / C28 -> 0.034582133 | F26: =SUMIFS(Portfolios!D:D, Portfolios!L:L, TRUE, Portfolios!B:B, Funds!A3) -> 0 | G26: =F26 / F28 -> 0 | I26: =SUMIFS(Portfolios!D:D, Portfolios!L:L, TRUE, Portfolios!B:B, Funds!A4) -> 145.4 | J26: =I26 / I28 -> 0.31028596 | L26: =SUMIFS(Portfolios!D:D, Portfolios!L:L, TRUE, Portfolios!B:B, Funds!A5) -> 110.9 | M26: =L26 / L28 -> 0.19440792 | O26: =SUMIFS(Portfolios!D:D, Portfolios!L:L, TRUE, Portfolios!B:B, Funds!A6) -> 416.1 | P26: =O26 / O28 -> 0.45115472 | R26: =SUMIFS(Portfolios!D:D, Portfolios!L:L, TRUE, Portfolios!B:B, Funds!A7) -> 361.9 | S26: =R26 / R28 -> 0.23136428 | U26: =SUMIFS(Portfolios!D:D, Portfolios!L:L, TRUE, Portfolios!B:B, Funds!A8) -> 374.3 | V26: =U26 / U28 -> 0.14660034 | X26: =SUMIFS(Portfolios!D:D, Portfolios!L:L, TRUE, Portfolios!B:B, Funds!A9) -> 805.5 | Y26: =X26 / X28 -> 0.21413191 | AA26: =SUMIFS(Portfolios!D:D, Portfolios!L:L, TRUE, Portfolios!B:B, Funds!A10) -> 1285.1 | AB26: =AA26 / AA28 -> 0.24122914 | AD26: =SUMIFS(Portfolios!D:D, Portfolios!L:L, TRUE, Portfolios!B:B, Funds!A11) -> 1624.7 | AE26: =AD26 / AD28 -> 0.2603978 | AG26: =SUMIFS(Portfolios!D:D, Portfolios!L:L, TRUE, Portfolios!B:B, Funds!A12) -> 2574.9 | AH26: =AG26 / AG28 -> 0.43390122 | AK26: =SUMIFS(Portfolios!D:D, Portfolios!L:L, TRUE) -> 8183 | AL26: =AK26 / AK28 -> 0.28805824
B27: Above 3.0x | C27: =SUMIFS(Portfolios!D:D, Portfolios!M:M, TRUE, Portfolios!B:B, Funds!A2) -> 14.8 | D27: =C27 / C28 -> 0.14217099 | F27: =SUMIFS(Portfolios!D:D, Portfolios!M:M, TRUE, Portfolios!B:B, Funds!A3) -> 0 | G27: =F27 / F28 -> 0 | I27: =SUMIFS(Portfolios!D:D, Portfolios!M:M, TRUE, Portfolios!B:B, Funds!A4) -> 113.7 | J27: =I27 / I28 -> 0.24263764 | L27: =SUMIFS(Portfolios!D:D, Portfolios!M:M, TRUE, Portfolios!B:B, Funds!A5) -> 276.6 | M27: =L27 / L28 -> 0.48488036 | O27: =SUMIFS(Portfolios!D:D, Portfolios!M:M, TRUE, Portfolios!B:B, Funds!A6) -> 112.3 | P27: =O27 / O28 -> 0.12176082 | R27: =SUMIFS(Portfolios!D:D, Portfolios!M:M, TRUE, Portfolios!B:B, Funds!A7) -> 331.9 | S27: =R27 / R28 -> 0.21218514 | U27: =SUMIFS(Portfolios!D:D, Portfolios!M:M, TRUE, Portfolios!B:B, Funds!A8) -> 537.2 | V27: =U27 / U28 -> 0.21040263 | X27: =SUMIFS(Portfolios!D:D, Portfolios!M:M, TRUE, Portfolios!B:B, Funds!A9) -> 110.4 | Y27: =X27 / X28 -> 0.029348433 | AA27: =SUMIFS(Portfolios!D:D, Portfolios!M:M, TRUE, Portfolios!B:B, Funds!A10) -> 1274.9 | AB27: =AA27 / AA28 -> 0.23931447 | AD27: =SUMIFS(Portfolios!D:D, Portfolios!M:M, TRUE, Portfolios!B:B, Funds!A11) -> 2037.3 | AE27: =AD27 / AD28 -> 0.32652701 | AG27: =SUMIFS(Portfolios!D:D, Portfolios!M:M, TRUE, Portfolios!B:B, Funds!A12) -> 891.9 | AH27: =AG27 / AG28 -> 0.15029574 | AK27: =SUMIFS(Portfolios!D:D, Portfolios!M:M, TRUE) -> 5701 | AL27: =AK27 / AK28 -> 0.20068679
B28: Total | C28: =SUM(C22:C27) -> 104.1 | D28: =SUM(D22:D27) -> 1 | F28: =SUM(F22:F27) -> 114.6 | G28: =SUM(G22:G27) -> 1 | I28: =SUM(I22:I27) -> 468.6 | J28: =SUM(J22:J27) -> 1 | L28: =SUM(L22:L27) -> 570.45 | M28: =SUM(M22:M27) -> 1 | O28: =SUM(O22:O27) -> 922.3 | P28: =SUM(P22:P27) -> 1 | R28: =SUM(R22:R27) -> 1564.2 | S28: =SUM(S22:S27) -> 1 | U28: =SUM(U22:U27) -> 2553.2 | V28: =SUM(V22:V27) -> 1 | X28: =SUM(X22:X27) -> 3761.7 | Y28: =SUM(Y22:Y27) -> 1 | AA28: =SUM(AA22:AA27) -> 5327.3 | AB28: =SUM(AB22:AB27) -> 1 | AD28: =SUM(AD22:AD27) -> 6239.3 | AE28: =SUM(AE22:AE27) -> 1 | AG28: =SUM(AG22:AG27) -> 5934.3 | AH28: =SUM(AH22:AH27) -> 1 | AK28: =SUM(AK22:AK27) -> 28407.45 | AL28: =SUM(AL22:AL27) -> 1
B30: Capital Invested in Impaired Deals
B31: Capital Invested in Impaired Deals | C31: =C22 + C23 -> 0.4 | F31: =F22 + F23 -> 0 | I31: =I22 + I23 -> 25 | L31: =L22 + L23 -> 95.15 | O31: =O22 + O23 -> 110.9 | R31: =R22 + R23 -> 358.4 | U31: =U22 + U23 -> 1180 | X31: =X22 + X23 -> 2363 | AA31: =AA22 + AA23 -> 1740.1 | AD31: =AD22 + AD23 -> 1039.9 | AG31: =AG22 + AG23 -> 278.8 | AK31: =AK22 + AK23 -> 7191.65
B32: Total capital invested | C32: =C28 -> 104.1 | F32: =F28 -> 114.6 | I32: =I28 -> 468.6 | L32: =L28 -> 570.45 | O32: =O28 -> 922.3 | R32: =R28 -> 1564.2 | U32: =U28 -> 2553.2 | X32: =X28 -> 3761.7 | AA32: =AA28 -> 5327.3 | AD32: =AD28 -> 6239.3 | AG32: =AG28 -> 5934.3 | AK32: =AK28 -> 28407.45
B33: % of capital invested in impaired deals | C33: =C31 / C32 -> 0.0038424592 | F33: =F31 / F32 -> 0 | I33: =I31 / I32 -> 0.053350405 | L33: =L31 / L32 -> 0.16679814 | O33: =O31 / O32 -> 0.12024287 | R33: =R31 / R32 -> 0.22912671 | U33: =U31 / U32 -> 0.46216513 | X33: =X31 / X32 -> 0.62817343 | AA33: =AA31 / AA32 -> 0.32663826 | AD33: =AD31 / AD32 -> 0.16666934 | AG33: =AG31 / AG32 -> 0.04698111 | AK33: =AK31 / AK32 -> 0.2531607
B35: Impaired Capital
B36: Total capital impaired | C36: =SUMIFS(Portfolios!N:N, Portfolios!B:B, Funds!A2) -> 0.4 | F36: =SUMIFS(Portfolios!N:N, Portfolios!B:B, Funds!A3) -> 0 | I36: =SUMIFS(Portfolios!N:N, Portfolios!B:B, Funds!A4) -> 3.7 | L36: =SUMIFS(Portfolios!N:N, Portfolios!B:B, Funds!A5) -> 67.35 | O36: =SUMIFS(Portfolios!N:N, Portfolios!B:B, Funds!A6) -> 99.3 | R36: =SUMIFS(Portfolios!N:N, Portfolios!B:B, Funds!A7) -> 243.4 | U36: =SUMIFS(Portfolios!N:N, Portfolios!B:B, Funds!A8) -> 936.6 | X36: =SUMIFS(Portfolios!N:N, Portfolios!B:B, Funds!A9) -> 1286.2 | AA36: =SUMIFS(Portfolios!N:N, Portfolios!B:B, Funds!A10) -> 1446.7 | AD36: =SUMIFS(Portfolios!N:N, Portfolios!B:B, Funds!A11) -> 930.8 | AG36: =SUMIFS(Portfolios!N:N, Portfolios!B:B, Funds!A12) -> 67.8 | AK36: =SUM(Portfolios!N:N) -> 5082.25
B37: Total capital invested | C37: =C28 -> 104.1 | F37: =F28 -> 114.6 | I37: =I28 -> 468.6 | L37: =L28 -> 570.45 | O37: =O28 -> 922.3 | R37: =R28 -> 1564.2 | U37: =U28 -> 2553.2 | X37: =X28 -> 3761.7 | AA37: =AA28 -> 5327.3 | AD37: =AD28 -> 6239.3 | AG37: =AG28 -> 5934.3 | AK37: =AK28 -> 28407.45
B38: % of capital impaired | C38: =C36 / C28 -> 0.0038424592 | F38: =F36 / F28 -> 0 | I38: =I36 / I28 -> 0.00789586 | L38: =L36 / L28 -> 0.11806469 | O38: =O36 / O28 -> 0.10766562 | R38: =R36 / R28 -> 0.1556067 | U38: =U36 / U28 -> 0.36683378 | X38: =X36 / X28 -> 0.34191988 | AA38: =AA36 / AA28 -> 0.27156346 | AD38: =AD36 / AD28 -> 0.1491834 | AG38: =AG36 / AG28 -> 0.011425105 | AK38: =AK36 / AK28 -> 0.17890553
AK40: =SUM(AL16:AL18)/SUM(AL13:AL14) -> 3.0689655
AK41: =SUM(AL25:AL27)/SUM(AL22:AL23) -> 2.8783937
AL43: =SUM(AL16:AL18) -> 0.72653061
AL44: =SUM(AL25:AL27) -> 0.72869617
